Workbook
Name Age: 'AW calculator'!$B$5
Name Age: '[1]AW calculator'!$B$5
Name cohortSize: [2]Parameters!$E$15
Name compliance: [2]Parameters!$E$112:$E$117
Name compliance.PostDiag: [2]Parameters!$E$118:$E$123
Name Disc: 'AW calculator'!$B$3
Name Disc: '[1]AW calculator'!$B$3
Name discCost: [2]Parameters!$E$9
Name discHealth: [2]Parameters!$E$8
Name endAge: [2]Parameters!$E$12
Name Female: 'AW calculator'!$B$4
Name Female: '[1]AW calculator'!$B$4
Name genPopUtility: [2]Parameters!$E$1783:$E$1792
Name iatrogenicHarmUtility: [2]Parameters!$E$1793
Name incidenceStage1: '[2]Intermediate Calcs'!$F$18:$AA$68
Name incidenceStage2: '[2]Intermediate Calcs'!$F$76:$AA$126
Name incidenceStage3: '[2]Intermediate Calcs'!$F$134:$AA$184
Name incidenceStage4: '[2]Intermediate Calcs'!$F$192:$AA$242
Name IncludeCancer: [2]Settings!$F$38:$F$59
Name lifetable: 'AW calculator'!$A$9:$E$109
Name lifetable: '[1]AW calculator'!$A$9:$E$109
Name minAgeBand: [2]Parameters!$E$92:$E$101
Name percFemale: [2]Parameters!$E$14
Name rngPercIatrogenic: '[2]Survival Table'!$F$106:$CO$115
Name socCompliance: [2]Parameters!$E$46:$E$67
Name socSpecificity: [2]Parameters!$E$68:$E$89
Name socTestCosts: [2]Parameters!$E$24:$E$45
Name socTestEligibility: '[2]Intermediate Calcs'!$G$248:$G$269
Name startAge: [2]Parameters!$E$11
Name tblDeaths5y: '[2]Survival Table'!$F$25:$CO$34
Name tblSurvival: '[2]Survival Table'!$F$10:$CO$19
Name testCosts: [2]Parameters!$E$1118:$E$1121
Name testSpecificity: [2]Parameters!$E$90
Name timeHorizon: [2]Parameters!$E$13
Name timeIatrogenicHarm: [2]Parameters!$E$19
Name timeShift3To1: '[2]Time Shift Lookup'!$F$29:$Y$50
Name timeShift4To1: '[2]Time Shift Lookup'!$F$55:$Y$76
Name timeShift4To2: '[2]Time Shift Lookup'!$F$81:$Y$102
Name timeShiftDist: '[2]Time Shift Lookup'!$F$10:$Y$21
Name timeShiftDistMean: '[2]Time Shift Lookup'!$E$10:$E$21
Name util: 'AW calculator'!$E$3
Name util: '[1]AW calculator'!$E$3

Sheet Raw Lung Inc&Surv
A1: stage | B1: Age_band | C1: male_incidenceper100k | E1: male_mean_survival | F1: female_incidenceper100k | G1: female_mean_survival
A2: I | B2: 50-54 | C2: 4.434902 | D2: 0.772 | E2: 26.24 | F2: 4.434902 | G2: 28.64
A3: I | B3: 55-59 | C3: 10.150356 | D3: 0.69 | E3: 21.42 | F3: 10.150356 | G3: 23.38
A4: I | B4: 60-64 | C4: 20.912485 | D4: 0.674 | E4: 17.7 | F4: 20.912485 | G4: 19.41
A5: I | B5: 65-69 | C5: 35.53529 | D5: 0.643 | E5: 13.55 | F5: 35.53529 | G5: 14.89
A6: I | B6: 70-74 | C6: 56.038109 | D6: 0.549 | E6: 10.08 | F6: 56.038109 | G6: 11.06
A7: I | B7: 75-79 | C7: 71.974258 | D7: 0.479 | E7: 9.18 | F7: 71.974258 | G7: 10.17
A8: II | B8: 50-54 | C8: 1.856267 | D8: 0.469 | E8: 18.06 | F8: 1.856267 | G8: 20.43
A9: II | B9: 55-59 | C9: 4.507937 | D9: 0.525 | E9: 14.47 | F9: 4.507937 | G9: 17
A10: II | B10: 60-64 | C10: 9.623693 | D10: 0.484 | E10: 13.07 | F10: 9.623693 | G10: 13.39
A11: II | B11: 65-69 | C11: 15.235883 | D11: 0.39 | E11: 9.01 | F11: 15.235883 | G11: 9.86
A12: II | B12: 70-74 | C12: 23.261631 | D12: 0.312 | E12: 7.18 | F12: 23.261631 | G12: 7.61
A13: II | B13: 75-79 | C13: 30.003927 | D13: 0.27 | E13: 7.25 | F13: 30.003927 | G13: 8.22
... A25: IV | B25: 75-79 | C25: 169.87109 | D25: 0.018 | E25: 4.12 | F25: 169.87109 | G25: 4.46

Sheet Corrected Inc&Surv
A1: stage | B1: Age_band | C1: incidenceper100k | D1: 5-year_net_survival | E1: male_mean_survival | F1: female_mean_survival | G1: pooled_mean_survival
A2: I | B2: 50-54 | C2: 4.434902 | D2: 0.772 | E2: 26.24 | F2: 28.64 | G2: =SUM(E2*(1-0.53) + F2*0.53) -> 27.512
A3: I | B3: 55-59 | C3: 10.150356 | D3: 0.69 | E3: 21.42 | F3: 23.38 | G3: =SUM(E3*(1-0.53) + F3*0.53) -> 22.4588
A4: I | B4: 60-64 | C4: 20.912485 | D4: 0.674 | E4: 17.7 | F4: 19.41 | G4: =SUM(E4*(1-0.53) + F4*0.53) -> 18.6063
A5: I | B5: 65-69 | C5: 35.53529 | D5: 0.643 | E5: 13.55 | F5: 14.89 | G5: =SUM(E5*(1-0.53) + F5*0.53) -> 14.2602
A6: I | B6: 70-74 | C6: 56.038109 | D6: 0.549 | E6: 10.08 | F6: 11.06 | G6: =SUM(E6*(1-0.53) + F6*0.53) -> 10.5994
A7: I | B7: 75-79 | C7: 71.974258 | D7: 0.479 | E7: 9.18 | F7: 10.17 | G7: =SUM(E7*(1-0.53) + F7*0.53) -> 9.7047
A8: II | B8: 50-54 | C8: 1.856267 | D8: 0.469 | E8: 18.06 | F8: 20.43 | G8: =SUM(E8*(1-0.53) + F8*0.53) -> 19.3161
A9: II | B9: 55-59 | C9: 4.507937 | D9: 0.525 | E9: 14.47 | F9: 17 | G9: =SUM(E9*(1-0.53) + F9*0.53) -> 15.8109
A10: II | B10: 60-64 | C10: 9.623693 | D10: 0.484 | E10: 13.07 | F10: 13.39 | G10: =SUM(E10*(1-0.53) + F10*0.53) -> 13.2396
A11: II | B11: 65-69 | C11: 15.235883 | D11: 0.39 | E11: 9.01 | F11: 9.86 | G11: =SUM(E11*(1-0.53) + F11*0.53) -> 9.4605
A12: II | B12: 70-74 | C12: 23.261631 | D12: 0.312 | E12: 7.18 | F12: 7.61 | G12: =SUM(E12*(1-0.53) + F12*0.53) -> 7.4079
A13: II | B13: 75-79 | C13: 30.003927 | D13: 0.27 | E13: =E12 -> 7.18 | F13: =F12 -> 7.61 | G13: =SUM(E13*(1-0.53) + F13*0.53) -> 7.4079
A14: III | B14: 50-54 | C14: 6.715834 | D14: 0.235 | E14: 10.05 | F14: 10.83 | G14: =SUM(E14*(1-0.53) + F14*0.53) -> 10.4634
A15: III | B15: 55-59 | C15: 14.493369 | D15: 0.18 | E15: 7.57 | F15: 8.29 | G15: =SUM(E15*(1-0.53) + F15*0.53) -> 7.9516
A16: III | B16: 60-64 | C16: 26.96892 | D16: 0.175 | E16: 6.48 | F16: 6.97 | G16: =SUM(E16*(1-0.53) + F16*0.53) -> 6.7397
A17: III | B17: 65-69 | C17: 41.374767 | D17: 0.138 | E17: 4.51 | F17: 4.63 | G17: =SUM(E17*(1-0.53) + F17*0.53) -> 4.5736
A18: III | B18: 70-74 | C18: 58.420326 | D18: 0.112 | E18: 3.46 | F18: 3.7 | G18: =SUM(E18*(1-0.53) + F18*0.53) -> 3.5872
A19: III | B19: 75-79 | C19: 73.279182 | D19: 0.096 | E19: =E18 -> 3.46 | F19: =F18 -> 3.7 | G19: =SUM(E19*(1-0.53) + F19*0.53) -> 3.5872
A20: IV | B20: 50-54 | C20: 17.516331 | D20: 0.055 | E20: 3.06 | F20: 2.87 | G20: =SUM(E20*(1-0.53) + F20*0.53) -> 2.9593
A21: IV | B21: 55-59 | C21: 35.513752 | D21: 0.045 | E21: 2.2 | F21: 2.34 | G21: =SUM(E21*(1-0.53) + F21*0.53) -> 2.2742
A22: IV | B22: 60-64 | C22: 65.085518 | D22: 0.035 | E22: 1.83 | F22: 1.94 | G22: =SUM(E22*(1-0.53) + F22*0.53) -> 1.8883
A23: IV | B23: 65-69 | C23: 99.622284 | D23: 0.027 | E23: 1.39 | F23: 1.51 | G23: =SUM(E23*(1-0.53) + F23*0.53) -> 1.4536
A24: IV | B24: 70-74 | C24: 138.44875 | D24: 0.023 | E24: 1.14 | F24: 1.28 | G24: =SUM(E24*(1-0.53) + F24*0.53) -> 1.2142
A25: IV | B25: 75-79 | C25: 169.87109 | D25: 0.018 | E25: =E24 -> 1.14 | F25: =F24 -> 1.28 | G25: =SUM(E25*(1-0.53) + F25*0.53) -> 1.2142

Sheet AW calculator
A1: NICE DSU Severity calculator - Allan Wailoo, Paul Tappenden. | N1: Calculations | Y1: Output
A2: USER INPUT VALUES | J2: Output | Z2: Males | AA2: Females | AB2: overall
A3: Discount rate | B3: 0.035 | D3: Utility source | E3: 1 | F3: (1= Hernandez 3L, 2 = PT source) | J3: AS | K3: =Z9 -> -0.48098126 | Y3: Life years | Z3: =SUMIF(P9:P109,"<>#N/A") -> 9.0301057 | AA3: =SUMIF(Q9:Q109,"<>#N/A") -> 10.319695 | AB3: =(Z3*(1-Female))+(AA3*Female) -> 9.713588
A4: Proportion female | B4: 0.53 | D4: Comparator QALE | E4: 6.03 | J4: PS | K4: =Z10 -> -0.086678615 | Y4: 1/2 cycle adjusted | Z4: =SUMIF(R9:R109,"<>#N/A") -> 8.5241602 | AA4: =SUMIF(S9:S109,"<>#N/A") -> 9.8069132 | AB4: =(Z4*(1-Female))+(AA4*Female) -> 9.2040193
A5: Starting age | B5: 80 | Y5: QALYs | Z5: =SUMIF(T9:T109,"<>#N/A") -> 6.4574922 | AA5: =SUMIF(U9:U109,"<>#N/A") -> 6.7805385 | AB5: =(Z5*(1-Female))+(AA5*Female) -> 6.6287067
A6: National Life Tables, England, period expectation of life, based on data for the years 2017-2019 | J6: Age-specific utility (from paper) | Y6: Disc QALYs | Z6: =SUMIF(V9:V109,"<>#N/A") -> 5.4506503 | AA6: =SUMIF(W9:W109,"<>#N/A") -> 5.6362511 | AB6: =(Z6*(1-Female))+(AA6*Female) -> 5.5490187
B7: male | C7: female | D7: Active utility | F7: male | G7: female | H7: PT | P7: Proportion alive at the beginning of the period | R7: 1/2 cycle adjust | T7: utilities | V7: discounted | Y7: check | Z7: =SUM(P9:P47) -> #N/A | AA7: =SUM(Q9:Q47) -> #N/A | AB7: =Z7*(1-Female)+AA7*Female -> #N/A
A8: age | B8: qx | C8: qx | D8: Male | E8: female | F8: utility_m4 | G8: utility_f4 | H8: Male | I8: Female | J8: Age cat | K8: Cat low bound | L8: Males | M8: Females | N8: Year | O8: Age | P8: Alive males | Q8: Alive females | R8: males | S8: females | T8: males | U8: females | V8: males | W8: females
A9: 0 | B9: 0.004312 | C9: 0.003576 | D9: =IF(util=1,F9,IF(util=2,H9,"err")) -> 0.94464086 | E9: =IF(util=1,G9,IF(util=2,I9,"err")) -> 0.91032568 | F9: 0.94464086 | G9: 0.91032568 | H9: =VLOOKUP($A9,$K$9:$M$26,2) -> 0.916 | I9: =VLOOKUP($A9,$K$9:$M$26,3) -> 0.881 | J9: 0-15 | K9: 0 | L9: =L10 -> 0.916 | M9: =M10 -> 0.881 | N9: 0 | O9: =Age+N9 -> 80 | P9: 1 | Q9: 1 | R9: =(P9+P10)/2 -> 0.973554 | S9: =(Q9+Q10)/2 -> 0.981175 | T9: =R9*VLOOKUP(O9,lifetable,4,FALSE) -> 0.75894717 | U9: =S9*VLOOKUP(O9,lifetable,5,FALSE) -> 0.71476395 | V9: =T9/(1+Disc)^N9 -> 0.75894717 | W9: =U9/(1+Disc)^N9 -> 0.71476395 | Y9: AS | Z9: =AB6-E4 -> -0.48098126
A10: 1 | B10: 0.000242 | C10: 0.000213 | D10: =IF(util=1,F10,IF(util=2,H10,"err")) -> 0.94464086 | E10: =IF(util=1,G10,IF(util=2,I10,"err")) -> 0.91032568 | F10: 0.94464086 | G10: 0.91032568 | H10: =VLOOKUP($A10,$K$9:$M$26,2) -> 0.916 | I10: =VLOOKUP($A10,$K$9:$M$26,3) -> 0.881 | J10: 16-17 | K10: 16 | L10: 0.916 | M10: 0.881 | N10: 1 | O10: =Age+N10 -> 81 | P10: =P9-P9*VLOOKUP(O9,lifetable,2,FALSE) -> 0.947108 | Q10: =Q9-Q9*VLOOKUP(O9,lifetable,3,FALSE) -> 0.96235 | R10: =(P10+P11)/2 -> 0.91922467 | S10: =(Q10+Q11)/2 -> 0.94196791 | T10: =R10*VLOOKUP(O10,lifetable,4,FALSE) -> 0.71291686 | U10: =S10*VLOOKUP(O10,lifetable,5,FALSE) -> 0.68071508 | V10: =T10/(1+Disc)^N10 -> 0.68880856 | W10: =U10/(1+Disc)^N10 -> 0.65769573 | Y10: PS | Z10: =Z9/AB6 -> -0.086678615
A11: 2 | B11: 0.000132 | C11: 0.000125 | D11: =IF(util=1,F11,IF(util=2,H11,"err")) -> 0.94464086 | E11: =IF(util=1,G11,IF(util=2,I11,"err")) -> 0.91032568 | F11: 0.94464086 | G11: 0.91032568 | H11: =VLOOKUP($A11,$K$9:$M$26,2) -> 0.916 | I11: =VLOOKUP($A11,$K$9:$M$26,3) -> 0.881 | J11: 18-19 | K11: 18 | L11: 0.933 | M11: 0.864 | N11: 2 | O11: =Age+N11 -> 82 | P11: =P10-P10*VLOOKUP(O10,lifetable,2,FALSE) -> 0.89134133 | Q11: =Q10-Q10*VLOOKUP(O10,lifetable,3,FALSE) -> 0.92158582 | R11: =(P11+P12)/2 -> 0.8623255 | S11: =(Q11+Q12)/2 -> 0.89952121 | T11: =R11*VLOOKUP(O11,lifetable,4,FALSE) -> 0.66530723 | U11: =S11*VLOOKUP(O11,lifetable,5,FALSE) -> 0.64470683 | V11: =T11/(1+Disc)^N11 -> 0.62107142 | W11: =U11/(1+Disc)^N11 -> 0.60184072
A12: 3 | B12: 0.000102 | C12: 9.8e-05 | D12: =IF(util=1,F12,IF(util=2,H12,"err")) -> 0.94464086 | E12: =IF(util=1,G12,IF(util=2,I12,"err")) -> 0.91032568 | F12: 0.94464086 | G12: 0.91032568 | H12: =VLOOKUP($A12,$K$9:$M$26,2) -> 0.916 | I12: =VLOOKUP($A12,$K$9:$M$26,3) -> 0.881 | J12: 20-24 | K12: 20 | L12: 0.895 | M12: 0.866 | N12: 3 | O12: =Age+N12 -> 83 | P12: =P11-P11*VLOOKUP(O11,lifetable,2,FALSE) -> 0.83330966 | Q12: =Q11-Q11*VLOOKUP(O11,lifetable,3,FALSE) -> 0.8774566 | R12: =(P12+P13)/2 -> 0.80271262 | S12: =(Q12+Q13)/2 -> 0.85321686 | T12: =R12*VLOOKUP(O12,lifetable,4,FALSE) -> 0.61604618 | U12: =S12*VLOOKUP(O12,lifetable,5,FALSE) -> 0.60637058 | V12: =T12/(1+Disc)^N12 -> 0.55563836 | W12: =U12/(1+Disc)^N12 -> 0.54691153
A13: 4 | B13: 9.4e-05 | C13: 6.4e-05 | D13: =IF(util=1,F13,IF(util=2,H13,"err")) -> 0.94464086 | E13: =IF(util=1,G13,IF(util=2,I13,"err")) -> 0.91032568 | F13: 0.94464086 | G13: 0.91032568 | H13: =VLOOKUP($A13,$K$9:$M$26,2) -> 0.916 | I13: =VLOOKUP($A13,$K$9:$M$26,3) -> 0.881 | J13: 25-29 | K13: 25 | L13: 0.895 | M13: 0.873 | N13: 4 | O13: =Age+N13 -> 84 | P13: =P12-P12*VLOOKUP(O12,lifetable,2,FALSE) -> 0.77211557 | Q13: =Q12-Q12*VLOOKUP(O12,lifetable,3,FALSE) -> 0.82897712 | R13: =(P13+P14)/2 -> 0.73989094 | S13: =(Q13+Q14)/2 -> 0.80306993 | T13: =R13*VLOOKUP(O13,lifetable,4,FALSE) -> 0.56479616 | U13: =S13*VLOOKUP(O13,lifetable,5,FALSE) -> 0.56580125 | V13: =T13/(1+Disc)^N13 -> 0.49218723 | W13: =U13/(1+Disc)^N13 -> 0.4930631
A14: 5 | B14: 8.9e-05 | C14: 8.5e-05 | D14: =IF(util=1,F14,IF(util=2,H14,"err")) -> 0.94464086 | E14: =IF(util=1,G14,IF(util=2,I14,"err")) -> 0.91032568 | F14: 0.94464086 | G14: 0.91032568 | H14: =VLOOKUP($A14,$K$9:$M$26,2) -> 0.916 | I14: =VLOOKUP($A14,$K$9:$M$26,3) -> 0.881 | J14: 30-34 | K14: 30 | L14: 0.916 | M14: 0.87 | N14: 5 | O14: =Age+N14 -> 85 | P14: =P13-P13*VLOOKUP(O13,lifetable,2,FALSE) -> 0.70766631 | Q14: =Q13-Q13*VLOOKUP(O13,lifetable,3,FALSE) -> 0.77716274 | R14: =(P14+P15)/2 -> 0.67468411 | S14: =(Q14+Q15)/2 -> 0.7494157 | T14: =R14*VLOOKUP(O14,lifetable,4,FALSE) -> 0.51222931 | U14: =S14*VLOOKUP(O14,lifetable,5,FALSE) -> 0.52331962 | V14: =T14/(1+Disc)^N14 -> 0.43128333 | W14: =U14/(1+Disc)^N14 -> 0.44062108
A15: 6 | B15: 8.3e-05 | C15: 7.9e-05 | D15: =IF(util=1,F15,IF(util=2,H15,"err")) -> 0.94464086 | E15: =IF(util=1,G15,IF(util=2,I15,"err")) -> 0.91032568 | F15: 0.94464086 | G15: 0.91032568 | H15: =VLOOKUP($A15,$K$9:$M$26,2) -> 0.916 | I15: =VLOOKUP($A15,$K$9:$M$26,3) -> 0.881 | J15: 35-39 | K15: 35 | L15: 0.862 | M15: 0.857 | N15: 6 | O15: =Age+N15 -> 86 | P15: =P14-P14*VLOOKUP(O14,lifetable,2,FALSE) -> 0.6417019 | Q15: =Q14-Q14*VLOOKUP(O14,lifetable,3,FALSE) -> 0.72166866 | R15: =(P15+P16)/2 -> 0.60792079 | S15: =(Q15+Q16)/2 -> 0.69222277 | T15: =R15*VLOOKUP(O15,lifetable,4,FALSE) -> 0.45900812 | U15: =S15*VLOOKUP(O15,lifetable,5,FALSE) -> 0.47898684 | V15: =T15/(1+Disc)^N15 -> 0.3734034 | W15: =U15/(1+Disc)^N15 -> 0.3896561
A16: 7 | B16: 7.3e-05 | C16: 6.1e-05 | D16: =IF(util=1,F16,IF(util=2,H16,"err")) -> 0.94464086 | E16: =IF(util=1,G16,IF(util=2,I16,"err")) -> 0.91032568 | F16: 0.94464086 | G16: 0.91032568 | H16: =VLOOKUP($A16,$K$9:$M$26,2) -> 0.916 | I16: =VLOOKUP($A16,$K$9:$M$26,3) -> 0.881 | J16: 40-44 | K16: 40 | L16: 0.87 | M16: 0.85 | N16: 7 | O16: =Age+N16 -> 87 | P16: =P15-P15*VLOOKUP(O15,lifetable,2,FALSE) -> 0.57413968 | Q16: =Q15-Q15*VLOOKUP(O15,lifetable,3,FALSE) -> 0.66277688 | R16: =(P16+P17)/2 -> 0.5404595 | S16: =(Q16+Q17)/2 -> 0.63228385 | T16: =R16*VLOOKUP(O16,lifetable,4,FALSE) -> 0.40580367 | U16: =S16*VLOOKUP(O16,lifetable,5,FALSE) -> 0.43343209 | V16: =T16/(1+Disc)^N16 -> 0.31895802 | W16: =U16/(1+Disc)^N16 -> 0.3406737
A17: 8 | B17: 6.4e-05 | C17: 6.4e-05 | D17: =IF(util=1,F17,IF(util=2,H17,"err")) -> 0.94464086 | E17: =IF(util=1,G17,IF(util=2,I17,"err")) -> 0.91032568 | F17: 0.94464086 | G17: 0.91032568 | H17: =VLOOKUP($A17,$K$9:$M$26,2) -> 0.916 | I17: =VLOOKUP($A17,$K$9:$M$26,3) -> 0.881 | J17: 45-49 | K17: 45 | L17: 0.824 | M17: 0.815 | N17: 8 | O17: =Age+N17 -> 88 | P17: =P16-P16*VLOOKUP(O16,lifetable,2,FALSE) -> 0.50677931 | Q17: =Q16-Q16*VLOOKUP(O16,lifetable,3,FALSE) -> 0.60179081 | R17: =(P17+P18)/2 -> 0.4733899 | S17: =(Q17+Q18)/2 -> 0.57016851 | T17: =R17*VLOOKUP(O17,lifetable,4,FALSE) -> 0.35344501 | U17: =S17*VLOOKUP(O17,lifetable,5,FALSE) -> 0.38711452 | V17: =T17/(1+Disc)^N17 -> 0.26841022 | W17: =U17/(1+Disc)^N17 -> 0.29397924
A18: 9 | B18: 6.2e-05 | C18: 5.6e-05 | D18: =IF(util=1,F18,IF(util=2,H18,"err")) -> 0.94464086 | E18: =IF(util=1,G18,IF(util=2,I18,"err")) -> 0.91032568 | F18: 0.94464086 | G18: 0.91032568 | H18: =VLOOKUP($A18,$K$9:$M$26,2) -> 0.916 | I18: =VLOOKUP($A18,$K$9:$M$26,3) -> 0.881 | J18: 50-54 | K18: 50 | L18: 0.837 | M18: 0.805 | N18: 9 | O18: =Age+N18 -> 89 | P18: =P17-P17*VLOOKUP(O17,lifetable,2,FALSE) -> 0.4400005 | Q18: =Q17-Q17*VLOOKUP(O17,lifetable,3,FALSE) -> 0.5385462 | R18: =(P18+P19)/2 -> 0.4074024 | S18: =(Q18+Q19)/2 -> 0.50699251 | T18: =R18*VLOOKUP(O18,lifetable,4,FALSE) -> 0.30244591 | U18: =S18*VLOOKUP(O18,lifetable,5,FALSE) -> 0.34084694 | V18: =T18/(1+Disc)^N18 -> 0.22191393 | W18: =U18/(1+Disc)^N18 -> 0.25008996
A19: 10 | B19: 7.2e-05 | C19: 6.4e-05 | D19: =IF(util=1,F19,IF(util=2,H19,"err")) -> 0.94464086 | E19: =IF(util=1,G19,IF(util=2,I19,"err")) -> 0.91032568 | F19: 0.94464086 | G19: 0.91032568 | H19: =VLOOKUP($A19,$K$9:$M$26,2) -> 0.916 | I19: =VLOOKUP($A19,$K$9:$M$26,3) -> 0.881 | J19: 55-59 | K19: 55 | L19: 0.817 | M19: 0.802 | N19: 10 | O19: =Age+N19 -> 90 | P19: =P18-P18*VLOOKUP(O18,lifetable,2,FALSE) -> 0.3748043 | Q19: =Q18-Q18*VLOOKUP(O18,lifetable,3,FALSE) -> 0.47543882 | R19: =(P19+P20)/2 -> 0.34523449 | S19: =(Q19+Q20)/2 -> 0.44414972 | T19: =R19*VLOOKUP(O19,lifetable,4,FALSE) -> 0.25481885 | U19: =S19*VLOOKUP(O19,lifetable,5,FALSE) -> 0.2955982 | V19: =T19/(1+Disc)^N19 -> 0.18064588 | W19: =U19/(1+Disc)^N19 -> 0.20955512
A20: 11 | B20: 8.1e-05 | C20: 6.2e-05 | D20: =IF(util=1,F20,IF(util=2,H20,"err")) -> 0.94464086 | E20: =IF(util=1,G20,IF(util=2,I20,"err")) -> 0.91032568 | F20: 0.94464086 | G20: 0.91032568 | H20: =VLOOKUP($A20,$K$9:$M$26,2) -> 0.916 | I20: =VLOOKUP($A20,$K$9:$M$26,3) -> 0.881 | J20: 60-64 | K20: 60 | L20: 0.809 | M20: 0.784 | N20: 11 | O20: =Age+N20 -> 91 | P20: =P19-P19*VLOOKUP(O19,lifetable,2,FALSE) -> 0.31566468 | Q20: =Q19-Q19*VLOOKUP(O19,lifetable,3,FALSE) -> 0.41286061 | R20: =(P20+P21)/2 -> 0.28774525 | S20: =(Q20+Q21)/2 -> 0.38232338 | T20: =R20*VLOOKUP(O20,lifetable,4,FALSE) -> 0.21115023 | U20: =S20*VLOOKUP(O20,lifetable,5,FALSE) -> 0.25183122 | V20: =T20/(1+Disc)^N20 -> 0.14462644 | W20: =U20/(1+Disc)^N20 -> 0.17249072
A21: 12 | B21: 0.000105 | C21: 5.7e-05 | D21: =IF(util=1,F21,IF(util=2,H21,"err")) -> 0.94464086 | E21: =IF(util=1,G21,IF(util=2,I21,"err")) -> 0.91032568 | F21: 0.94464086 | G21: 0.91032568 | H21: =VLOOKUP($A21,$K$9:$M$26,2) -> 0.916 | I21: =VLOOKUP($A21,$K$9:$M$26,3) -> 0.881 | J21: 65-69 | K21: 65 | L21: 0.798 | M21: 0.782 | N21: 12 | O21: =Age+N21 -> 92 | P21: =P20-P20*VLOOKUP(O20,lifetable,2,FALSE) -> 0.25982581 | Q21: =Q20-Q20*VLOOKUP(O20,lifetable,3,FALSE) -> 0.35178614 | R21: =(P21+P22)/2 -> 0.23458373 | S21: =(Q21+Q22)/2 -> 0.3227323 | T21: =R21*VLOOKUP(O21,lifetable,4,FALSE) -> 0.17112795 | U21: =S21*VLOOKUP(O21,lifetable,5,FALSE) -> 0.21033832 | V21: =T21/(1+Disc)^N21 -> 0.11324962 | W21: =U21/(1+Disc)^N21 -> 0.13919839
A22: 13 | B22: 0.000125 | C22: 7.9e-05 | D22: =IF(util=1,F22,IF(util=2,H22,"err")) -> 0.94464086 | E22: =IF(util=1,G22,IF(util=2,I22,"err")) -> 0.91032568 | F22: 0.94464086 | G22: 0.91032568 | H22: =VLOOKUP($A22,$K$9:$M$26,2) -> 0.916 | I22: =VLOOKUP($A22,$K$9:$M$26,3) -> 0.881 | J22: 70-74 | K22: 70 | L22: 0.802 | M22: 0.787 | N22: 13 | O22: =Age+N22 -> 93 | P22: =P21-P21*VLOOKUP(O21,lifetable,2,FALSE) -> 0.20934165 | Q22: =Q21-Q21*VLOOKUP(O21,lifetable,3,FALSE) -> 0.29367846 | R22: =(P22+P23)/2 -> 0.18693864 | S22: =(Q22+Q23)/2 -> 0.26685108 | T22: =R22*VLOOKUP(O22,lifetable,4,FALSE) -> 0.13556154 | U22: =S22*VLOOKUP(O22,lifetable,5,FALSE) -> 0.17204126 | V22: =T22/(1+Disc)^N22 -> 0.086678608 | W22: =U22/(1+Disc)^N22 -> 0.1100039
... A26: 17 | B26: 0.000303 | C26: 0.000159 | D26: =IF(util=1,F26,IF(util=2,H26,"err")) -> 0.94333139 | E26: =IF(util=1,G26,IF(util=2,I26,"err")) -> 0.91087276 | F26: 0.94333139 | G26: 0.91087276 | H26: =VLOOKUP($A26,$K$9:$M$26,2) -> 0.916 | I26: =VLOOKUP($A26,$K$9:$M$26,3) -> 0.881 | J26: 90+ | K26: 90 | L26: 0.663 | M26: 0.665 | N26: 17 | O26: =Age+N26 -> 97 | P26: =P25-P25*VLOOKUP(O25,lifetable,2,FALSE) -> 0.065759168 | Q26: =Q25-Q25*VLOOKUP(O25,lifetable,3,FALSE) -> 0.11087082 | R26: =(P26+P27)/2 -> 0.055726358 | S26: =(Q26+Q27)/2 -> 0.096061805 | T26: =R26*VLOOKUP(O26,lifetable,4,FALSE) -> 0.0394389 | U26: =S26*VLOOKUP(O26,lifetable,5,FALSE) -> 0.059152745 | V26: =T26/(1+Disc)^N26 -> 0.021975504 | W26: =U26/(1+Disc)^N26 -> 0.032960133
A27: 18 | B27: 0.000387 | C27: 0.000211 | D27: =IF(util=1,F27,IF(util=2,H27,"err")) -> 0.94198997 | E27: =IF(util=1,G27,IF(util=2,I27,"err")) -> 0.911239 | F27: 0.94198997 | G27: 0.911239 | H27: =VLOOKUP($A27,$K$9:$M$26,2) -> 0.933 | I27: =VLOOKUP($A27,$K$9:$M$26,3) -> 0.864 | N27: 18 | O27: =Age+N27 -> 98 | P27: =P26-P26*VLOOKUP(O26,lifetable,2,FALSE) -> 0.045693547 | Q27: =Q26-Q26*VLOOKUP(O26,lifetable,3,FALSE) -> 0.081252789 | R27: =(P27+P28)/2 -> 0.038236338 | S27: =(Q27+Q28)/2 -> 0.069333452 | T27: =R27*VLOOKUP(O27,lifetable,4,FALSE) -> 0.026893427 | U27: =S27*VLOOKUP(O27,lifetable,5,FALSE) -> 0.042180875 | V27: =T27/(1+Disc)^N27 -> 0.014478376 | W27: =U27/(1+Disc)^N27 -> 0.022708544
A28: 19 | B28: 0.000415 | C28: 0.000194 | D28: =IF(util=1,F28,IF(util=2,H28,"err")) -> 0.94061612 | E28: =IF(util=1,G28,IF(util=2,I28,"err")) -> 0.9114333 | F28: 0.94061612 | G28: 0.9114333 | H28: =VLOOKUP($A28,$K$9:$M$26,2) -> 0.933 | I28: =VLOOKUP($A28,$K$9:$M$26,3) -> 0.864 | N28: 19 | O28: =Age+N28 -> 99 | P28: =P27-P27*VLOOKUP(O27,lifetable,2,FALSE) -> 0.030779128 | Q28: =Q27-Q27*VLOOKUP(O27,lifetable,3,FALSE) -> 0.057414115 | R28: =(P28+P29)/2 -> 0.025105534 | S28: =(Q28+Q29)/2 -> 0.048380635 | T28: =R28*VLOOKUP(O28,lifetable,4,FALSE) -> 0.017548004 | U28: =S28*VLOOKUP(O28,lifetable,5,FALSE) -> 0.029073073 | V28: =T28/(1+Disc)^N28 -> 0.0091276942 | W28: =U28/(1+Disc)^N28 -> 0.015122524
A29: 20 | B29: 0.000503 | C29: 0.000179 | D29: =IF(util=1,F29,IF(util=2,H29,"err")) -> 0.93920935 | E29: =IF(util=1,G29,IF(util=2,I29,"err")) -> 0.91146389 | F29: 0.93920935 | G29: 0.91146389 | H29: =VLOOKUP($A29,$K$9:$M$26,2) -> 0.895 | I29: =VLOOKUP($A29,$K$9:$M$26,3) -> 0.866 | N29: 20 | O29: =Age+N29 -> 100 | P29: =P28-P28*VLOOKUP(O28,lifetable,2,FALSE) -> 0.019431941 | Q29: =Q28-Q28*VLOOKUP(O28,lifetable,3,FALSE) -> 0.039347156 | R29: =(P29+P30)/2 -> 0.015661464 | S29: =(Q29+Q30)/2 -> 0.032455384 | T29: =R29*VLOOKUP(O29,lifetable,4,FALSE) -> 0.010878361 | U29: =S29*VLOOKUP(O29,lifetable,5,FALSE) -> 0.019259913 | V29: =T29/(1+Disc)^N29 -> 0.0054670929 | W29: =U29/(1+Disc)^N29 -> 0.009679375
A30: 21 | B30: 0.000498 | C30: 0.000201 | D30: =IF(util=1,F30,IF(util=2,H30,"err")) -> 0.93776916 | E30: =IF(util=1,G30,IF(util=2,I30,"err")) -> 0.91133843 | F30: 0.93776916 | G30: 0.91133843 | H30: =VLOOKUP($A30,$K$9:$M$26,2) -> 0.895 | I30: =VLOOKUP($A30,$K$9:$M$26,3) -> 0.866 | N30: 21 | O30: =Age+N30 -> 101 | P30: =P29-P29*VLOOKUP(O29,lifetable,2,FALSE) -> 0.011890987 | Q30: =Q29-Q29*VLOOKUP(O29,lifetable,3,FALSE) -> 0.025563611 | R30: =(P30+P31)/2 -> #N/A | S30: =(Q30+Q31)/2 -> #N/A | T30: =R30*VLOOKUP(O30,lifetable,4,FALSE) -> #N/A | U30: =S30*VLOOKUP(O30,lifetable,5,FALSE) -> #N/A | V30: =T30/(1+Disc)^N30 -> #N/A | W30: =U30/(1+Disc)^N30 -> #N/A
A31: 22 | B31: 0.000478 | C31: 0.000215 | D31: =IF(util=1,F31,IF(util=2,H31,"err")) -> 0.93629505 | E31: =IF(util=1,G31,IF(util=2,I31,"err")) -> 0.91106401 | F31: 0.93629505 | G31: 0.91106401 | H31: =VLOOKUP($A31,$K$9:$M$26,2) -> 0.895 | I31: =VLOOKUP($A31,$K$9:$M$26,3) -> 0.866 | N31: 22 | O31: =Age+N31 -> 102 | P31: =P30-P30*VLOOKUP(O30,lifetable,2,FALSE) -> #N/A | Q31: =Q30-Q30*VLOOKUP(O30,lifetable,3,FALSE) -> #N/A | R31: =(P31+P32)/2 -> #N/A | S31: =(Q31+Q32)/2 -> #N/A | T31: =R31*VLOOKUP(O31,lifetable,4,FALSE) -> #N/A | U31: =S31*VLOOKUP(O31,lifetable,5,FALSE) -> #N/A | V31: =T31/(1+Disc)^N31 -> #N/A | W31: =U31/(1+Disc)^N31 -> #N/A
A32: 23 | B32: 0.00047 | C32: 0.0002 | D32: =IF(util=1,F32,IF(util=2,H32,"err")) -> 0.93478653 | E32: =IF(util=1,G32,IF(util=2,I32,"err")) -> 0.91064718 | F32: 0.93478653 | G32: 0.91064718 | H32: =VLOOKUP($A32,$K$9:$M$26,2) -> 0.895 | I32: =VLOOKUP($A32,$K$9:$M$26,3) -> 0.866 | N32: 23 | O32: =Age+N32 -> 103 | P32: =P31-P31*VLOOKUP(O31,lifetable,2,FALSE) -> #N/A | Q32: =Q31-Q31*VLOOKUP(O31,lifetable,3,FALSE) -> #N/A | R32: =(P32+P33)/2 -> #N/A | S32: =(Q32+Q33)/2 -> #N/A | T32: =R32*VLOOKUP(O32,lifetable,4,FALSE) -> #N/A | U32: =S32*VLOOKUP(O32,lifetable,5,FALSE) -> #N/A | V32: =T32/(1+Disc)^N32 -> #N/A | W32: =U32/(1+Disc)^N32 -> #N/A
A33: 24 | B33: 0.000513 | C33: 0.000218 | D33: =IF(util=1,F33,IF(util=2,H33,"err")) -> 0.93324312 | E33: =IF(util=1,G33,IF(util=2,I33,"err")) -> 0.910094 | F33: 0.93324312 | G33: 0.910094 | H33: =VLOOKUP($A33,$K$9:$M$26,2) -> 0.895 | I33: =VLOOKUP($A33,$K$9:$M$26,3) -> 0.866 | N33: 24 | O33: =Age+N33 -> 104 | P33: =P32-P32*VLOOKUP(O32,lifetable,2,FALSE) -> #N/A | Q33: =Q32-Q32*VLOOKUP(O32,lifetable,3,FALSE) -> #N/A | R33: =(P33+P34)/2 -> #N/A | S33: =(Q33+Q34)/2 -> #N/A | T33: =R33*VLOOKUP(O33,lifetable,4,FALSE) -> #N/A | U33: =S33*VLOOKUP(O33,lifetable,5,FALSE) -> #N/A | V33: =T33/(1+Disc)^N33 -> #N/A | W33: =U33/(1+Disc)^N33 -> #N/A
A34: 25 | B34: 0.000538 | C34: 0.000244 | D34: =IF(util=1,F34,IF(util=2,H34,"err")) -> 0.93166431 | E34: =IF(util=1,G34,IF(util=2,I34,"err")) -> 0.90941003 | F34: 0.93166431 | G34: 0.90941003 | H34: =VLOOKUP($A34,$K$9:$M$26,2) -> 0.895 | I34: =VLOOKUP($A34,$K$9:$M$26,3) -> 0.873 | N34: 25 | O34: =Age+N34 -> 105 | P34: =P33-P33*VLOOKUP(O33,lifetable,2,FALSE) -> #N/A | Q34: =Q33-Q33*VLOOKUP(O33,lifetable,3,FALSE) -> #N/A | R34: =(P34+P35)/2 -> #N/A | S34: =(Q34+Q35)/2 -> #N/A | T34: =R34*VLOOKUP(O34,lifetable,4,FALSE) -> #N/A | U34: =S34*VLOOKUP(O34,lifetable,5,FALSE) -> #N/A | V34: =T34/(1+Disc)^N34 -> #N/A | W34: =U34/(1+Disc)^N34 -> #N/A
A35: 26 | B35: 0.000543 | C35: 0.000259 | D35: =IF(util=1,F35,IF(util=2,H35,"err")) -> 0.93004962 | E35: =IF(util=1,G35,IF(util=2,I35,"err")) -> 0.90860044 | F35: 0.93004962 | G35: 0.90860044 | H35: =VLOOKUP($A35,$K$9:$M$26,2) -> 0.895 | I35: =VLOOKUP($A35,$K$9:$M$26,3) -> 0.873 | N35: 26 | O35: =Age+N35 -> 106 | P35: =P34-P34*VLOOKUP(O34,lifetable,2,FALSE) -> #N/A | Q35: =Q34-Q34*VLOOKUP(O34,lifetable,3,FALSE) -> #N/A | R35: =(P35+P36)/2 -> #N/A | S35: =(Q35+Q36)/2 -> #N/A | T35: =R35*VLOOKUP(O35,lifetable,4,FALSE) -> #N/A | U35: =S35*VLOOKUP(O35,lifetable,5,FALSE) -> #N/A | V35: =T35/(1+Disc)^N35 -> #N/A | W35: =U35/(1+Disc)^N35 -> #N/A
A36: 27 | B36: 0.000574 | C36: 0.00027 | D36: =IF(util=1,F36,IF(util=2,H36,"err")) -> 0.92839856 | E36: =IF(util=1,G36,IF(util=2,I36,"err")) -> 0.90766993 | F36: 0.92839856 | G36: 0.90766993 | H36: =VLOOKUP($A36,$K$9:$M$26,2) -> 0.895 | I36: =VLOOKUP($A36,$K$9:$M$26,3) -> 0.873 | N36: 27 | O36: =Age+N36 -> 107 | P36: =P35-P35*VLOOKUP(O35,lifetable,2,FALSE) -> #N/A | Q36: =Q35-Q35*VLOOKUP(O35,lifetable,3,FALSE) -> #N/A | R36: =(P36+P37)/2 -> #N/A | S36: =(Q36+Q37)/2 -> #N/A | T36: =R36*VLOOKUP(O36,lifetable,4,FALSE) -> #N/A | U36: =S36*VLOOKUP(O36,lifetable,5,FALSE) -> #N/A | V36: =T36/(1+Disc)^N36 -> #N/A | W36: =U36/(1+Disc)^N36 -> #N/A
A37: 28 | B37: 0.000629 | C37: 0.000304 | D37: =IF(util=1,F37,IF(util=2,H37,"err")) -> 0.92671065 | E37: =IF(util=1,G37,IF(util=2,I37,"err")) -> 0.90662285 | F37: 0.92671065 | G37: 0.90662285 | H37: =VLOOKUP($A37,$K$9:$M$26,2) -> 0.895 | I37: =VLOOKUP($A37,$K$9:$M$26,3) -> 0.873 | N37: 28 | O37: =Age+N37 -> 108 | P37: =P36-P36*VLOOKUP(O36,lifetable,2,FALSE) -> #N/A | Q37: =Q36-Q36*VLOOKUP(O36,lifetable,3,FALSE) -> #N/A | R37: =(P37+P38)/2 -> #N/A | S37: =(Q37+Q38)/2 -> #N/A | T37: =R37*VLOOKUP(O37,lifetable,4,FALSE) -> #N/A | U37: =S37*VLOOKUP(O37,lifetable,5,FALSE) -> #N/A | V37: =T37/(1+Disc)^N37 -> #N/A | W37: =U37/(1+Disc)^N37 -> #N/A
A38: 29 | B38: 0.000664 | C38: 0.000302 | D38: =IF(util=1,F38,IF(util=2,H38,"err")) -> 0.92498541 | E38: =IF(util=1,G38,IF(util=2,I38,"err")) -> 0.90546319 | F38: 0.92498541 | G38: 0.90546319 | H38: =VLOOKUP($A38,$K$9:$M$26,2) -> 0.895 | I38: =VLOOKUP($A38,$K$9:$M$26,3) -> 0.873 | N38: 29 | O38: =Age+N38 -> 109 | P38: =P37-P37*VLOOKUP(O37,lifetable,2,FALSE) -> #N/A | Q38: =Q37-Q37*VLOOKUP(O37,lifetable,3,FALSE) -> #N/A | R38: =(P38+P39)/2 -> #N/A | S38: =(Q38+Q39)/2 -> #N/A | T38: =R38*VLOOKUP(O38,lifetable,4,FALSE) -> #N/A | U38: =S38*VLOOKUP(O38,lifetable,5,FALSE) -> #N/A | V38: =T38/(1+Disc)^N38 -> #N/A | W38: =U38/(1+Disc)^N38 -> #N/A
... A109: 100 | B109: 0.38807 | C109: 0.350306 | D109: =IF(util=1,F109,IF(util=2,H109,"err")) -> 0.6945941 | E109: =IF(util=1,G109,IF(util=2,I109,"err")) -> 0.59342736 | F109: 0.6945941 | G109: 0.59342736 | H109: =VLOOKUP($A109,$K$9:$M$26,2) -> 0.663 | I109: =VLOOKUP($A109,$K$9:$M$26,3) -> 0.665 | N109: 100 | O109: =Age+N109 -> 180 | P109: =P108-P108*VLOOKUP(O108,lifetable,2,FALSE) -> #N/A | Q109: =Q108-Q108*VLOOKUP(O108,lifetable,3,FALSE) -> #N/A | R109: =(P109+P110)/2 -> #N/A | S109: =(Q109+Q110)/2 -> #N/A | T109: =R109*VLOOKUP(O109,lifetable,4,FALSE) -> #N/A | U109: =S109*VLOOKUP(O109,lifetable,5,FALSE) -> #N/A | V109: =T109/(1+Disc)^N109 -> #N/A | W109: =U109/(1+Disc)^N109 -> #N/A
D110: =IF(util=1,F110,IF(util=2,H110,"err")) -> 0.69022425 | E110: =IF(util=1,G110,IF(util=2,I110,"err")) -> 0.58589766 | F110: 0.69022425 | G110: 0.58589766 | I110: =VLOOKUP($A110,$K$9:$M$26,3) -> 0.881

Sheet QALYsForUndiagnosedCancer (2)
B1: Undiagnosed Cancer
B2: Stage I | D2: Stage II | F2: Stage III | H2: Stage IV | Q2: Stage I | U2: Stage II | Y2: Stage III | AC2: Stage IV
A3: Age | B3: QALYs | C3: No. patients | D3: QALYs | E3: No. patients | F3: QALYs | G3: No. patients | H3: QALYs | I3: No. patients | K3: Total | L3: w/modifier | M3: % | N3: Value to paste into r | P3: Gen pop QALYs | Q3: Absolute shortfall | R3: Modifier | S3: Proportional shortfall | T3: Modifier | U3: Absolute shortfall | V3: Modifier | W3: Proportional shortfall | X3: Modifier | Y3: Absolute shortfall | Z3: Modifier | AA3: Proportional shortfall | AB3: Modifier | AC3: Absolute shortfall | AD3: Modifier | AE3: Proportional shortfall | AF3: Modifier
A4: 50 | B4: =(Stage4to1!J2+Stage3to1!J2+Stage2to1!J2+Stage1to1!J2)/(Stage4to1!F2+Stage3to1!F2+Stage2to1!F2+Stage1to1!F2) -> 5.4139755 | C4: =Stage4to1!F2+Stage3to1!F2+Stage2to1!F2+Stage1to1!F2 -> 83.160969 | D4: =(Stage4to1!K2+Stage3to1!K2+Stage2to1!K2+Stage1to1!K2+Stage4to2!K2+Stage3to2!K2+Stage2to2!K2)/(Stage4to1!G2+Stage3to1!G2+Stage2to1!G2+Stage1to1!G2+Stage4to2!G2+Stage3to2!G2+Stage2to2!G2) -> 3.3643994 | E4: =Stage4to1!G2+Stage3to1!G2+Stage2to1!G2+Stage1to1!G2+Stage4to2!G2+Stage3to2!G2+Stage2to2!G2 -> 67.108587 | F4: =(Stage4to1!L2+Stage3to1!L2+Stage2to1!L2+Stage1to1!L2+Stage4to2!L2+Stage3to2!L2+Stage2to2!L2+Stage4to3!L2+Stage3to3!L2)/(Stage4to1!H2+Stage3to1!H2+Stage2to1!H2+Stage1to1!H2+Stage4to2!H2+Stage3to2!H2+Stage2to2!H2+Stage4to3!H2+Stage3to3!H2) -> 1.9314957 | G4: =Stage4to1!H2+Stage3to1!H2+Stage2to1!H2+Stage1to1!H2+Stage4to2!H2+Stage3to2!H2+Stage2to2!H2+Stage4to3!H2+Stage3to3!H2 -> 74.421465 | H4: =(Stage4to1!M2+Stage3to1!M2+Stage2to1!M2+Stage1to1!M2+Stage4to2!M2+Stage3to2!M2+Stage2to2!M2+Stage4to3!M2+Stage3to3!M2+Stage4to4!M2)/(Stage4to1!I2+Stage3to1!I2+Stage2to1!I2+Stage1to1!I2+Stage4to2!I2+Stage3to2!I2+Stage2to2!I2+Stage4to3!I2+Stage3to3!I2+Stage4to4!I2) -> 0.77499481 | I4: =Stage4to1!I2+Stage3to1!I2+Stage2to1!I2+Stage1to1!I2+Stage4to2!I2+Stage3to2!I2+Stage2to2!I2+Stage4to3!I2+Stage3to3!I2+Stage4to4!I2 -> 83.02675 | K4: =SUM(C4+E4+G4+I4) -> 307.71777 | L4: =SUM(E4+G4+I4) -> 224.5568 | M4: =ROUND((L4/K4)*100, 1) -> 73 | N4: 73 | P4: 15.926122 | Q4: =P4-B4 -> 10.512146 | R4: =IF(Q4<12,1,IF(Q4<18,1.2,1.7)) -> 1 | S4: =Q4/P4 -> 0.66005689 | T4: =IF(S4<0.85,1,IF(S4<0.95,1.2,1.7)) -> 1 | U4: =P4-D4 -> 12.561723 | V4: =IF(U4<12,1,IF(U4<18,1.2,1.7)) -> 1.2 | W4: =U4/$P4 -> 0.78874962 | X4: =IF(W4<0.85,1,IF(W4<0.95,1.2,1.7)) -> 1 | Y4: =P4-F4 -> 13.994626 | Z4: =IF(Y4<12,1,IF(Y4<18,1.2,1.7)) -> 1.2 | AA4: =Y4/$P4 -> 0.87872153 | AB4: =IF(AA4<0.85,1,IF(AA4<0.95,1.2,1.7)) -> 1.2 | AC4: =P4-H4 -> 15.151127 | AD4: =IF(AC4<12,1,IF(AC4<18,1.2,1.7)) -> 1.2 | AE4: =AC4/P4 -> 0.95133813 | AF4: =IF(AE4<0.85,1,IF(AE4<0.95,1.2,1.7)) -> 1.7
A5: 51 | B5: =(Stage4to1!J3+Stage3to1!J3+Stage2to1!J3+Stage1to1!J3)/(Stage4to1!F3+Stage3to1!F3+Stage2to1!F3+Stage1to1!F3) -> 5.411537 | C5: =Stage4to1!F3+Stage3to1!F3+Stage2to1!F3+Stage1to1!F3 -> 83.007364 | D5: =(Stage4to1!K3+Stage3to1!K3+Stage2to1!K3+Stage1to1!K3+Stage4to2!K3+Stage3to2!K3+Stage2to2!K3)/(Stage4to1!G3+Stage3to1!G3+Stage2to1!G3+Stage1to1!G3+Stage4to2!G3+Stage3to2!G3+Stage2to2!G3) -> 3.3638337 | E5: =Stage4to1!G3+Stage3to1!G3+Stage2to1!G3+Stage1to1!G3+Stage4to2!G3+Stage3to2!G3+Stage2to2!G3 -> 67.052446 | F5: =(Stage4to1!L3+Stage3to1!L3+Stage2to1!L3+Stage1to1!L3+Stage4to2!L3+Stage3to2!L3+Stage2to2!L3+Stage4to3!L3+Stage3to3!L3)/(Stage4to1!H3+Stage3to1!H3+Stage2to1!H3+Stage1to1!H3+Stage4to2!H3+Stage3to2!H3+Stage2to2!H3+Stage4to3!H3+Stage3to3!H3) -> 1.9313139 | G5: =Stage4to1!H3+Stage3to1!H3+Stage2to1!H3+Stage1to1!H3+Stage4to2!H3+Stage3to2!H3+Stage2to2!H3+Stage4to3!H3+Stage3to3!H3 -> 74.393574 | H5: =(Stage4to1!M3+Stage3to1!M3+Stage2to1!M3+Stage1to1!M3+Stage4to2!M3+Stage3to2!M3+Stage2to2!M3+Stage4to3!M3+Stage3to3!M3+Stage4to4!M3)/(Stage4to1!I3+Stage3to1!I3+Stage2to1!I3+Stage1to1!I3+Stage4to2!I3+Stage3to2!I3+Stage2to2!I3+Stage4to3!I3+Stage3to3!I3+Stage4to4!I3) -> 0.77499679 | I5: =Stage4to1!I3+Stage3to1!I3+Stage2to1!I3+Stage1to1!I3+Stage4to2!I3+Stage3to2!I3+Stage2to2!I3+Stage4to3!I3+Stage3to3!I3+Stage4to4!I3 -> 83.02175 | K5: =SUM(C5+E5+G5+I5) -> 307.47513 | L5: =SUM(E5+G5+I5) -> 224.46777 | M5: =ROUND((L5/K5)*100, 1) -> 73 | N5: 73 | P5: 15.626547 | Q5: =P5-B5 -> 10.21501 | R5: =IF(Q5<12,1,IF(Q5<18,1.2,1.7)) -> 1 | S5: =Q5/P5 -> 0.65369591 | T5: =IF(S5<0.85,1,IF(S5<0.95,1.2,1.7)) -> 1 | U5: =P5-D5 -> 12.262713 | V5: =IF(U5<12,1,IF(U5<18,1.2,1.7)) -> 1.2 | W5: =U5/$P5 -> 0.78473595 | X5: =IF(W5<0.85,1,IF(W5<0.95,1.2,1.7)) -> 1 | Y5: =P5-F5 -> 13.695233 | Z5: =IF(Y5<12,1,IF(Y5<18,1.2,1.7)) -> 1.2 | AA5: =Y5/$P5 -> 0.87640815 | AB5: =IF(AA5<0.85,1,IF(AA5<0.95,1.2,1.7)) -> 1.2 | AC5: =P5-H5 -> 14.85155 | AD5: =IF(AC5<12,1,IF(AC5<18,1.2,1.7)) -> 1.2 | AE5: =AC5/P5 -> 0.95040511 | AF5: =IF(AE5<0.85,1,IF(AE5<0.95,1.2,1.7)) -> 1.7
A6: 52 | B6: =(Stage4to1!J4+Stage3to1!J4+Stage2to1!J4+Stage1to1!J4)/(Stage4to1!F4+Stage3to1!F4+Stage2to1!F4+Stage1to1!F4) -> 5.4088285 | C6: =Stage4to1!F4+Stage3to1!F4+Stage2to1!F4+Stage1to1!F4 -> 82.843185 | D6: =(Stage4to1!K4+Stage3to1!K4+Stage2to1!K4+Stage1to1!K4+Stage4to2!K4+Stage3to2!K4+Stage2to2!K4)/(Stage4to1!G4+Stage3to1!G4+Stage2to1!G4+Stage1to1!G4+Stage4to2!G4+Stage3to2!G4+Stage2to2!G4) -> 3.3631921 | E6: =Stage4to1!G4+Stage3to1!G4+Stage2to1!G4+Stage1to1!G4+Stage4to2!G4+Stage3to2!G4+Stage2to2!G4 -> 66.994927 | F6: =(Stage4to1!L4+Stage3to1!L4+Stage2to1!L4+Stage1to1!L4+Stage4to2!L4+Stage3to2!L4+Stage2to2!L4+Stage4to3!L4+Stage3to3!L4)/(Stage4to1!H4+Stage3to1!H4+Stage2to1!H4+Stage1to1!H4+Stage4to2!H4+Stage3to2!H4+Stage2to2!H4+Stage4to3!H4+Stage3to3!H4) -> 1.9311248 | G6: =Stage4to1!H4+Stage3to1!H4+Stage2to1!H4+Stage1to1!H4+Stage4to2!H4+Stage3to2!H4+Stage2to2!H4+Stage4to3!H4+Stage3to3!H4 -> 74.365733 | H6: =(Stage4to1!M4+Stage3to1!M4+Stage2to1!M4+Stage1to1!M4+Stage4to2!M4+Stage3to2!M4+Stage2to2!M4+Stage4to3!M4+Stage3to3!M4+Stage4to4!M4)/(Stage4to1!I4+Stage3to1!I4+Stage2to1!I4+Stage1to1!I4+Stage4to2!I4+Stage3to2!I4+Stage2to2!I4+Stage4to3!I4+Stage3to3!I4+Stage4to4!I4) -> 0.77499887 | I6: =Stage4to1!I4+Stage3to1!I4+Stage2to1!I4+Stage1to1!I4+Stage4to2!I4+Stage3to2!I4+Stage2to2!I4+Stage4to3!I4+Stage3to3!I4+Stage4to4!I4 -> 83.01674 | K6: =SUM(C6+E6+G6+I6) -> 307.22059 | L6: =SUM(G6+I6) -> 157.38247 | M6: =ROUND((L6/K6)*100, 1) -> 51.2 | N6: 51.2 | P6: 15.322131 | Q6: =P6-B6 -> 9.9133027 | R6: =IF(Q6<12,1,IF(Q6<18,1.2,1.7)) -> 1 | S6: =Q6/P6 -> 0.64699242 | T6: =IF(S6<0.85,1,IF(S6<0.95,1.2,1.7)) -> 1 | U6: =P6-D6 -> 11.958939 | V6: =IF(U6<12,1,IF(U6<18,1.2,1.7)) -> 1 | W6: =U6/$P6 -> 0.78050102 | X6: =IF(W6<0.85,1,IF(W6<0.95,1.2,1.7)) -> 1 | Y6: =P6-F6 -> 13.391006 | Z6: =IF(Y6<12,1,IF(Y6<18,1.2,1.7)) -> 1.2 | AA6: =Y6/$P6 -> 0.873965 | AB6: =IF(AA6<0.85,1,IF(AA6<0.95,1.2,1.7)) -> 1.2 | AC6: =P6-H6 -> 14.547132 | AD6: =IF(AC6<12,1,IF(AC6<18,1.2,1.7)) -> 1.2 | AE6: =AC6/P6 -> 0.94941964 | AF6: =IF(AE6<0.85,1,IF(AE6<0.95,1.2,1.7)) -> 1.2
A7: 53 | B7: =(Stage4to1!J5+Stage3to1!J5+Stage2to1!J5+Stage1to1!J5)/(Stage4to1!F5+Stage3to1!F5+Stage2to1!F5+Stage1to1!F5) -> 5.4058427 | C7: =Stage4to1!F5+Stage3to1!F5+Stage2to1!F5+Stage1to1!F5 -> 82.665124 | D7: =(Stage4to1!K5+Stage3to1!K5+Stage2to1!K5+Stage1to1!K5+Stage4to2!K5+Stage3to2!K5+Stage2to2!K5)/(Stage4to1!G5+Stage3to1!G5+Stage2to1!G5+Stage1to1!G5+Stage4to2!G5+Stage3to2!G5+Stage2to2!G5) -> 3.3624476 | E7: =Stage4to1!G5+Stage3to1!G5+Stage2to1!G5+Stage1to1!G5+Stage4to2!G5+Stage3to2!G5+Stage2to2!G5 -> 66.934889 | F7: =(Stage4to1!L5+Stage3to1!L5+Stage2to1!L5+Stage1to1!L5+Stage4to2!L5+Stage3to2!L5+Stage2to2!L5+Stage4to3!L5+Stage3to3!L5)/(Stage4to1!H5+Stage3to1!H5+Stage2to1!H5+Stage1to1!H5+Stage4to2!H5+Stage3to2!H5+Stage2to2!H5+Stage4to3!H5+Stage3to3!H5) -> 1.9308955 | G7: =Stage4to1!H5+Stage3to1!H5+Stage2to1!H5+Stage1to1!H5+Stage4to2!H5+Stage3to2!H5+Stage2to2!H5+Stage4to3!H5+Stage3to3!H5 -> 74.340291 | H7: =(Stage4to1!M5+Stage3to1!M5+Stage2to1!M5+Stage1to1!M5+Stage4to2!M5+Stage3to2!M5+Stage2to2!M5+Stage4to3!M5+Stage3to3!M5+Stage4to4!M5)/(Stage4to1!I5+Stage3to1!I5+Stage2to1!I5+Stage1to1!I5+Stage4to2!I5+Stage3to2!I5+Stage2to2!I5+Stage4to3!I5+Stage3to3!I5+Stage4to4!I5) -> 0.77500055 | I7: =Stage4to1!I5+Stage3to1!I5+Stage2to1!I5+Stage1to1!I5+Stage4to2!I5+Stage3to2!I5+Stage2to2!I5+Stage4to3!I5+Stage3to3!I5+Stage4to4!I5 -> 83.01287 | K7: =SUM(C7+E7+G7+I7) -> 306.95317 | L7: =SUM(G7+I7) -> 157.35316 | M7: =ROUND((L7/K7)*100, 1) -> 51.3 | N7: 51.3 | P7: 15.012754 | Q7: =P7-B7 -> 9.6069117 | R7: =IF(Q7<12,1,IF(Q7<18,1.2,1.7)) -> 1 | S7: =Q7/P7 -> 0.63991666 | T7: =IF(S7<0.85,1,IF(S7<0.95,1.2,1.7)) -> 1 | U7: =P7-D7 -> 11.650307 | V7: =IF(U7<12,1,IF(U7<18,1.2,1.7)) -> 1 | W7: =U7/$P7 -> 0.77602727 | X7: =IF(W7<0.85,1,IF(W7<0.95,1.2,1.7)) -> 1 | Y7: =P7-F7 -> 13.081859 | Z7: =IF(Y7<12,1,IF(Y7<18,1.2,1.7)) -> 1.2 | AA7: =Y7/$P7 -> 0.871383 | AB7: =IF(AA7<0.85,1,IF(AA7<0.95,1.2,1.7)) -> 1.2 | AC7: =P7-H7 -> 14.237754 | AD7: =IF(AC7<12,1,IF(AC7<18,1.2,1.7)) -> 1.2 | AE7: =AC7/P7 -> 0.94837719 | AF7: =IF(AE7<0.85,1,IF(AE7<0.95,1.2,1.7)) -> 1.2
A8: 54 | B8: =(Stage4to1!J6+Stage3to1!J6+Stage2to1!J6+Stage1to1!J6)/(Stage4to1!F6+Stage3to1!F6+Stage2to1!F6+Stage1to1!F6) -> 5.4026472 | C8: =Stage4to1!F6+Stage3to1!F6+Stage2to1!F6+Stage1to1!F6 -> 82.457876 | D8: =(Stage4to1!K6+Stage3to1!K6+Stage2to1!K6+Stage1to1!K6+Stage4to2!K6+Stage3to2!K6+Stage2to2!K6)/(Stage4to1!G6+Stage3to1!G6+Stage2to1!G6+Stage1to1!G6+Stage4to2!G6+Stage3to2!G6+Stage2to2!G6) -> 3.3616484 | E8: =Stage4to1!G6+Stage3to1!G6+Stage2to1!G6+Stage1to1!G6+Stage4to2!G6+Stage3to2!G6+Stage2to2!G6 -> 66.859255 | F8: =(Stage4to1!L6+Stage3to1!L6+Stage2to1!L6+Stage1to1!L6+Stage4to2!L6+Stage3to2!L6+Stage2to2!L6+Stage4to3!L6+Stage3to3!L6)/(Stage4to1!H6+Stage3to1!H6+Stage2to1!H6+Stage1to1!H6+Stage4to2!H6+Stage3to2!H6+Stage2to2!H6+Stage4to3!H6+Stage3to3!H6) -> 1.9306493 | G8: =Stage4to1!H6+Stage3to1!H6+Stage2to1!H6+Stage1to1!H6+Stage4to2!H6+Stage3to2!H6+Stage2to2!H6+Stage4to3!H6+Stage3to3!H6 -> 74.303095 | H8: =(Stage4to1!M6+Stage3to1!M6+Stage2to1!M6+Stage1to1!M6+Stage4to2!M6+Stage3to2!M6+Stage2to2!M6+Stage4to3!M6+Stage3to3!M6+Stage4to4!M6)/(Stage4to1!I6+Stage3to1!I6+Stage2to1!I6+Stage1to1!I6+Stage4to2!I6+Stage3to2!I6+Stage2to2!I6+Stage4to3!I6+Stage3to3!I6+Stage4to4!I6) -> 0.77500341 | I8: =Stage4to1!I6+Stage3to1!I6+Stage2to1!I6+Stage1to1!I6+Stage4to2!I6+Stage3to2!I6+Stage2to2!I6+Stage4to3!I6+Stage3to3!I6+Stage4to4!I6 -> 83.00619 | K8: =SUM(C8+E8+G8+I8) -> 306.62642 | L8: =SUM(G8+I8) -> 157.30928 | M8: =ROUND((L8/K8)*100, 1) -> 51.3 | N8: 51.3 | O8: =SUM(N4:N8)/5 -> 59.96 | P8: 14.697495 | Q8: =P8-B8 -> 9.2948479 | R8: =IF(Q8<12,1,IF(Q8<18,1.2,1.7)) -> 1 | S8: =Q8/P8 -> 0.63241034 | T8: =IF(S8<0.85,1,IF(S8<0.95,1.2,1.7)) -> 1 | U8: =P8-D8 -> 11.335847 | V8: =IF(U8<12,1,IF(U8<18,1.2,1.7)) -> 1 | W8: =U8/$P8 -> 0.77127746 | X8: =IF(W8<0.85,1,IF(W8<0.95,1.2,1.7)) -> 1 | Y8: =P8-F8 -> 12.766846 | Z8: =IF(Y8<12,1,IF(Y8<18,1.2,1.7)) -> 1.2 | AA8: =Y8/$P8 -> 0.86864093 | AB8: =IF(AA8<0.85,1,IF(AA8<0.95,1.2,1.7)) -> 1.2 | AC8: =P8-H8 -> 13.922492 | AD8: =IF(AC8<12,1,IF(AC8<18,1.2,1.7)) -> 1.2 | AE8: =AC8/P8 -> 0.94726969 | AF8: =IF(AE8<0.85,1,IF(AE8<0.95,1.2,1.7)) -> 1.2
A9: 55 | B9: =(Stage4to1!J7+Stage3to1!J7+Stage2to1!J7+Stage1to1!J7)/(Stage4to1!F7+Stage3to1!F7+Stage2to1!F7+Stage1to1!F7) -> 4.8899401 | C9: =Stage4to1!F7+Stage3to1!F7+Stage2to1!F7+Stage1to1!F7 -> 160.10683 | D9: =(Stage4to1!K7+Stage3to1!K7+Stage2to1!K7+Stage1to1!K7+Stage4to2!K7+Stage3to2!K7+Stage2to2!K7)/(Stage4to1!G7+Stage3to1!G7+Stage2to1!G7+Stage1to1!G7+Stage4to2!G7+Stage3to2!G7+Stage2to2!G7) -> 3.0963829 | E9: =Stage4to1!G7+Stage3to1!G7+Stage2to1!G7+Stage1to1!G7+Stage4to2!G7+Stage3to2!G7+Stage2to2!G7 -> 137.36778 | F9: =(Stage4to1!L7+Stage3to1!L7+Stage2to1!L7+Stage1to1!L7+Stage4to2!L7+Stage3to2!L7+Stage2to2!L7+Stage4to3!L7+Stage3to3!L7)/(Stage4to1!H7+Stage3to1!H7+Stage2to1!H7+Stage1to1!H7+Stage4to2!H7+Stage3to2!H7+Stage2to2!H7+Stage4to3!H7+Stage3to3!H7) -> 1.6412507 | G9: =Stage4to1!H7+Stage3to1!H7+Stage2to1!H7+Stage1to1!H7+Stage4to2!H7+Stage3to2!H7+Stage2to2!H7+Stage4to3!H7+Stage3to3!H7 -> 153.89336 | H9: =(Stage4to1!M7+Stage3to1!M7+Stage2to1!M7+Stage1to1!M7+Stage4to2!M7+Stage3to2!M7+Stage2to2!M7+Stage4to3!M7+Stage3to3!M7+Stage4to4!M7)/(Stage4to1!I7+Stage3to1!I7+Stage2to1!I7+Stage1to1!I7+Stage4to2!I7+Stage3to2!I7+Stage2to2!I7+Stage4to3!I7+Stage3to3!I7+Stage4to4!I7) -> 0.51606395 | I9: =Stage4to1!I7+Stage3to1!I7+Stage2to1!I7+Stage1to1!I7+Stage4to2!I7+Stage3to2!I7+Stage2to2!I7+Stage4to3!I7+Stage3to3!I7+Stage4to4!I7 -> 168.21613 | K9: =SUM(C9+E9+G9+I9) -> 619.5841 | L9: =SUM(G9+I9) -> 322.10949 | M9: =ROUND((L9/K9)*100, 1) -> 52 | N9: 52 | P9: 14.376846 | Q9: =P9-B9 -> 9.4869059 | R9: =IF(Q9<12,1,IF(Q9<18,1.2,1.7)) -> 1 | S9: =Q9/P9 -> 0.65987393 | T9: =IF(S9<0.85,1,IF(S9<0.95,1.2,1.7)) -> 1 | U9: =P9-D9 -> 11.280463 | V9: =IF(U9<12,1,IF(U9<18,1.2,1.7)) -> 1 | W9: =U9/$P9 -> 0.78462711 | X9: =IF(W9<0.85,1,IF(W9<0.95,1.2,1.7)) -> 1 | Y9: =P9-F9 -> 12.735595 | Z9: =IF(Y9<12,1,IF(Y9<18,1.2,1.7)) -> 1.2 | AA9: =Y9/$P9 -> 0.8858407 | AB9: =IF(AA9<0.85,1,IF(AA9<0.95,1.2,1.7)) -> 1.2 | AC9: =P9-H9 -> 13.860782 | AD9: =IF(AC9<12,1,IF(AC9<18,1.2,1.7)) -> 1.2 | AE9: =AC9/P9 -> 0.96410451 | AF9: =IF(AE9<0.85,1,IF(AE9<0.95,1.2,1.7)) -> 1.7
A10: 56 | B10: =(Stage4to1!J8+Stage3to1!J8+Stage2to1!J8+Stage1to1!J8)/(Stage4to1!F8+Stage3to1!F8+Stage2to1!F8+Stage1to1!F8) -> 4.8863548 | C10: =Stage4to1!F8+Stage3to1!F8+Stage2to1!F8+Stage1to1!F8 -> 159.67296 | D10: =(Stage4to1!K8+Stage3to1!K8+Stage2to1!K8+Stage1to1!K8+Stage4to2!K8+Stage3to2!K8+Stage2to2!K8)/(Stage4to1!G8+Stage3to1!G8+Stage2to1!G8+Stage1to1!G8+Stage4to2!G8+Stage3to2!G8+Stage2to2!G8) -> 3.0954621 | E10: =Stage4to1!G8+Stage3to1!G8+Stage2to1!G8+Stage1to1!G8+Stage4to2!G8+Stage3to2!G8+Stage2to2!G8 -> 137.20154 | F10: =(Stage4to1!L8+Stage3to1!L8+Stage2to1!L8+Stage1to1!L8+Stage4to2!L8+Stage3to2!L8+Stage2to2!L8+Stage4to3!L8+Stage3to3!L8)/(Stage4to1!H8+Stage3to1!H8+Stage2to1!H8+Stage1to1!H8+Stage4to2!H8+Stage3to2!H8+Stage2to2!H8+Stage4to3!H8+Stage3to3!H8) -> 1.6409388 | G10: =Stage4to1!H8+Stage3to1!H8+Stage2to1!H8+Stage1to1!H8+Stage4to2!H8+Stage3to2!H8+Stage2to2!H8+Stage4to3!H8+Stage3to3!H8 -> 153.82143 | H10: =(Stage4to1!M8+Stage3to1!M8+Stage2to1!M8+Stage1to1!M8+Stage4to2!M8+Stage3to2!M8+Stage2to2!M8+Stage4to3!M8+Stage3to3!M8+Stage4to4!M8)/(Stage4to1!I8+Stage3to1!I8+Stage2to1!I8+Stage1to1!I8+Stage4to2!I8+Stage3to2!I8+Stage2to2!I8+Stage4to3!I8+Stage3to3!I8+Stage4to4!I8) -> 0.51606555 | I10: =Stage4to1!I8+Stage3to1!I8+Stage2to1!I8+Stage1to1!I8+Stage4to2!I8+Stage3to2!I8+Stage2to2!I8+Stage4to3!I8+Stage3to3!I8+Stage4to4!I8 -> 168.20495 | K10: =SUM(C10+E10+G10+I10) -> 618.90087 | L10: =SUM(G10+I10) -> 322.02638 | M10: =ROUND((L10/K10)*100, 1) -> 52 | N10: 52 | P10: 14.05178 | Q10: =P10-B10 -> 9.1654254 | R10: =IF(Q10<12,1,IF(Q10<18,1.2,1.7)) -> 1 | S10: =Q10/P10 -> 0.6522608 | T10: =IF(S10<0.85,1,IF(S10<0.95,1.2,1.7)) -> 1 | U10: =P10-D10 -> 10.956318 | V10: =IF(U10<12,1,IF(U10<18,1.2,1.7)) -> 1 | W10: =U10/$P10 -> 0.77971032 | X10: =IF(W10<0.85,1,IF(W10<0.95,1.2,1.7)) -> 1 | Y10: =P10-F10 -> 12.410841 | Z10: =IF(Y10<12,1,IF(Y10<18,1.2,1.7)) -> 1.2 | AA10: =Y10/$P10 -> 0.883222 | AB10: =IF(AA10<0.85,1,IF(AA10<0.95,1.2,1.7)) -> 1.2 | AC10: =P10-H10 -> 13.535715 | AD10: =IF(AC10<12,1,IF(AC10<18,1.2,1.7)) -> 1.2 | AE10: =AC10/P10 -> 0.96327401 | AF10: =IF(AE10<0.85,1,IF(AE10<0.95,1.2,1.7)) -> 1.7
A11: 57 | B11: =(Stage4to1!J9+Stage3to1!J9+Stage2to1!J9+Stage1to1!J9)/(Stage4to1!F9+Stage3to1!F9+Stage2to1!F9+Stage1to1!F9) -> 4.8825314 | C11: =Stage4to1!F9+Stage3to1!F9+Stage2to1!F9+Stage1to1!F9 -> 159.17604 | D11: =(Stage4to1!K9+Stage3to1!K9+Stage2to1!K9+Stage1to1!K9+Stage4to2!K9+Stage3to2!K9+Stage2to2!K9)/(Stage4to1!G9+Stage3to1!G9+Stage2to1!G9+Stage1to1!G9+Stage4to2!G9+Stage3to2!G9+Stage2to2!G9) -> 3.0945244 | E11: =Stage4to1!G9+Stage3to1!G9+Stage2to1!G9+Stage1to1!G9+Stage4to2!G9+Stage3to2!G9+Stage2to2!G9 -> 136.99478 | F11: =(Stage4to1!L9+Stage3to1!L9+Stage2to1!L9+Stage1to1!L9+Stage4to2!L9+Stage3to2!L9+Stage2to2!L9+Stage4to3!L9+Stage3to3!L9)/(Stage4to1!H9+Stage3to1!H9+Stage2to1!H9+Stage1to1!H9+Stage4to2!H9+Stage3to2!H9+Stage2to2!H9+Stage4to3!H9+Stage3to3!H9) -> 1.6405746 | G11: =Stage4to1!H9+Stage3to1!H9+Stage2to1!H9+Stage1to1!H9+Stage4to2!H9+Stage3to2!H9+Stage2to2!H9+Stage4to3!H9+Stage3to3!H9 -> 153.72388 | H11: =(Stage4to1!M9+Stage3to1!M9+Stage2to1!M9+Stage1to1!M9+Stage4to2!M9+Stage3to2!M9+Stage2to2!M9+Stage4to3!M9+Stage3to3!M9+Stage4to4!M9)/(Stage4to1!I9+Stage3to1!I9+Stage2to1!I9+Stage1to1!I9+Stage4to2!I9+Stage3to2!I9+Stage2to2!I9+Stage4to3!I9+Stage3to3!I9+Stage4to4!I9) -> 0.51606779 | I11: =Stage4to1!I9+Stage3to1!I9+Stage2to1!I9+Stage1to1!I9+Stage4to2!I9+Stage3to2!I9+Stage2to2!I9+Stage4to3!I9+Stage3to3!I9+Stage4to4!I9 -> 168.18899 | K11: =SUM(C11+E11+G11+I11) -> 618.08369 | L11: =SUM(G11+I11) -> 321.91287 | M11: =ROUND((L11/K11)*100, 1) -> 52.1 | N11: 52.1 | P11: 13.723302 | Q11: =P11-B11 -> 8.8407701 | R11: =IF(Q11<12,1,IF(Q11<18,1.2,1.7)) -> 1 | S11: =Q11/P11 -> 0.64421598 | T11: =IF(S11<0.85,1,IF(S11<0.95,1.2,1.7)) -> 1 | U11: =P11-D11 -> 10.628777 | V11: =IF(U11<12,1,IF(U11<18,1.2,1.7)) -> 1 | W11: =U11/$P11 -> 0.77450584 | X11: =IF(W11<0.85,1,IF(W11<0.95,1.2,1.7)) -> 1 | Y11: =P11-F11 -> 12.082727 | Z11: =IF(Y11<12,1,IF(Y11<18,1.2,1.7)) -> 1.2 | AA11: =Y11/$P11 -> 0.88045336 | AB11: =IF(AA11<0.85,1,IF(AA11<0.95,1.2,1.7)) -> 1.2 | AC11: =P11-H11 -> 13.207234 | AD11: =IF(AC11<12,1,IF(AC11<18,1.2,1.7)) -> 1.2 | AE11: =AC11/P11 -> 0.96239478 | AF11: =IF(AE11<0.85,1,IF(AE11<0.95,1.2,1.7)) -> 1.7
A12: 58 | B12: =(Stage4to1!J10+Stage3to1!J10+Stage2to1!J10+Stage1to1!J10)/(Stage4to1!F10+Stage3to1!F10+Stage2to1!F10+Stage1to1!F10) -> 4.8784032 | C12: =Stage4to1!F10+Stage3to1!F10+Stage2to1!F10+Stage1to1!F10 -> 158.62801 | D12: =(Stage4to1!K10+Stage3to1!K10+Stage2to1!K10+Stage1to1!K10+Stage4to2!K10+Stage3to2!K10+Stage2to2!K10)/(Stage4to1!G10+Stage3to1!G10+Stage2to1!G10+Stage1to1!G10+Stage4to2!G10+Stage3to2!G10+Stage2to2!G10) -> 3.093607 | E12: =Stage4to1!G10+Stage3to1!G10+Stage2to1!G10+Stage1to1!G10+Stage4to2!G10+Stage3to2!G10+Stage2to2!G10 -> 136.75447 | F12: =(Stage4to1!L10+Stage3to1!L10+Stage2to1!L10+Stage1to1!L10+Stage4to2!L10+Stage3to2!L10+Stage2to2!L10+Stage4to3!L10+Stage3to3!L10)/(Stage4to1!H10+Stage3to1!H10+Stage2to1!H10+Stage1to1!H10+Stage4to2!H10+Stage3to2!H10+Stage2to2!H10+Stage4to3!H10+Stage3to3!H10) -> 1.6401896 | G12: =Stage4to1!H10+Stage3to1!H10+Stage2to1!H10+Stage1to1!H10+Stage4to2!H10+Stage3to2!H10+Stage2to2!H10+Stage4to3!H10+Stage3to3!H10 -> 153.6 | H12: =(Stage4to1!M10+Stage3to1!M10+Stage2to1!M10+Stage1to1!M10+Stage4to2!M10+Stage3to2!M10+Stage2to2!M10+Stage4to3!M10+Stage3to3!M10+Stage4to4!M10)/(Stage4to1!I10+Stage3to1!I10+Stage2to1!I10+Stage1to1!I10+Stage4to2!I10+Stage3to2!I10+Stage2to2!I10+Stage4to3!I10+Stage3to3!I10+Stage4to4!I10) -> 0.51607067 | I12: =Stage4to1!I10+Stage3to1!I10+Stage2to1!I10+Stage1to1!I10+Stage4to2!I10+Stage3to2!I10+Stage2to2!I10+Stage4to3!I10+Stage3to3!I10+Stage4to4!I10 -> 168.16724 | K12: =SUM(C12+E12+G12+I12) -> 617.14972 | L12: =SUM(G12+I12) -> 321.76724 | M12: =ROUND((L12/K12)*100, 1) -> 52.1 | N12: 52.1 | P12: 13.390654 | Q12: =P12-B12 -> 8.5122509 | R12: =IF(Q12<12,1,IF(Q12<18,1.2,1.7)) -> 1 | S12: =Q12/P12 -> 0.63568597 | T12: =IF(S12<0.85,1,IF(S12<0.95,1.2,1.7)) -> 1 | U12: =P12-D12 -> 10.297047 | V12: =IF(U12<12,1,IF(U12<18,1.2,1.7)) -> 1 | W12: =U12/$P12 -> 0.76897267 | X12: =IF(W12<0.85,1,IF(W12<0.95,1.2,1.7)) -> 1 | Y12: =P12-F12 -> 11.750465 | Z12: =IF(Y12<12,1,IF(Y12<18,1.2,1.7)) -> 1 | AA12: =Y12/$P12 -> 0.87751236 | AB12: =IF(AA12<0.85,1,IF(AA12<0.95,1.2,1.7)) -> 1.2 | AC12: =P12-H12 -> 12.874583 | AD12: =IF(AC12<12,1,IF(AC12<18,1.2,1.7)) -> 1.2 | AE12: =AC12/P12 -> 0.96146038 | AF12: =IF(AE12<0.85,1,IF(AE12<0.95,1.2,1.7)) -> 1.7
A13: 59 | B13: =(Stage4to1!J11+Stage3to1!J11+Stage2to1!J11+Stage1to1!J11)/(Stage4to1!F11+Stage3to1!F11+Stage2to1!F11+Stage1to1!F11) -> 4.8738861 | C13: =Stage4to1!F11+Stage3to1!F11+Stage2to1!F11+Stage1to1!F11 -> 158.0514 | D13: =(Stage4to1!K11+Stage3to1!K11+Stage2to1!K11+Stage1to1!K11+Stage4to2!K11+Stage3to2!K11+Stage2to2!K11)/(Stage4to1!G11+Stage3to1!G11+Stage2to1!G11+Stage1to1!G11+Stage4to2!G11+Stage3to2!G11+Stage2to2!G11) -> 3.0926566 | E13: =Stage4to1!G11+Stage3to1!G11+Stage2to1!G11+Stage1to1!G11+Stage4to2!G11+Stage3to2!G11+Stage2to2!G11 -> 136.5033 | F13: =(Stage4to1!L11+Stage3to1!L11+Stage2to1!L11+Stage1to1!L11+Stage4to2!L11+Stage3to2!L11+Stage2to2!L11+Stage4to3!L11+Stage3to3!L11)/(Stage4to1!H11+Stage3to1!H11+Stage2to1!H11+Stage1to1!H11+Stage4to2!H11+Stage3to2!H11+Stage2to2!H11+Stage4to3!H11+Stage3to3!H11) -> 1.6398208 | G13: =Stage4to1!H11+Stage3to1!H11+Stage2to1!H11+Stage1to1!H11+Stage4to2!H11+Stage3to2!H11+Stage2to2!H11+Stage4to3!H11+Stage3to3!H11 -> 153.46355 | H13: =(Stage4to1!M11+Stage3to1!M11+Stage2to1!M11+Stage1to1!M11+Stage4to2!M11+Stage3to2!M11+Stage2to2!M11+Stage4to3!M11+Stage3to3!M11+Stage4to4!M11)/(Stage4to1!I11+Stage3to1!I11+Stage2to1!I11+Stage1to1!I11+Stage4to2!I11+Stage3to2!I11+Stage2to2!I11+Stage4to3!I11+Stage3to3!I11+Stage4to4!I11) -> 0.51607408 | I13: =Stage4to1!I11+Stage3to1!I11+Stage2to1!I11+Stage1to1!I11+Stage4to2!I11+Stage3to2!I11+Stage2to2!I11+Stage4to3!I11+Stage3to3!I11+Stage4to4!I11 -> 168.1415 | K13: =SUM(C13+E13+G13+I13) -> 616.15976 | L13: =SUM(G13+I13) -> 321.60505 | M13: =ROUND((L13/K13)*100, 1) -> 52.2 | N13: 52.2 | O13: =SUM(N9:N13)/5 -> 52.08 | P13: 13.054301 | Q13: =P13-B13 -> 8.1804152 | R13: =IF(Q13<12,1,IF(Q13<18,1.2,1.7)) -> 1 | S13: =Q13/P13 -> 0.6266452 | T13: =IF(S13<0.85,1,IF(S13<0.95,1.2,1.7)) -> 1 | U13: =P13-D13 -> 9.9616446 | V13: =IF(U13<12,1,IF(U13<18,1.2,1.7)) -> 1 | W13: =U13/$P13 -> 0.7630929 | X13: =IF(W13<0.85,1,IF(W13<0.95,1.2,1.7)) -> 1 | Y13: =P13-F13 -> 11.414481 | Z13: =IF(Y13<12,1,IF(Y13<18,1.2,1.7)) -> 1 | AA13: =Y13/$P13 -> 0.87438464 | AB13: =IF(AA13<0.85,1,IF(AA13<0.95,1.2,1.7)) -> 1.2 | AC13: =P13-H13 -> 12.538227 | AD13: =IF(AC13<12,1,IF(AC13<18,1.2,1.7)) -> 1.2 | AE13: =AC13/P13 -> 0.96046712 | AF13: =IF(AE13<0.85,1,IF(AE13<0.95,1.2,1.7)) -> 1.7
A14: 60 | B14: =(Stage4to1!J12+Stage3to1!J12+Stage2to1!J12+Stage1to1!J12)/(Stage4to1!F12+Stage3to1!F12+Stage2to1!F12+Stage1to1!F12) -> 4.5401202 | C14: =Stage4to1!F12+Stage3to1!F12+Stage2to1!F12+Stage1to1!F12 -> 269.27558 | D14: =(Stage4to1!K12+Stage3to1!K12+Stage2to1!K12+Stage1to1!K12+Stage4to2!K12+Stage3to2!K12+Stage2to2!K12)/(Stage4to1!G12+Stage3to1!G12+Stage2to1!G12+Stage1to1!G12+Stage4to2!G12+Stage3to2!G12+Stage2to2!G12) -> 2.8277609 | E14: =Stage4to1!G12+Stage3to1!G12+Stage2to1!G12+Stage1to1!G12+Stage4to2!G12+Stage3to2!G12+Stage2to2!G12 -> 248.86187 | F14: =(Stage4to1!L12+Stage3to1!L12+Stage2to1!L12+Stage1to1!L12+Stage4to2!L12+Stage3to2!L12+Stage2to2!L12+Stage4to3!L12+Stage3to3!L12)/(Stage4to1!H12+Stage3to1!H12+Stage2to1!H12+Stage1to1!H12+Stage4to2!H12+Stage3to2!H12+Stage2to2!H12+Stage4to3!H12+Stage3to3!H12) -> 1.5759347 | G14: =Stage4to1!H12+Stage3to1!H12+Stage2to1!H12+Stage1to1!H12+Stage4to2!H12+Stage3to2!H12+Stage2to2!H12+Stage4to3!H12+Stage3to3!H12 -> 281.88747 | H14: =(Stage4to1!M12+Stage3to1!M12+Stage2to1!M12+Stage1to1!M12+Stage4to2!M12+Stage3to2!M12+Stage2to2!M12+Stage4to3!M12+Stage3to3!M12+Stage4to4!M12)/(Stage4to1!I12+Stage3to1!I12+Stage2to1!I12+Stage1to1!I12+Stage4to2!I12+Stage3to2!I12+Stage2to2!I12+Stage4to3!I12+Stage3to3!I12+Stage4to4!I12) -> 0.47441214 | I14: =Stage4to1!I12+Stage3to1!I12+Stage2to1!I12+Stage1to1!I12+Stage4to2!I12+Stage3to2!I12+Stage2to2!I12+Stage4to3!I12+Stage3to3!I12+Stage4to4!I12 -> 308.13969 | K14: =SUM(C14+E14+G14+I14) -> 1108.1646 | L14: =SUM(G14+I14) -> 590.02716 | M14: =ROUND((L14/K14)*100, 1) -> 53.2 | N14: 53.2 | P14: 12.713385 | Q14: =P14-B14 -> 8.1732643 | R14: =IF(Q14<12,1,IF(Q14<18,1.2,1.7)) -> 1 | S14: =Q14/P14 -> 0.64288658 | T14: =IF(S14<0.85,1,IF(S14<0.95,1.2,1.7)) -> 1 | U14: =P14-D14 -> 9.8856236 | V14: =IF(U14<12,1,IF(U14<18,1.2,1.7)) -> 1 | W14: =U14/$P14 -> 0.77757607 | X14: =IF(W14<0.85,1,IF(W14<0.95,1.2,1.7)) -> 1 | Y14: =P14-F14 -> 11.13745 | Z14: =IF(Y14<12,1,IF(Y14<18,1.2,1.7)) -> 1 | AA14: =Y14/$P14 -> 0.87604129 | AB14: =IF(AA14<0.85,1,IF(AA14<0.95,1.2,1.7)) -> 1.2 | AC14: =P14-H14 -> 12.238972 | AD14: =IF(AC14<12,1,IF(AC14<18,1.2,1.7)) -> 1.2 | AE14: =AC14/P14 -> 0.96268404 | AF14: =IF(AE14<0.85,1,IF(AE14<0.95,1.2,1.7)) -> 1.7
A15: 61 | B15: =(Stage4to1!J13+Stage3to1!J13+Stage2to1!J13+Stage1to1!J13)/(Stage4to1!F13+Stage3to1!F13+Stage2to1!F13+Stage1to1!F13) -> 4.5355354 | C15: =Stage4to1!F13+Stage3to1!F13+Stage2to1!F13+Stage1to1!F13 -> 268.28013 | D15: =(Stage4to1!K13+Stage3to1!K13+Stage2to1!K13+Stage1to1!K13+Stage4to2!K13+Stage3to2!K13+Stage2to2!K13)/(Stage4to1!G13+Stage3to1!G13+Stage2to1!G13+Stage1to1!G13+Stage4to2!G13+Stage3to2!G13+Stage2to2!G13) -> 2.8266546 | E15: =Stage4to1!G13+Stage3to1!G13+Stage2to1!G13+Stage1to1!G13+Stage4to2!G13+Stage3to2!G13+Stage2to2!G13 -> 248.41141 | F15: =(Stage4to1!L13+Stage3to1!L13+Stage2to1!L13+Stage1to1!L13+Stage4to2!L13+Stage3to2!L13+Stage2to2!L13+Stage4to3!L13+Stage3to3!L13)/(Stage4to1!H13+Stage3to1!H13+Stage2to1!H13+Stage1to1!H13+Stage4to2!H13+Stage3to2!H13+Stage2to2!H13+Stage4to3!H13+Stage3to3!H13) -> 1.5755451 | G15: =Stage4to1!H13+Stage3to1!H13+Stage2to1!H13+Stage1to1!H13+Stage4to2!H13+Stage3to2!H13+Stage2to2!H13+Stage4to3!H13+Stage3to3!H13 -> 281.65668 | H15: =(Stage4to1!M13+Stage3to1!M13+Stage2to1!M13+Stage1to1!M13+Stage4to2!M13+Stage3to2!M13+Stage2to2!M13+Stage4to3!M13+Stage3to3!M13+Stage4to4!M13)/(Stage4to1!I13+Stage3to1!I13+Stage2to1!I13+Stage1to1!I13+Stage4to2!I13+Stage3to2!I13+Stage2to2!I13+Stage4to3!I13+Stage3to3!I13+Stage4to4!I13) -> 0.47441486 | I15: =Stage4to1!I13+Stage3to1!I13+Stage2to1!I13+Stage1to1!I13+Stage4to2!I13+Stage3to2!I13+Stage2to2!I13+Stage4to3!I13+Stage3to3!I13+Stage4to4!I13 -> 308.09952 | K15: =SUM(C15+E15+G15+I15) -> 1106.4477 | L15: =SUM(G15+I15) -> 589.7562 | M15: =ROUND((L15/K15)*100, 1) -> 53.3 | N15: 53.3 | P15: 12.369371 | Q15: =P15-B15 -> 7.8338354 | R15: =IF(Q15<12,1,IF(Q15<18,1.2,1.7)) -> 1 | S15: =Q15/P15 -> 0.6333253 | T15: =IF(S15<0.85,1,IF(S15<0.95,1.2,1.7)) -> 1 | U15: =P15-D15 -> 9.5427161 | V15: =IF(U15<12,1,IF(U15<18,1.2,1.7)) -> 1 | W15: =U15/$P15 -> 0.77147951 | X15: =IF(W15<0.85,1,IF(W15<0.95,1.2,1.7)) -> 1 | Y15: =P15-F15 -> 10.793826 | Z15: =IF(Y15<12,1,IF(Y15<18,1.2,1.7)) -> 1 | AA15: =Y15/$P15 -> 0.87262528 | AB15: =IF(AA15<0.85,1,IF(AA15<0.95,1.2,1.7)) -> 1.2 | AC15: =P15-H15 -> 11.894956 | AD15: =IF(AC15<12,1,IF(AC15<18,1.2,1.7)) -> 1 | AE15: =AC15/P15 -> 0.961646 | AF15: =IF(AE15<0.85,1,IF(AE15<0.95,1.2,1.7)) -> 1.7
A16: 62 | B16: =(Stage4to1!J14+Stage3to1!J14+Stage2to1!J14+Stage1to1!J14)/(Stage4to1!F14+Stage3to1!F14+Stage2to1!F14+Stage1to1!F14) -> 4.5304877 | C16: =Stage4to1!F14+Stage3to1!F14+Stage2to1!F14+Stage1to1!F14 -> 267.1918 | D16: =(Stage4to1!K14+Stage3to1!K14+Stage2to1!K14+Stage1to1!K14+Stage4to2!K14+Stage3to2!K14+Stage2to2!K14)/(Stage4to1!G14+Stage3to1!G14+Stage2to1!G14+Stage1to1!G14+Stage4to2!G14+Stage3to2!G14+Stage2to2!G14) -> 2.8254764 | E16: =Stage4to1!G14+Stage3to1!G14+Stage2to1!G14+Stage1to1!G14+Stage4to2!G14+Stage3to2!G14+Stage2to2!G14 -> 247.91314 | F16: =(Stage4to1!L14+Stage3to1!L14+Stage2to1!L14+Stage1to1!L14+Stage4to2!L14+Stage3to2!L14+Stage2to2!L14+Stage4to3!L14+Stage3to3!L14)/(Stage4to1!H14+Stage3to1!H14+Stage2to1!H14+Stage1to1!H14+Stage4to2!H14+Stage3to2!H14+Stage2to2!H14+Stage4to3!H14+Stage3to3!H14) -> 1.5751291 | G16: =Stage4to1!H14+Stage3to1!H14+Stage2to1!H14+Stage1to1!H14+Stage4to2!H14+Stage3to2!H14+Stage2to2!H14+Stage4to3!H14+Stage3to3!H14 -> 281.39407 | H16: =(Stage4to1!M14+Stage3to1!M14+Stage2to1!M14+Stage1to1!M14+Stage4to2!M14+Stage3to2!M14+Stage2to2!M14+Stage4to3!M14+Stage3to3!M14+Stage4to4!M14)/(Stage4to1!I14+Stage3to1!I14+Stage2to1!I14+Stage1to1!I14+Stage4to2!I14+Stage3to2!I14+Stage2to2!I14+Stage4to3!I14+Stage3to3!I14+Stage4to4!I14) -> 0.47441805 | I16: =Stage4to1!I14+Stage3to1!I14+Stage2to1!I14+Stage1to1!I14+Stage4to2!I14+Stage3to2!I14+Stage2to2!I14+Stage4to3!I14+Stage3to3!I14+Stage4to4!I14 -> 308.05261 | K16: =SUM(C16+E16+G16+I16) -> 1104.5516 | L16: =SUM(G16+I16) -> 589.44668 | M16: =ROUND((L16/K16)*100, 1) -> 53.4 | N16: 53.4 | P16: 12.021493 | Q16: =P16-B16 -> 7.4910052 | R16: =IF(Q16<12,1,IF(Q16<18,1.2,1.7)) -> 1 | S16: =Q16/P16 -> 0.62313435 | T16: =IF(S16<0.85,1,IF(S16<0.95,1.2,1.7)) -> 1 | U16: =P16-D16 -> 9.1960165 | V16: =IF(U16<12,1,IF(U16<18,1.2,1.7)) -> 1 | W16: =U16/$P16 -> 0.7649646 | X16: =IF(W16<0.85,1,IF(W16<0.95,1.2,1.7)) -> 1 | Y16: =P16-F16 -> 10.446364 | Z16: =IF(Y16<12,1,IF(Y16<18,1.2,1.7)) -> 1 | AA16: =Y16/$P16 -> 0.86897392 | AB16: =IF(AA16<0.85,1,IF(AA16<0.95,1.2,1.7)) -> 1.2 | AC16: =P16-H16 -> 11.547075 | AD16: =IF(AC16<12,1,IF(AC16<18,1.2,1.7)) -> 1 | AE16: =AC16/P16 -> 0.96053585 | AF16: =IF(AE16<0.85,1,IF(AE16<0.95,1.2,1.7)) -> 1.7
A17: 63 | B17: =(Stage4to1!J15+Stage3to1!J15+Stage2to1!J15+Stage1to1!J15)/(Stage4to1!F15+Stage3to1!F15+Stage2to1!F15+Stage1to1!F15) -> 4.5247701 | C17: =Stage4to1!F15+Stage3to1!F15+Stage2to1!F15+Stage1to1!F15 -> 266.02138 | D17: =(Stage4to1!K15+Stage3to1!K15+Stage2to1!K15+Stage1to1!K15+Stage4to2!K15+Stage3to2!K15+Stage2to2!K15)/(Stage4to1!G15+Stage3to1!G15+Stage2to1!G15+Stage1to1!G15+Stage4to2!G15+Stage3to2!G15+Stage2to2!G15) -> 2.8241921 | E17: =Stage4to1!G15+Stage3to1!G15+Stage2to1!G15+Stage1to1!G15+Stage4to2!G15+Stage3to2!G15+Stage2to2!G15 -> 247.38523 | F17: =(Stage4to1!L15+Stage3to1!L15+Stage2to1!L15+Stage1to1!L15+Stage4to2!L15+Stage3to2!L15+Stage2to2!L15+Stage4to3!L15+Stage3to3!L15)/(Stage4to1!H15+Stage3to1!H15+Stage2to1!H15+Stage1to1!H15+Stage4to2!H15+Stage3to2!H15+Stage2to2!H15+Stage4to3!H15+Stage3to3!H15) -> 1.5746867 | G17: =Stage4to1!H15+Stage3to1!H15+Stage2to1!H15+Stage1to1!H15+Stage4to2!H15+Stage3to2!H15+Stage2to2!H15+Stage4to3!H15+Stage3to3!H15 -> 281.11706 | H17: =(Stage4to1!M15+Stage3to1!M15+Stage2to1!M15+Stage1to1!M15+Stage4to2!M15+Stage3to2!M15+Stage2to2!M15+Stage4to3!M15+Stage3to3!M15+Stage4to4!M15)/(Stage4to1!I15+Stage3to1!I15+Stage2to1!I15+Stage1to1!I15+Stage4to2!I15+Stage3to2!I15+Stage2to2!I15+Stage4to3!I15+Stage3to3!I15+Stage4to4!I15) -> 0.47442136 | I17: =Stage4to1!I15+Stage3to1!I15+Stage2to1!I15+Stage1to1!I15+Stage4to2!I15+Stage3to2!I15+Stage2to2!I15+Stage4to3!I15+Stage3to3!I15+Stage4to4!I15 -> 308.00312 | K17: =SUM(C17+E17+G17+I17) -> 1102.5268 | L17: =SUM(G17+I17) -> 589.12018 | M17: =ROUND((L17/K17)*100, 1) -> 53.4 | N17: 53.4 | P17: 11.673321 | Q17: =P17-B17 -> 7.1485512 | R17: =IF(Q17<12,1,IF(Q17<18,1.2,1.7)) -> 1 | S17: =Q17/P17 -> 0.61238366 | T17: =IF(S17<0.85,1,IF(S17<0.95,1.2,1.7)) -> 1 | U17: =P17-D17 -> 8.8491291 | V17: =IF(U17<12,1,IF(U17<18,1.2,1.7)) -> 1 | W17: =U17/$P17 -> 0.75806439 | X17: =IF(W17<0.85,1,IF(W17<0.95,1.2,1.7)) -> 1 | Y17: =P17-F17 -> 10.098635 | Z17: =IF(Y17<12,1,IF(Y17<18,1.2,1.7)) -> 1 | AA17: =Y17/$P17 -> 0.8651038 | AB17: =IF(AA17<0.85,1,IF(AA17<0.95,1.2,1.7)) -> 1.2 | AC17: =P17-H17 -> 11.1989 | AD17: =IF(AC17<12,1,IF(AC17<18,1.2,1.7)) -> 1 | AE17: =AC17/P17 -> 0.95935849 | AF17: =IF(AE17<0.85,1,IF(AE17<0.95,1.2,1.7)) -> 1.7
