Workbook
Name Age: 'AW calculator'!$B$5
Name Age: '[1]AW calculator'!$B$5
Name cohortSize: [2]Parameters!$E$15
Name compliance: [2]Parameters!$E$112:$E$117
Name compliance.PostDiag: [2]Parameters!$E$118:$E$123
Name Disc: 'AW calculator'!$B$3
Name Disc: '[1]AW calculator'!$B$3
Name discCost: [2]Parameters!$E$9
Name discHealth: [2]Parameters!$E$8
Name endAge: [2]Parameters!$E$12
Name Female: 'AW calculator'!$B$4
Name Female: '[1]AW calculator'!$B$4
Name genPopUtility: [2]Parameters!$E$1783:$E$1792
Name iatrogenicHarmUtility: [2]Parameters!$E$1793
Name incidenceStage1: '[2]Intermediate Calcs'!$F$18:$AA$68
Name incidenceStage2: '[2]Intermediate Calcs'!$F$76:$AA$126
Name incidenceStage3: '[2]Intermediate Calcs'!$F$134:$AA$184
Name incidenceStage4: '[2]Intermediate Calcs'!$F$192:$AA$242
Name IncludeCancer: [2]Settings!$F$38:$F$59
Name lifetable: 'AW calculator'!$A$9:$E$109
Name lifetable: '[1]AW calculator'!$A$9:$E$109
Name minAgeBand: [2]Parameters!$E$92:$E$101
Name percFemale: [2]Parameters!$E$14
Name rngPercIatrogenic: '[2]Survival Table'!$F$106:$CO$115
Name socCompliance: [2]Parameters!$E$46:$E$67
Name socSpecificity: [2]Parameters!$E$68:$E$89
Name socTestCosts: [2]Parameters!$E$24:$E$45
Name socTestEligibility: '[2]Intermediate Calcs'!$G$248:$G$269
Name startAge: [2]Parameters!$E$11
Name tblDeaths5y: '[2]Survival Table'!$F$25:$CO$34
Name tblSurvival: '[2]Survival Table'!$F$10:$CO$19
Name testCosts: [2]Parameters!$E$1118:$E$1121
Name testSpecificity: [2]Parameters!$E$90
Name timeHorizon: [2]Parameters!$E$13
Name timeIatrogenicHarm: [2]Parameters!$E$19
Name timeShift3To1: '[2]Time Shift Lookup'!$F$29:$Y$50
Name timeShift4To1: '[2]Time Shift Lookup'!$F$55:$Y$76
Name timeShift4To2: '[2]Time Shift Lookup'!$F$81:$Y$102
Name timeShiftDist: '[2]Time Shift Lookup'!$F$10:$Y$21
Name timeShiftDistMean: '[2]Time Shift Lookup'!$E$10:$E$21
Name util: 'AW calculator'!$E$3
Name util: '[1]AW calculator'!$E$3

Sheet Raw Lung Inc&Surv
A1: stage | B1: Age_band | C1: male_incidenceper100k | E1: male_mean_survival | F1: female_incidenceper100k | G1: female_mean_survival
A2: I | B2: 50-54 | C2: 4.434902 | D2: 0.772 | E2: 26.24 | F2: 4.434902 | G2: 28.64
A3: I | B3: 55-59 | C3: 10.150356 | D3: 0.69 | E3: 21.42 | F3: 10.150356 | G3: 23.38
A4: I | B4: 60-64 | C4: 20.912485 | D4: 0.674 | E4: 17.7 | F4: 20.912485 | G4: 19.41
A5: I | B5: 65-69 | C5: 35.53529 | D5: 0.643 | E5: 13.55 | F5: 35.53529 | G5: 14.89
A6: I | B6: 70-74 | C6: 56.038109 | D6: 0.549 | E6: 10.08 | F6: 56.038109 | G6: 11.06
A7: I | B7: 75-79 | C7: 71.974258 | D7: 0.479 | E7: 9.18 | F7: 71.974258 | G7: 10.17
A8: II | B8: 50-54 | C8: 1.856267 | D8: 0.469 | E8: 18.06 | F8: 1.856267 | G8: 20.43
A9: II | B9: 55-59 | C9: 4.507937 | D9: 0.525 | E9: 14.47 | F9: 4.507937 | G9: 17
A10: II | B10: 60-64 | C10: 9.623693 | D10: 0.484 | E10: 13.07 | F10: 9.623693 | G10: 13.39
A11: II | B11: 65-69 | C11: 15.235883 | D11: 0.39 | E11: 9.01 | F11: 15.235883 | G11: 9.86
A12: II | B12: 70-74 | C12: 23.261631 | D12: 0.312 | E12: 7.18 | F12: 23.261631 | G12: 7.61
A13: II | B13: 75-79 | C13: 30.003927 | D13: 0.27 | E13: 7.25 | F13: 30.003927 | G13: 8.22
... A25: IV | B25: 75-79 | C25: 169.87109 | D25: 0.018 | E25: 4.12 | F25: 169.87109 | G25: 4.46

Sheet Corrected Inc&Surv
A1: stage | B1: Age_band | C1: incidenceper100k | D1: 5-year_net_survival | E1: male_mean_survival | F1: female_mean_survival | G1: pooled_mean_survival
A2: I | B2: 50-54 | C2: 4.434902 | D2: 0.772 | E2: 26.24 | F2: 28.64 | G2: =SUM(E2*(1-0.53) + F2*0.53) -> 27.512
A3: I | B3: 55-59 | C3: 10.150356 | D3: 0.69 | E3: 21.42 | F3: 23.38 | G3: =SUM(E3*(1-0.53) + F3*0.53) -> 22.4588
A4: I | B4: 60-64 | C4: 20.912485 | D4: 0.674 | E4: 17.7 | F4: 19.41 | G4: =SUM(E4*(1-0.53) + F4*0.53) -> 18.6063
A5: I | B5: 65-69 | C5: 35.53529 | D5: 0.643 | E5: 13.55 | F5: 14.89 | G5: =SUM(E5*(1-0.53) + F5*0.53) -> 14.2602
A6: I | B6: 70-74 | C6: 56.038109 | D6: 0.549 | E6: 10.08 | F6: 11.06 | G6: =SUM(E6*(1-0.53) + F6*0.53) -> 10.5994
A7: I | B7: 75-79 | C7: 71.974258 | D7: 0.479 | E7: 9.18 | F7: 10.17 | G7: =SUM(E7*(1-0.53) + F7*0.53) -> 9.7047
A8: II | B8: 50-54 | C8: 1.856267 | D8: 0.469 | E8: 18.06 | F8: 20.43 | G8: =SUM(E8*(1-0.53) + F8*0.53) -> 19.3161
A9: II | B9: 55-59 | C9: 4.507937 | D9: 0.525 | E9: 14.47 | F9: 17 | G9: =SUM(E9*(1-0.53) + F9*0.53) -> 15.8109
A10: II | B10: 60-64 | C10: 9.623693 | D10: 0.484 | E10: 13.07 | F10: 13.39 | G10: =SUM(E10*(1-0.53) + F10*0.53) -> 13.2396
A11: II | B11: 65-69 | C11: 15.235883 | D11: 0.39 | E11: 9.01 | F11: 9.86 | G11: =SUM(E11*(1-0.53) + F11*0.53) -> 9.4605
A12: II | B12: 70-74 | C12: 23.261631 | D12: 0.312 | E12: 7.18 | F12: 7.61 | G12: =SUM(E12*(1-0.53) + F12*0.53) -> 7.4079
A13: II | B13: 75-79 | C13: 30.003927 | D13: 0.27 | E13: =E12 -> 7.18 | F13: =F12 -> 7.61 | G13: =SUM(E13*(1-0.53) + F13*0.53) -> 7.4079
A14: III | B14: 50-54 | C14: 6.715834 | D14: 0.235 | E14: 10.05 | F14: 10.83 | G14: =SUM(E14*(1-0.53) + F14*0.53) -> 10.4634
A15: III | B15: 55-59 | C15: 14.493369 | D15: 0.18 | E15: 7.57 | F15: 8.29 | G15: =SUM(E15*(1-0.53) + F15*0.53) -> 7.9516
A16: III | B16: 60-64 | C16: 26.96892 | D16: 0.175 | E16: 6.48 | F16: 6.97 | G16: =SUM(E16*(1-0.53) + F16*0.53) -> 6.7397
A17: III | B17: 65-69 | C17: 41.374767 | D17: 0.138 | E17: 4.51 | F17: 4.63 | G17: =SUM(E17*(1-0.53) + F17*0.53) -> 4.5736
A18: III | B18: 70-74 | C18: 58.420326 | D18: 0.112 | E18: 3.46 | F18: 3.7 | G18: =SUM(E18*(1-0.53) + F18*0.53) -> 3.5872
A19: III | B19: 75-79 | C19: 73.279182 | D19: 0.096 | E19: =E18 -> 3.46 | F19: =F18 -> 3.7 | G19: =SUM(E19*(1-0.53) + F19*0.53) -> 3.5872
A20: IV | B20: 50-54 | C20: 17.516331 | D20: 0.055 | E20: 3.06 | F20: 2.87 | G20: =SUM(E20*(1-0.53) + F20*0.53) -> 2.9593
A21: IV | B21: 55-59 | C21: 35.513752 | D21: 0.045 | E21: 2.2 | F21: 2.34 | G21: =SUM(E21*(1-0.53) + F21*0.53) -> 2.2742
A22: IV | B22: 60-64 | C22: 65.085518 | D22: 0.035 | E22: 1.83 | F22: 1.94 | G22: =SUM(E22*(1-0.53) + F22*0.53) -> 1.8883
A23: IV | B23: 65-69 | C23: 99.622284 | D23: 0.027 | E23: 1.39 | F23: 1.51 | G23: =SUM(E23*(1-0.53) + F23*0.53) -> 1.4536
A24: IV | B24: 70-74 | C24: 138.44875 | D24: 0.023 | E24: 1.14 | F24: 1.28 | G24: =SUM(E24*(1-0.53) + F24*0.53) -> 1.2142
A25: IV | B25: 75-79 | C25: 169.87109 | D25: 0.018 | E25: =E24 -> 1.14 | F25: =F24 -> 1.28 | G25: =SUM(E25*(1-0.53) + F25*0.53) -> 1.2142

Sheet AW calculator
A1: NICE DSU Severity calculator - Allan Wailoo, Paul Tappenden. | N1: Calculations | Y1: Output
A2: USER INPUT VALUES | J2: Output | Z2: Males | AA2: Females | AB2: overall
A3: Discount rate | B3: 0.035 | D3: Utility source | E3: 1 | F3: (1= Hernandez 3L, 2 = PT source) | J3: AS | K3: =Z9 -> -0.48098126 | Y3: Life years | Z3: =SUMIF(P9:P109,"<>#N/A") -> 9.0301057 | AA3: =SUMIF(Q9:Q109,"<>#N/A") -> 10.319695 | AB3: =(Z3*(1-Female))+(AA3*Female) -> 9.713588
A4: Proportion female | B4: 0.53 | D4: Comparator QALE | E4: 6.03 | J4: PS | K4: =Z10 -> -0.086678615 | Y4: 1/2 cycle adjusted | Z4: =SUMIF(R9:R109,"<>#N/A") -> 8.5241602 | AA4: =SUMIF(S9:S109,"<>#N/A") -> 9.8069132 | AB4: =(Z4*(1-Female))+(AA4*Female) -> 9.2040193
A5: Starting age | B5: 80 | Y5: QALYs | Z5: =SUMIF(T9:T109,"<>#N/A") -> 6.4574922 | AA5: =SUMIF(U9:U109,"<>#N/A") -> 6.7805385 | AB5: =(Z5*(1-Female))+(AA5*Female) -> 6.6287067
A6: National Life Tables, England, period expectation of life, based on data for the years 2017-2019 | J6: Age-specific utility (from paper) | Y6: Disc QALYs | Z6: =SUMIF(V9:V109,"<>#N/A") -> 5.4506503 | AA6: =SUMIF(W9:W109,"<>#N/A") -> 5.6362511 | AB6: =(Z6*(1-Female))+(AA6*Female) -> 5.5490187
B7: male | C7: female | D7: Active utility | F7: male | G7: female | H7: PT | P7: Proportion alive at the beginning of the period | R7: 1/2 cycle adjust | T7: utilities | V7: discounted | Y7: check | Z7: =SUM(P9:P47) -> #N/A | AA7: =SUM(Q9:Q47) -> #N/A | AB7: =Z7*(1-Female)+AA7*Female -> #N/A
A8: age | B8: qx | C8: qx | D8: Male | E8: female | F8: utility_m4 | G8: utility_f4 | H8: Male | I8: Female | J8: Age cat | K8: Cat low bound | L8: Males | M8: Females | N8: Year | O8: Age | P8: Alive males | Q8: Alive females | R8: males | S8: females | T8: males | U8: females | V8: males | W8: females
A9: 0 | B9: 0.004312 | C9: 0.003576 | D9: =IF(util=1,F9,IF(util=2,H9,"err")) -> 0.94464086 | E9: =IF(util=1,G9,IF(util=2,I9,"err")) -> 0.91032568 | F9: 0.94464086 | G9: 0.91032568 | H9: =VLOOKUP($A9,$K$9:$M$26,2) -> 0.916 | I9: =VLOOKUP($A9,$K$9:$M$26,3) -> 0.881 | J9: 0-15 | K9: 0 | L9: =L10 -> 0.916 | M9: =M10 -> 0.881 | N9: 0 | O9: =Age+N9 -> 80 | P9: 1 | Q9: 1 | R9: =(P9+P10)/2 -> 0.973554 | S9: =(Q9+Q10)/2 -> 0.981175 | T9: =R9*VLOOKUP(O9,lifetable,4,FALSE) -> 0.75894717 | U9: =S9*VLOOKUP(O9,lifetable,5,FALSE) -> 0.71476395 | V9: =T9/(1+Disc)^N9 -> 0.75894717 | W9: =U9/(1+Disc)^N9 -> 0.71476395 | Y9: AS | Z9: =AB6-E4 -> -0.48098126
A10: 1 | B10: 0.000242 | C10: 0.000213 | D10: =IF(util=1,F10,IF(util=2,H10,"err")) -> 0.94464086 | E10: =IF(util=1,G10,IF(util=2,I10,"err")) -> 0.91032568 | F10: 0.94464086 | G10: 0.91032568 | H10: =VLOOKUP($A10,$K$9:$M$26,2) -> 0.916 | I10: =VLOOKUP($A10,$K$9:$M$26,3) -> 0.881 | J10: 16-17 | K10: 16 | L10: 0.916 | M10: 0.881 | N10: 1 | O10: =Age+N10 -> 81 | P10: =P9-P9*VLOOKUP(O9,lifetable,2,FALSE) -> 0.947108 | Q10: =Q9-Q9*VLOOKUP(O9,lifetable,3,FALSE) -> 0.96235 | R10: =(P10+P11)/2 -> 0.91922467 | S10: =(Q10+Q11)/2 -> 0.94196791 | T10: =R10*VLOOKUP(O10,lifetable,4,FALSE) -> 0.71291686 | U10: =S10*VLOOKUP(O10,lifetable,5,FALSE) -> 0.68071508 | V10: =T10/(1+Disc)^N10 -> 0.68880856 | W10: =U10/(1+Disc)^N10 -> 0.65769573 | Y10: PS | Z10: =Z9/AB6 -> -0.086678615
A11: 2 | B11: 0.000132 | C11: 0.000125 | D11: =IF(util=1,F11,IF(util=2,H11,"err")) -> 0.94464086 | E11: =IF(util=1,G11,IF(util=2,I11,"err")) -> 0.91032568 | F11: 0.94464086 | G11: 0.91032568 | H11: =VLOOKUP($A11,$K$9:$M$26,2) -> 0.916 | I11: =VLOOKUP($A11,$K$9:$M$26,3) -> 0.881 | J11: 18-19 | K11: 18 | L11: 0.933 | M11: 0.864 | N11: 2 | O11: =Age+N11 -> 82 | P11: =P10-P10*VLOOKUP(O10,lifetable,2,FALSE) -> 0.89134133 | Q11: =Q10-Q10*VLOOKUP(O10,lifetable,3,FALSE) -> 0.92158582 | R11: =(P11+P12)/2 -> 0.8623255 | S11: =(Q11+Q12)/2 -> 0.89952121 | T11: =R11*VLOOKUP(O11,lifetable,4,FALSE) -> 0.66530723 | U11: =S11*VLOOKUP(O11,lifetable,5,FALSE) -> 0.64470683 | V11: =T11/(1+Disc)^N11 -> 0.62107142 | W11: =U11/(1+Disc)^N11 -> 0.60184072
A12: 3 | B12: 0.000102 | C12: 9.8e-05 | D12: =IF(util=1,F12,IF(util=2,H12,"err")) -> 0.94464086 | E12: =IF(util=1,G12,IF(util=2,I12,"err")) -> 0.91032568 | F12: 0.94464086 | G12: 0.91032568 | H12: =VLOOKUP($A12,$K$9:$M$26,2) -> 0.916 | I12: =VLOOKUP($A12,$K$9:$M$26,3) -> 0.881 | J12: 20-24 | K12: 20 | L12: 0.895 | M12: 0.866 | N12: 3 | O12: =Age+N12 -> 83 | P12: =P11-P11*VLOOKUP(O11,lifetable,2,FALSE) -> 0.83330966 | Q12: =Q11-Q11*VLOOKUP(O11,lifetable,3,FALSE) -> 0.8774566 | R12: =(P12+P13)/2 -> 0.80271262 | S12: =(Q12+Q13)/2 -> 0.85321686 | T12: =R12*VLOOKUP(O12,lifetable,4,FALSE) -> 0.61604618 | U12: =S12*VLOOKUP(O12,lifetable,5,FALSE) -> 0.60637058 | V12: =T12/(1+Disc)^N12 -> 0.55563836 | W12: =U12/(1+Disc)^N12 -> 0.54691153
A13: 4 | B13: 9.4e-05 | C13: 6.4e-05 | D13: =IF(util=1,F13,IF(util=2,H13,"err")) -> 0.94464086 | E13: =IF(util=1,G13,IF(util=2,I13,"err")) -> 0.91032568 | F13: 0.94464086 | G13: 0.91032568 | H13: =VLOOKUP($A13,$K$9:$M$26,2) -> 0.916 | I13: =VLOOKUP($A13,$K$9:$M$26,3) -> 0.881 | J13: 25-29 | K13: 25 | L13: 0.895 | M13: 0.873 | N13: 4 | O13: =Age+N13 -> 84 | P13: =P12-P12*VLOOKUP(O12,lifetable,2,FALSE) -> 0.77211557 | Q13: =Q12-Q12*VLOOKUP(O12,lifetable,3,FALSE) -> 0.82897712 | R13: =(P13+P14)/2 -> 0.73989094 | S13: =(Q13+Q14)/2 -> 0.80306993 | T13: =R13*VLOOKUP(O13,lifetable,4,FALSE) -> 0.56479616 | U13: =S13*VLOOKUP(O13,lifetable,5,FALSE) -> 0.56580125 | V13: =T13/(1+Disc)^N13 -> 0.49218723 | W13: =U13/(1+Disc)^N13 -> 0.4930631
A14: 5 | B14: 8.9e-05 | C14: 8.5e-05 | D14: =IF(util=1,F14,IF(util=2,H14,"err")) -> 0.94464086 | E14: =IF(util=1,G14,IF(util=2,I14,"err")) -> 0.91032568 | F14: 0.94464086 | G14: 0.91032568 | H14: =VLOOKUP($A14,$K$9:$M$26,2) -> 0.916 | I14: =VLOOKUP($A14,$K$9:$M$26,3) -> 0.881 | J14: 30-34 | K14: 30 | L14: 0.916 | M14: 0.87 | N14: 5 | O14: =Age+N14 -> 85 | P14: =P13-P13*VLOOKUP(O13,lifetable,2,FALSE) -> 0.70766631 | Q14: =Q13-Q13*VLOOKUP(O13,lifetable,3,FALSE) -> 0.77716274 | R14: =(P14+P15)/2 -> 0.67468411 | S14: =(Q14+Q15)/2 -> 0.7494157 | T14: =R14*VLOOKUP(O14,lifetable,4,FALSE) -> 0.51222931 | U14: =S14*VLOOKUP(O14,lifetable,5,FALSE) -> 0.52331962 | V14: =T14/(1+Disc)^N14 -> 0.43128333 | W14: =U14/(1+Disc)^N14 -> 0.44062108
A15: 6 | B15: 8.3e-05 | C15: 7.9e-05 | D15: =IF(util=1,F15,IF(util=2,H15,"err")) -> 0.94464086 | E15: =IF(util=1,G15,IF(util=2,I15,"err")) -> 0.91032568 | F15: 0.94464086 | G15: 0.91032568 | H15: =VLOOKUP($A15,$K$9:$M$26,2) -> 0.916 | I15: =VLOOKUP($A15,$K$9:$M$26,3) -> 0.881 | J15: 35-39 | K15: 35 | L15: 0.862 | M15: 0.857 | N15: 6 | O15: =Age+N15 -> 86 | P15: =P14-P14*VLOOKUP(O14,lifetable,2,FALSE) -> 0.6417019 | Q15: =Q14-Q14*VLOOKUP(O14,lifetable,3,FALSE) -> 0.72166866 | R15: =(P15+P16)/2 -> 0.60792079 | S15: =(Q15+Q16)/2 -> 0.69222277 | T15: =R15*VLOOKUP(O15,lifetable,4,FALSE) -> 0.45900812 | U15: =S15*VLOOKUP(O15,lifetable,5,FALSE) -> 0.47898684 | V15: =T15/(1+Disc)^N15 -> 0.3734034 | W15: =U15/(1+Disc)^N15 -> 0.3896561
A16: 7 | B16: 7.3e-05 | C16: 6.1e-05 | D16: =IF(util=1,F16,IF(util=2,H16,"err")) -> 0.94464086 | E16: =IF(util=1,G16,IF(util=2,I16,"err")) -> 0.91032568 | F16: 0.94464086 | G16: 0.91032568 | H16: =VLOOKUP($A16,$K$9:$M$26,2) -> 0.916 | I16: =VLOOKUP($A16,$K$9:$M$26,3) -> 0.881 | J16: 40-44 | K16: 40 | L16: 0.87 | M16: 0.85 | N16: 7 | O16: =Age+N16 -> 87 | P16: =P15-P15*VLOOKUP(O15,lifetable,2,FALSE) -> 0.57413968 | Q16: =Q15-Q15*VLOOKUP(O15,lifetable,3,FALSE) -> 0.66277688 | R16: =(P16+P17)/2 -> 0.5404595 | S16: =(Q16+Q17)/2 -> 0.63228385 | T16: =R16*VLOOKUP(O16,lifetable,4,FALSE) -> 0.40580367 | U16: =S16*VLOOKUP(O16,lifetable,5,FALSE) -> 0.43343209 | V16: =T16/(1+Disc)^N16 -> 0.31895802 | W16: =U16/(1+Disc)^N16 -> 0.3406737
A17: 8 | B17: 6.4e-05 | C17: 6.4e-05 | D17: =IF(util=1,F17,IF(util=2,H17,"err")) -> 0.94464086 | E17: =IF(util=1,G17,IF(util=2,I17,"err")) -> 0.91032568 | F17: 0.94464086 | G17: 0.91032568 | H17: =VLOOKUP($A17,$K$9:$M$26,2) -> 0.916 | I17: =VLOOKUP($A17,$K$9:$M$26,3) -> 0.881 | J17: 45-49 | K17: 45 | L17: 0.824 | M17: 0.815 | N17: 8 | O17: =Age+N17 -> 88 | P17: =P16-P16*VLOOKUP(O16,lifetable,2,FALSE) -> 0.50677931 | Q17: =Q16-Q16*VLOOKUP(O16,lifetable,3,FALSE) -> 0.60179081 | R17: =(P17+P18)/2 -> 0.4733899 | S17: =(Q17+Q18)/2 -> 0.57016851 | T17: =R17*VLOOKUP(O17,lifetable,4,FALSE) -> 0.35344501 | U17: =S17*VLOOKUP(O17,lifetable,5,FALSE) -> 0.38711452 | V17: =T17/(1+Disc)^N17 -> 0.26841022 | W17: =U17/(1+Disc)^N17 -> 0.29397924
A18: 9 | B18: 6.2e-05 | C18: 5.6e-05 | D18: =IF(util=1,F18,IF(util=2,H18,"err")) -> 0.94464086 | E18: =IF(util=1,G18,IF(util=2,I18,"err")) -> 0.91032568 | F18: 0.94464086 | G18: 0.91032568 | H18: =VLOOKUP($A18,$K$9:$M$26,2) -> 0.916 | I18: =VLOOKUP($A18,$K$9:$M$26,3) -> 0.881 | J18: 50-54 | K18: 50 | L18: 0.837 | M18: 0.805 | N18: 9 | O18: =Age+N18 -> 89 | P18: =P17-P17*VLOOKUP(O17,lifetable,2,FALSE) -> 0.4400005 | Q18: =Q17-Q17*VLOOKUP(O17,lifetable,3,FALSE) -> 0.5385462 | R18: =(P18+P19)/2 -> 0.4074024 | S18: =(Q18+Q19)/2 -> 0.50699251 | T18: =R18*VLOOKUP(O18,lifetable,4,FALSE) -> 0.30244591 | U18: =S18*VLOOKUP(O18,lifetable,5,FALSE) -> 0.34084694 | V18: =T18/(1+Disc)^N18 -> 0.22191393 | W18: =U18/(1+Disc)^N18 -> 0.25008996
A19: 10 | B19: 7.2e-05 | C19: 6.4e-05 | D19: =IF(util=1,F19,IF(util=2,H19,"err")) -> 0.94464086 | E19: =IF(util=1,G19,IF(util=2,I19,"err")) -> 0.91032568 | F19: 0.94464086 | G19: 0.91032568 | H19: =VLOOKUP($A19,$K$9:$M$26,2) -> 0.916 | I19: =VLOOKUP($A19,$K$9:$M$26,3) -> 0.881 | J19: 55-59 | K19: 55 | L19: 0.817 | M19: 0.802 | N19: 10 | O19: =Age+N19 -> 90 | P19: =P18-P18*VLOOKUP(O18,lifetable,2,FALSE) -> 0.3748043 | Q19: =Q18-Q18*VLOOKUP(O18,lifetable,3,FALSE) -> 0.47543882 | R19: =(P19+P20)/2 -> 0.34523449 | S19: =(Q19+Q20)/2 -> 0.44414972 | T19: =R19*VLOOKUP(O19,lifetable,4,FALSE) -> 0.25481885 | U19: =S19*VLOOKUP(O19,lifetable,5,FALSE) -> 0.2955982 | V19: =T19/(1+Disc)^N19 -> 0.18064588 | W19: =U19/(1+Disc)^N19 -> 0.20955512
A20: 11 | B20: 8.1e-05 | C20: 6.2e-05 | D20: =IF(util=1,F20,IF(util=2,H20,"err")) -> 0.94464086 | E20: =IF(util=1,G20,IF(util=2,I20,"err")) -> 0.91032568 | F20: 0.94464086 | G20: 0.91032568 | H20: =VLOOKUP($A20,$K$9:$M$26,2) -> 0.916 | I20: =VLOOKUP($A20,$K$9:$M$26,3) -> 0.881 | J20: 60-64 | K20: 60 | L20: 0.809 | M20: 0.784 | N20: 11 | O20: =Age+N20 -> 91 | P20: =P19-P19*VLOOKUP(O19,lifetable,2,FALSE) -> 0.31566468 | Q20: =Q19-Q19*VLOOKUP(O19,lifetable,3,FALSE) -> 0.41286061 | R20: =(P20+P21)/2 -> 0.28774525 | S20: =(Q20+Q21)/2 -> 0.38232338 | T20: =R20*VLOOKUP(O20,lifetable,4,FALSE) -> 0.21115023 | U20: =S20*VLOOKUP(O20,lifetable,5,FALSE) -> 0.25183122 | V20: =T20/(1+Disc)^N20 -> 0.14462644 | W20: =U20/(1+Disc)^N20 -> 0.17249072
A21: 12 | B21: 0.000105 | C21: 5.7e-05 | D21: =IF(util=1,F21,IF(util=2,H21,"err")) -> 0.94464086 | E21: =IF(util=1,G21,IF(util=2,I21,"err")) -> 0.91032568 | F21: 0.94464086 | G21: 0.91032568 | H21: =VLOOKUP($A21,$K$9:$M$26,2) -> 0.916 | I21: =VLOOKUP($A21,$K$9:$M$26,3) -> 0.881 | J21: 65-69 | K21: 65 | L21: 0.798 | M21: 0.782 | N21: 12 | O21: =Age+N21 -> 92 | P21: =P20-P20*VLOOKUP(O20,lifetable,2,FALSE) -> 0.25982581 | Q21: =Q20-Q20*VLOOKUP(O20,lifetable,3,FALSE) -> 0.35178614 | R21: =(P21+P22)/2 -> 0.23458373 | S21: =(Q21+Q22)/2 -> 0.3227323 | T21: =R21*VLOOKUP(O21,lifetable,4,FALSE) -> 0.17112795 | U21: =S21*VLOOKUP(O21,lifetable,5,FALSE) -> 0.21033832 | V21: =T21/(1+Disc)^N21 -> 0.11324962 | W21: =U21/(1+Disc)^N21 -> 0.13919839
A22: 13 | B22: 0.000125 | C22: 7.9e-05 | D22: =IF(util=1,F22,IF(util=2,H22,"err")) -> 0.94464086 | E22: =IF(util=1,G22,IF(util=2,I22,"err")) -> 0.91032568 | F22: 0.94464086 | G22: 0.91032568 | H22: =VLOOKUP($A22,$K$9:$M$26,2) -> 0.916 | I22: =VLOOKUP($A22,$K$9:$M$26,3) -> 0.881 | J22: 70-74 | K22: 70 | L22: 0.802 | M22: 0.787 | N22: 13 | O22: =Age+N22 -> 93 | P22: =P21-P21*VLOOKUP(O21,lifetable,2,FALSE) -> 0.20934165 | Q22: =Q21-Q21*VLOOKUP(O21,lifetable,3,FALSE) -> 0.29367846 | R22: =(P22+P23)/2 -> 0.18693864 | S22: =(Q22+Q23)/2 -> 0.26685108 | T22: =R22*VLOOKUP(O22,lifetable,4,FALSE) -> 0.13556154 | U22: =S22*VLOOKUP(O22,lifetable,5,FALSE) -> 0.17204126 | V22: =T22/(1+Disc)^N22 -> 0.086678608 | W22: =U22/(1+Disc)^N22 -> 0.1100039
... A26: 17 | B26: 0.000303 | C26: 0.000159 | D26: =IF(util=1,F26,IF(util=2,H26,"err")) -> 0.94333139 | E26: =IF(util=1,G26,IF(util=2,I26,"err")) -> 0.91087276 | F26: 0.94333139 | G26: 0.91087276 | H26: =VLOOKUP($A26,$K$9:$M$26,2) -> 0.916 | I26: =VLOOKUP($A26,$K$9:$M$26,3) -> 0.881 | J26: 90+ | K26: 90 | L26: 0.663 | M26: 0.665 | N26: 17 | O26: =Age+N26 -> 97 | P26: =P25-P25*VLOOKUP(O25,lifetable,2,FALSE) -> 0.065759168 | Q26: =Q25-Q25*VLOOKUP(O25,lifetable,3,FALSE) -> 0.11087082 | R26: =(P26+P27)/2 -> 0.055726358 | S26: =(Q26+Q27)/2 -> 0.096061805 | T26: =R26*VLOOKUP(O26,lifetable,4,FALSE) -> 0.0394389 | U26: =S26*VLOOKUP(O26,lifetable,5,FALSE) -> 0.059152745 | V26: =T26/(1+Disc)^N26 -> 0.021975504 | W26: =U26/(1+Disc)^N26 -> 0.032960133
A27: 18 | B27: 0.000387 | C27: 0.000211 | D27: =IF(util=1,F27,IF(util=2,H27,"err")) -> 0.94198997 | E27: =IF(util=1,G27,IF(util=2,I27,"err")) -> 0.911239 | F27: 0.94198997 | G27: 0.911239 | H27: =VLOOKUP($A27,$K$9:$M$26,2) -> 0.933 | I27: =VLOOKUP($A27,$K$9:$M$26,3) -> 0.864 | N27: 18 | O27: =Age+N27 -> 98 | P27: =P26-P26*VLOOKUP(O26,lifetable,2,FALSE) -> 0.045693547 | Q27: =Q26-Q26*VLOOKUP(O26,lifetable,3,FALSE) -> 0.081252789 | R27: =(P27+P28)/2 -> 0.038236338 | S27: =(Q27+Q28)/2 -> 0.069333452 | T27: =R27*VLOOKUP(O27,lifetable,4,FALSE) -> 0.026893427 | U27: =S27*VLOOKUP(O27,lifetable,5,FALSE) -> 0.042180875 | V27: =T27/(1+Disc)^N27 -> 0.014478376 | W27: =U27/(1+Disc)^N27 -> 0.022708544
A28: 19 | B28: 0.000415 | C28: 0.000194 | D28: =IF(util=1,F28,IF(util=2,H28,"err")) -> 0.94061612 | E28: =IF(util=1,G28,IF(util=2,I28,"err")) -> 0.9114333 | F28: 0.94061612 | G28: 0.9114333 | H28: =VLOOKUP($A28,$K$9:$M$26,2) -> 0.933 | I28: =VLOOKUP($A28,$K$9:$M$26,3) -> 0.864 | N28: 19 | O28: =Age+N28 -> 99 | P28: =P27-P27*VLOOKUP(O27,lifetable,2,FALSE) -> 0.030779128 | Q28: =Q27-Q27*VLOOKUP(O27,lifetable,3,FALSE) -> 0.057414115 | R28: =(P28+P29)/2 -> 0.025105534 | S28: =(Q28+Q29)/2 -> 0.048380635 | T28: =R28*VLOOKUP(O28,lifetable,4,FALSE) -> 0.017548004 | U28: =S28*VLOOKUP(O28,lifetable,5,FALSE) -> 0.029073073 | V28: =T28/(1+Disc)^N28 -> 0.0091276942 | W28: =U28/(1+Disc)^N28 -> 0.015122524
A29: 20 | B29: 0.000503 | C29: 0.000179 | D29: =IF(util=1,F29,IF(util=2,H29,"err")) -> 0.93920935 | E29: =IF(util=1,G29,IF(util=2,I29,"err")) -> 0.91146389 | F29: 0.93920935 | G29: 0.91146389 | H29: =VLOOKUP($A29,$K$9:$M$26,2) -> 0.895 | I29: =VLOOKUP($A29,$K$9:$M$26,3) -> 0.866 | N29: 20 | O29: =Age+N29 -> 100 | P29: =P28-P28*VLOOKUP(O28,lifetable,2,FALSE) -> 0.019431941 | Q29: =Q28-Q28*VLOOKUP(O28,lifetable,3,FALSE) -> 0.039347156 | R29: =(P29+P30)/2 -> 0.015661464 | S29: =(Q29+Q30)/2 -> 0.032455384 | T29: =R29*VLOOKUP(O29,lifetable,4,FALSE) -> 0.010878361 | U29: =S29*VLOOKUP(O29,lifetable,5,FALSE) -> 0.019259913 | V29: =T29/(1+Disc)^N29 -> 0.0054670929 | W29: =U29/(1+Disc)^N29 -> 0.009679375
A30: 21 | B30: 0.000498 | C30: 0.000201 | D30: =IF(util=1,F30,IF(util=2,H30,"err")) -> 0.93776916 | E30: =IF(util=1,G30,IF(util=2,I30,"err")) -> 0.91133843 | F30: 0.93776916 | G30: 0.91133843 | H30: =VLOOKUP($A30,$K$9:$M$26,2) -> 0.895 | I30: =VLOOKUP($A30,$K$9:$M$26,3) -> 0.866 | N30: 21 | O30: =Age+N30 -> 101 | P30: =P29-P29*VLOOKUP(O29,lifetable,2,FALSE) -> 0.011890987 | Q30: =Q29-Q29*VLOOKUP(O29,lifetable,3,FALSE) -> 0.025563611 | R30: =(P30+P31)/2 -> #N/A | S30: =(Q30+Q31)/2 -> #N/A | T30: =R30*VLOOKUP(O30,lifetable,4,FALSE) -> #N/A | U30: =S30*VLOOKUP(O30,lifetable,5,FALSE) -> #N/A | V30: =T30/(1+Disc)^N30 -> #N/A | W30: =U30/(1+Disc)^N30 -> #N/A
A31: 22 | B31: 0.000478 | C31: 0.000215 | D31: =IF(util=1,F31,IF(util=2,H31,"err")) -> 0.93629505 | E31: =IF(util=1,G31,IF(util=2,I31,"err")) -> 0.91106401 | F31: 0.93629505 | G31: 0.91106401 | H31: =VLOOKUP($A31,$K$9:$M$26,2) -> 0.895 | I31: =VLOOKUP($A31,$K$9:$M$26,3) -> 0.866 | N31: 22 | O31: =Age+N31 -> 102 | P31: =P30-P30*VLOOKUP(O30,lifetable,2,FALSE) -> #N/A | Q31: =Q30-Q30*VLOOKUP(O30,lifetable,3,FALSE) -> #N/A | R31: =(P31+P32)/2 -> #N/A | S31: =(Q31+Q32)/2 -> #N/A | T31: =R31*VLOOKUP(O31,lifetable,4,FALSE) -> #N/A | U31: =S31*VLOOKUP(O31,lifetable,5,FALSE) -> #N/A | V31: =T31/(1+Disc)^N31 -> #N/A | W31: =U31/(1+Disc)^N31 -> #N/A
A32: 23 | B32: 0.00047 | C32: 0.0002 | D32: =IF(util=1,F32,IF(util=2,H32,"err")) -> 0.93478653 | E32: =IF(util=1,G32,IF(util=2,I32,"err")) -> 0.91064718 | F32: 0.93478653 | G32: 0.91064718 | H32: =VLOOKUP($A32,$K$9:$M$26,2) -> 0.895 | I32: =VLOOKUP($A32,$K$9:$M$26,3) -> 0.866 | N32: 23 | O32: =Age+N32 -> 103 | P32: =P31-P31*VLOOKUP(O31,lifetable,2,FALSE) -> #N/A | Q32: =Q31-Q31*VLOOKUP(O31,lifetable,3,FALSE) -> #N/A | R32: =(P32+P33)/2 -> #N/A | S32: =(Q32+Q33)/2 -> #N/A | T32: =R32*VLOOKUP(O32,lifetable,4,FALSE) -> #N/A | U32: =S32*VLOOKUP(O32,lifetable,5,FALSE) -> #N/A | V32: =T32/(1+Disc)^N32 -> #N/A | W32: =U32/(1+Disc)^N32 -> #N/A
A33: 24 | B33: 0.000513 | C33: 0.000218 | D33: =IF(util=1,F33,IF(util=2,H33,"err")) -> 0.93324312 | E33: =IF(util=1,G33,IF(util=2,I33,"err")) -> 0.910094 | F33: 0.93324312 | G33: 0.910094 | H33: =VLOOKUP($A33,$K$9:$M$26,2) -> 0.895 | I33: =VLOOKUP($A33,$K$9:$M$26,3) -> 0.866 | N33: 24 | O33: =Age+N33 -> 104 | P33: =P32-P32*VLOOKUP(O32,lifetable,2,FALSE) -> #N/A | Q33: =Q32-Q32*VLOOKUP(O32,lifetable,3,FALSE) -> #N/A | R33: =(P33+P34)/2 -> #N/A | S33: =(Q33+Q34)/2 -> #N/A | T33: =R33*VLOOKUP(O33,lifetable,4,FALSE) -> #N/A | U33: =S33*VLOOKUP(O33,lifetable,5,FALSE) -> #N/A | V33: =T33/(1+Disc)^N33 -> #N/A | W33: =U33/(1+Disc)^N33 -> #N/A
A34: 25 | B34: 0.000538 | C34: 0.000244 | D34: =IF(util=1,F34,IF(util=2,H34,"err")) -> 0.93166431 | E34: =IF(util=1,G34,IF(util=2,I34,"err")) -> 0.90941003 | F34: 0.93166431 | G34: 0.90941003 | H34: =VLOOKUP($A34,$K$9:$M$26,2) -> 0.895 | I34: =VLOOKUP($A34,$K$9:$M$26,3) -> 0.873 | N34: 25 | O34: =Age+N34 -> 105 | P34: =P33-P33*VLOOKUP(O33,lifetable,2,FALSE) -> #N/A | Q34: =Q33-Q33*VLOOKUP(O33,lifetable,3,FALSE) -> #N/A | R34: =(P34+P35)/2 -> #N/A | S34: =(Q34+Q35)/2 -> #N/A | T34: =R34*VLOOKUP(O34,lifetable,4,FALSE) -> #N/A | U34: =S34*VLOOKUP(O34,lifetable,5,FALSE) -> #N/A | V34: =T34/(1+Disc)^N34 -> #N/A | W34: =U34/(1+Disc)^N34 -> #N/A
A35: 26 | B35: 0.000543 | C35: 0.000259 | D35: =IF(util=1,F35,IF(util=2,H35,"err")) -> 0.93004962 | E35: =IF(util=1,G35,IF(util=2,I35,"err")) -> 0.90860044 | F35: 0.93004962 | G35: 0.90860044 | H35: =VLOOKUP($A35,$K$9:$M$26,2) -> 0.895 | I35: =VLOOKUP($A35,$K$9:$M$26,3) -> 0.873 | N35: 26 | O35: =Age+N35 -> 106 | P35: =P34-P34*VLOOKUP(O34,lifetable,2,FALSE) -> #N/A | Q35: =Q34-Q34*VLOOKUP(O34,lifetable,3,FALSE) -> #N/A | R35: =(P35+P36)/2 -> #N/A | S35: =(Q35+Q36)/2 -> #N/A | T35: =R35*VLOOKUP(O35,lifetable,4,FALSE) -> #N/A | U35: =S35*VLOOKUP(O35,lifetable,5,FALSE) -> #N/A | V35: =T35/(1+Disc)^N35 -> #N/A | W35: =U35/(1+Disc)^N35 -> #N/A
A36: 27 | B36: 0.000574 | C36: 0.00027 | D36: =IF(util=1,F36,IF(util=2,H36,"err")) -> 0.92839856 | E36: =IF(util=1,G36,IF(util=2,I36,"err")) -> 0.90766993 | F36: 0.92839856 | G36: 0.90766993 | H36: =VLOOKUP($A36,$K$9:$M$26,2) -> 0.895 | I36: =VLOOKUP($A36,$K$9:$M$26,3) -> 0.873 | N36: 27 | O36: =Age+N36 -> 107 | P36: =P35-P35*VLOOKUP(O35,lifetable,2,FALSE) -> #N/A | Q36: =Q35-Q35*VLOOKUP(O35,lifetable,3,FALSE) -> #N/A | R36: =(P36+P37)/2 -> #N/A | S36: =(Q36+Q37)/2 -> #N/A | T36: =R36*VLOOKUP(O36,lifetable,4,FALSE) -> #N/A | U36: =S36*VLOOKUP(O36,lifetable,5,FALSE) -> #N/A | V36: =T36/(1+Disc)^N36 -> #N/A | W36: =U36/(1+Disc)^N36 -> #N/A
A37: 28 | B37: 0.000629 | C37: 0.000304 | D37: =IF(util=1,F37,IF(util=2,H37,"err")) -> 0.92671065 | E37: =IF(util=1,G37,IF(util=2,I37,"err")) -> 0.90662285 | F37: 0.92671065 | G37: 0.90662285 | H37: =VLOOKUP($A37,$K$9:$M$26,2) -> 0.895 | I37: =VLOOKUP($A37,$K$9:$M$26,3) -> 0.873 | N37: 28 | O37: =Age+N37 -> 108 | P37: =P36-P36*VLOOKUP(O36,lifetable,2,FALSE) -> #N/A | Q37: =Q36-Q36*VLOOKUP(O36,lifetable,3,FALSE) -> #N/A | R37: =(P37+P38)/2 -> #N/A | S37: =(Q37+Q38)/2 -> #N/A | T37: =R37*VLOOKUP(O37,lifetable,4,FALSE) -> #N/A | U37: =S37*VLOOKUP(O37,lifetable,5,FALSE) -> #N/A | V37: =T37/(1+Disc)^N37 -> #N/A | W37: =U37/(1+Disc)^N37 -> #N/A
A38: 29 | B38: 0.000664 | C38: 0.000302 | D38: =IF(util=1,F38,IF(util=2,H38,"err")) -> 0.92498541 | E38: =IF(util=1,G38,IF(util=2,I38,"err")) -> 0.90546319 | F38: 0.92498541 | G38: 0.90546319 | H38: =VLOOKUP($A38,$K$9:$M$26,2) -> 0.895 | I38: =VLOOKUP($A38,$K$9:$M$26,3) -> 0.873 | N38: 29 | O38: =Age+N38 -> 109 | P38: =P37-P37*VLOOKUP(O37,lifetable,2,FALSE) -> #N/A | Q38: =Q37-Q37*VLOOKUP(O37,lifetable,3,FALSE) -> #N/A | R38: =(P38+P39)/2 -> #N/A | S38: =(Q38+Q39)/2 -> #N/A | T38: =R38*VLOOKUP(O38,lifetable,4,FALSE) -> #N/A | U38: =S38*VLOOKUP(O38,lifetable,5,FALSE) -> #N/A | V38: =T38/(1+Disc)^N38 -> #N/A | W38: =U38/(1+Disc)^N38 -> #N/A
... A109: 100 | B109: 0.38807 | C109: 0.350306 | D109: =IF(util=1,F109,IF(util=2,H109,"err")) -> 0.6945941 | E109: =IF(util=1,G109,IF(util=2,I109,"err")) -> 0.59342736 | F109: 0.6945941 | G109: 0.59342736 | H109: =VLOOKUP($A109,$K$9:$M$26,2) -> 0.663 | I109: =VLOOKUP($A109,$K$9:$M$26,3) -> 0.665 | N109: 100 | O109: =Age+N109 -> 180 | P109: =P108-P108*VLOOKUP(O108,lifetable,2,FALSE) -> #N/A | Q109: =Q108-Q108*VLOOKUP(O108,lifetable,3,FALSE) -> #N/A | R109: =(P109+P110)/2 -> #N/A | S109: =(Q109+Q110)/2 -> #N/A | T109: =R109*VLOOKUP(O109,lifetable,4,FALSE) -> #N/A | U109: =S109*VLOOKUP(O109,lifetable,5,FALSE) -> #N/A | V109: =T109/(1+Disc)^N109 -> #N/A | W109: =U109/(1+Disc)^N109 -> #N/A
D110: =IF(util=1,F110,IF(util=2,H110,"err")) -> 0.69022425 | E110: =IF(util=1,G110,IF(util=2,I110,"err")) -> 0.58589766 | F110: 0.69022425 | G110: 0.58589766 | I110: =VLOOKUP($A110,$K$9:$M$26,3) -> 0.881

Sheet QALYsForUndiagnosedCancer
B2: Undiagnosed Cancer | G2: Stage I | K2: Stage II | O2: Stage III | S2: Stage IV
A3: Age | B3: Stage I | C3: Stage II | D3: Stage III | E3: Stage IV | F3: Gen pop QALYs | G3: Absolute shortfall | H3: Modifier | I3: Proportional shortfall | J3: Modifier | K3: Absolute shortfall | L3: Modifier | M3: Proportional shortfall | N3: Modifier | O3: Absolute shortfall | P3: Modifier | Q3: Proportional shortfall | R3: Modifier | S3: Absolute shortfall | T3: Modifier | U3: Proportional shortfall | V3: Modifier
A4: 50 | B4: =(Stage4to1!F2*Stage4to1!C2+Stage3to1!F2*Stage3to1!C2+Stage2to1!F2*Stage2to1!C2+Stage1to1!F2*Stage1to1!C2)/(Stage4to1!C2+Stage3to1!C2+Stage2to1!C2+Stage1to1!C2) -> 3.8832798 | C4: =(Stage4to2!F2*Stage4to2!C2+Stage3to2!F2*Stage3to2!C2+Stage2to2!F2*Stage2to2!C2)/(Stage4to2!C2+Stage3to2!C2+Stage2to2!C2) -> 2.9973706 | D4: =(Stage4to3!F2*Stage4to3!C2+Stage3to3!F2*Stage3to3!C2)/(Stage4to3!C2+Stage3to3!C2) -> 2.2545528 | E4: =Stage4to4!F2 -> 1.3878624 | F4: 15.926122 | G4: =F4-B4 -> 12.042842 | H4: =IF(G4<12,1,IF(G4<18,1.2,1.7)) -> 1.2 | I4: =G4/F4 -> 0.75616915 | J4: =IF(I4<0.85,1,IF(I4<0.95,1.2,1.7)) -> 1 | K4: =F4-C4 -> 12.928751 | L4: =IF(K4<12,1,IF(K4<18,1.2,1.7)) -> 1.2 | M4: =K4/$F4 -> 0.81179533 | N4: =IF(M4<0.85,1,IF(M4<0.95,1.2,1.7)) -> 1 | O4: =F4-D4 -> 13.671569 | P4: =IF(O4<12,1,IF(O4<18,1.2,1.7)) -> 1.2 | Q4: =O4/$F4 -> 0.8584368 | R4: =IF(Q4<0.85,1,IF(Q4<0.95,1.2,1.7)) -> 1.2 | S4: =F4-E4 -> 14.53826 | T4: =IF(S4<12,1,IF(S4<18,1.2,1.7)) -> 1.2 | U4: =S4/F4 -> 0.91285623 | V4: =IF(U4<0.85,1,IF(U4<0.95,1.2,1.7)) -> 1.2
A5: 51 | B5: =(Stage4to1!F3*Stage4to1!C3+Stage3to1!F3*Stage3to1!C3+Stage2to1!F3*Stage2to1!C3+Stage1to1!F3*Stage1to1!C3)/(Stage4to1!C3+Stage3to1!C3+Stage2to1!C3+Stage1to1!C3) -> 3.7804777 | C5: =(Stage4to2!F3*Stage4to2!C3+Stage3to2!F3*Stage3to2!D3+Stage2to2!F3*Stage2to2!C3)/(Stage4to2!C3+Stage3to2!D3+Stage2to2!C3) -> 3.739592 | D5: =(Stage4to3!F3*Stage4to3!C3+Stage3to3!F3*Stage3to3!C3)/(Stage4to3!C3+Stage3to3!C3) -> 2.2514389 | E5: =Stage4to4!F3 -> 1.3878624 | F5: 15.626547 | G5: =F5-B5 -> 11.846069 | H5: =IF(G5<12,1,IF(G5<18,1.2,1.7)) -> 1 | I5: =G5/F5 -> 0.75807337 | J5: =IF(I5<0.85,1,IF(I5<0.95,1.2,1.7)) -> 1 | K5: =F5-C5 -> 11.886954 | L5: =IF(K5<12,1,IF(K5<18,1.2,1.7)) -> 1 | M5: =K5/$F5 -> 0.7606898 | N5: =IF(M5<0.85,1,IF(M5<0.95,1.2,1.7)) -> 1 | O5: =F5-D5 -> 13.375108 | P5: =IF(O5<12,1,IF(O5<18,1.2,1.7)) -> 1.2 | Q5: =O5/$F5 -> 0.85592217 | R5: =IF(Q5<0.85,1,IF(Q5<0.95,1.2,1.7)) -> 1.2 | S5: =F5-E5 -> 14.238684 | T5: =IF(S5<12,1,IF(S5<18,1.2,1.7)) -> 1.2 | U5: =S5/F5 -> 0.9111856 | V5: =IF(U5<0.85,1,IF(U5<0.95,1.2,1.7)) -> 1.2
A6: 52 | B6: =(Stage4to1!F4*Stage4to1!C4+Stage3to1!F4*Stage3to1!C4+Stage2to1!F4*Stage2to1!C4+Stage1to1!F4*Stage1to1!C4)/(Stage4to1!C4+Stage3to1!C4+Stage2to1!C4+Stage1to1!C4) -> 3.740963 | C6: =(Stage4to2!F4*Stage4to2!C4+Stage3to2!F4*Stage3to2!C4+Stage2to2!F4*Stage2to2!C4)/(Stage4to2!C4+Stage3to2!C4+Stage2to2!C4) -> 2.9230619 | D6: =(Stage4to3!F4*Stage4to3!C4+Stage3to3!F4*Stage3to3!C4)/(Stage4to3!C4+Stage3to3!C4) -> 2.2378267 | E6: =Stage4to4!F4 -> 1.3878624 | F6: 15.322131 | G6: =F6-B6 -> 11.581168 | H6: =IF(G6<12,1,IF(G6<18,1.2,1.7)) -> 1 | I6: =G6/F6 -> 0.75584578 | J6: =IF(I6<0.85,1,IF(I6<0.95,1.2,1.7)) -> 1 | K6: =F6-C6 -> 12.399069 | L6: =IF(K6<12,1,IF(K6<18,1.2,1.7)) -> 1.2 | M6: =K6/$F6 -> 0.80922616 | N6: =IF(M6<0.85,1,IF(M6<0.95,1.2,1.7)) -> 1 | O6: =F6-D6 -> 13.084304 | P6: =IF(O6<12,1,IF(O6<18,1.2,1.7)) -> 1.2 | Q6: =O6/$F6 -> 0.85394808 | R6: =IF(Q6<0.85,1,IF(Q6<0.95,1.2,1.7)) -> 1.2 | S6: =F6-E6 -> 13.934269 | T6: =IF(S6<12,1,IF(S6<18,1.2,1.7)) -> 1.2 | U6: =S6/F6 -> 0.90942106 | V6: =IF(U6<0.85,1,IF(U6<0.95,1.2,1.7)) -> 1.2
A7: 53 | B7: =(Stage4to1!F5*Stage4to1!C5+Stage3to1!F5*Stage3to1!C5+Stage2to1!F5*Stage2to1!C5+Stage1to1!F5*Stage1to1!C5)/(Stage4to1!C5+Stage3to1!C5+Stage2to1!C5+Stage1to1!C5) -> 3.7208411 | C7: =(Stage4to2!F5*Stage4to2!C5+Stage3to2!F5*Stage3to2!C5+Stage2to2!F5*Stage2to2!C5)/(Stage4to2!C5+Stage3to2!C5+Stage2to2!C5) -> 2.8571874 | D7: =(Stage4to3!F5*Stage4to3!C5+Stage3to3!F5*Stage3to3!C5)/(Stage4to3!C5+Stage3to3!C5) -> 2.1934221 | E7: =Stage4to4!F5 -> 1.3814874 | F7: 15.012754 | G7: =F7-B7 -> 11.291913 | H7: =IF(G7<12,1,IF(G7<18,1.2,1.7)) -> 1 | I7: =G7/F7 -> 0.75215467 | J7: =IF(I7<0.85,1,IF(I7<0.95,1.2,1.7)) -> 1 | K7: =F7-C7 -> 12.155567 | L7: =IF(K7<12,1,IF(K7<18,1.2,1.7)) -> 1.2 | M7: =K7/$F7 -> 0.80968267 | N7: =IF(M7<0.85,1,IF(M7<0.95,1.2,1.7)) -> 1 | O7: =F7-D7 -> 12.819332 | P7: =IF(O7<12,1,IF(O7<18,1.2,1.7)) -> 1.2 | Q7: =O7/$F7 -> 0.85389609 | R7: =IF(Q7<0.85,1,IF(Q7<0.95,1.2,1.7)) -> 1.2 | S7: =F7-E7 -> 13.631267 | T7: =IF(S7<12,1,IF(S7<18,1.2,1.7)) -> 1.2 | U7: =S7/F7 -> 0.90797908 | V7: =IF(U7<0.85,1,IF(U7<0.95,1.2,1.7)) -> 1.2
A8: 54 | B8: =(Stage4to1!F6*Stage4to1!C6+Stage3to1!F6*Stage3to1!C6+Stage2to1!F6*Stage2to1!C6+Stage1to1!F6*Stage1to1!C6)/(Stage4to1!C6+Stage3to1!C6+Stage2to1!C6+Stage1to1!C6) -> 3.7270801 | C8: =(Stage4to2!F6*Stage4to2!C6+Stage3to2!F6*Stage3to2!C6+Stage2to2!F6*Stage2to2!C6)/(Stage4to2!C6+Stage3to2!C6+Stage2to2!C6) -> 2.8879178 | D8: =(Stage4to3!F6*Stage4to3!C6+Stage3to3!F6*Stage3to3!C6)/(Stage4to3!C6+Stage3to3!C6) -> 2.0040733 | E8: =Stage4to4!F6 -> 1.3746094 | F8: 14.697495 | G8: =F8-B8 -> 10.970415 | H8: =IF(G8<12,1,IF(G8<18,1.2,1.7)) -> 1 | I8: =G8/F8 -> 0.74641393 | J8: =IF(I8<0.85,1,IF(I8<0.95,1.2,1.7)) -> 1 | K8: =F8-C8 -> 11.809577 | L8: =IF(K8<12,1,IF(K8<18,1.2,1.7)) -> 1 | M8: =K8/$F8 -> 0.80350952 | N8: =IF(M8<0.85,1,IF(M8<0.95,1.2,1.7)) -> 1 | O8: =F8-D8 -> 12.693422 | P8: =IF(O8<12,1,IF(O8<18,1.2,1.7)) -> 1.2 | Q8: =O8/$F8 -> 0.86364525 | R8: =IF(Q8<0.85,1,IF(Q8<0.95,1.2,1.7)) -> 1.2 | S8: =F8-E8 -> 13.322886 | T8: =IF(S8<12,1,IF(S8<18,1.2,1.7)) -> 1.2 | U8: =S8/F8 -> 0.90647322 | V8: =IF(U8<0.85,1,IF(U8<0.95,1.2,1.7)) -> 1.2
A9: 55 | B9: =(Stage4to1!F7*Stage4to1!C7+Stage3to1!F7*Stage3to1!C7+Stage2to1!F7*Stage2to1!C7+Stage1to1!F7*Stage1to1!C7)/(Stage4to1!C7+Stage3to1!C7+Stage2to1!C7+Stage1to1!C7) -> 3.1346585 | C9: =(Stage4to2!F7*Stage4to2!C7+Stage3to2!F7*Stage3to2!C7+Stage2to2!F7*Stage2to2!C7)/(Stage4to2!C7+Stage3to2!C7+Stage2to2!C7) -> 2.3637926 | D9: =(Stage4to3!F7*Stage4to3!C7+Stage3to3!F7*Stage3to3!C7)/(Stage4to3!C7+Stage3to3!C7) -> 1.7276353 | E9: =Stage4to4!F7 -> 1.0618765 | F9: 14.376846 | G9: =F9-B9 -> 11.242188 | H9: =IF(G9<12,1,IF(G9<18,1.2,1.7)) -> 1 | I9: =G9/F9 -> 0.7819648 | J9: =IF(I9<0.85,1,IF(I9<0.95,1.2,1.7)) -> 1 | K9: =F9-C9 -> 12.013053 | L9: =IF(K9<12,1,IF(K9<18,1.2,1.7)) -> 1.2 | M9: =K9/$F9 -> 0.83558337 | N9: =IF(M9<0.85,1,IF(M9<0.95,1.2,1.7)) -> 1 | O9: =F9-D9 -> 12.649211 | P9: =IF(O9<12,1,IF(O9<18,1.2,1.7)) -> 1.2 | Q9: =O9/$F9 -> 0.87983211 | R9: =IF(Q9<0.85,1,IF(Q9<0.95,1.2,1.7)) -> 1.2 | S9: =F9-E9 -> 13.31497 | T9: =IF(S9<12,1,IF(S9<18,1.2,1.7)) -> 1.2 | U9: =S9/F9 -> 0.92613981 | V9: =IF(U9<0.85,1,IF(U9<0.95,1.2,1.7)) -> 1.2
A10: 56 | B10: =(Stage4to1!F8*Stage4to1!C8+Stage3to1!F8*Stage3to1!C8+Stage2to1!F8*Stage2to1!C8+Stage1to1!F8*Stage1to1!C8)/(Stage4to1!C8+Stage3to1!C8+Stage2to1!C8+Stage1to1!C8) -> 3.102355 | C10: =(Stage4to2!F8*Stage4to2!C8+Stage3to2!F8*Stage3to2!C8+Stage2to2!F8*Stage2to2!C8)/(Stage4to2!C8+Stage3to2!C8+Stage2to2!C8) -> 2.3474721 | D10: =(Stage4to3!F8*Stage4to3!C8+Stage3to3!F8*Stage3to3!C8)/(Stage4to3!C8+Stage3to3!C8) -> 1.726156 | E10: =Stage4to4!F8 -> 1.0618765 | F10: 14.05178 | G10: =F10-B10 -> 10.949425 | H10: =IF(G10<12,1,IF(G10<18,1.2,1.7)) -> 1 | I10: =G10/F10 -> 0.77921979 | J10: =IF(I10<0.85,1,IF(I10<0.95,1.2,1.7)) -> 1 | K10: =F10-C10 -> 11.704308 | L10: =IF(K10<12,1,IF(K10<18,1.2,1.7)) -> 1 | M10: =K10/$F10 -> 0.8329413 | N10: =IF(M10<0.85,1,IF(M10<0.95,1.2,1.7)) -> 1 | O10: =F10-D10 -> 12.325624 | P10: =IF(O10<12,1,IF(O10<18,1.2,1.7)) -> 1.2 | Q10: =O10/$F10 -> 0.87715749 | R10: =IF(Q10<0.85,1,IF(Q10<0.95,1.2,1.7)) -> 1.2 | S10: =F10-E10 -> 12.989904 | T10: =IF(S10<12,1,IF(S10<18,1.2,1.7)) -> 1.2 | U10: =S10/F10 -> 0.92443117 | V10: =IF(U10<0.85,1,IF(U10<0.95,1.2,1.7)) -> 1.2
A11: 57 | B11: =(Stage4to1!F9*Stage4to1!C9+Stage3to1!F9*Stage3to1!C9+Stage2to1!F9*Stage2to1!C9+Stage1to1!F9*Stage1to1!C9)/(Stage4to1!C9+Stage3to1!C9+Stage2to1!C9+Stage1to1!C9) -> 3.0669189 | C11: =(Stage4to2!F9*Stage4to2!C9+Stage3to2!F9*Stage3to2!C9+Stage2to2!F9*Stage2to2!C9)/(Stage4to2!C9+Stage3to2!C9+Stage2to2!C9) -> 2.3115315 | D11: =(Stage4to3!F9*Stage4to3!C9+Stage3to3!F9*Stage3to3!C9)/(Stage4to3!C9+Stage3to3!C9) -> 1.7201453 | E11: =Stage4to4!F9 -> 1.0618765 | F11: 13.723302 | G11: =F11-B11 -> 10.656383 | H11: =IF(G11<12,1,IF(G11<18,1.2,1.7)) -> 1 | I11: =G11/F11 -> 0.77651741 | J11: =IF(I11<0.85,1,IF(I11<0.95,1.2,1.7)) -> 1 | K11: =F11-C11 -> 11.41177 | L11: =IF(K11<12,1,IF(K11<18,1.2,1.7)) -> 1 | M11: =K11/$F11 -> 0.83156156 | N11: =IF(M11<0.85,1,IF(M11<0.95,1.2,1.7)) -> 1 | O11: =F11-D11 -> 12.003156 | P11: =IF(O11<12,1,IF(O11<18,1.2,1.7)) -> 1.2 | Q11: =O11/$F11 -> 0.87465514 | R11: =IF(Q11<0.85,1,IF(Q11<0.95,1.2,1.7)) -> 1.2 | S11: =F11-E11 -> 12.661425 | T11: =IF(S11<12,1,IF(S11<18,1.2,1.7)) -> 1.2 | U11: =S11/F11 -> 0.92262237 | V11: =IF(U11<0.85,1,IF(U11<0.95,1.2,1.7)) -> 1.2
A12: 58 | B12: =(Stage4to1!F10*Stage4to1!C10+Stage3to1!F10*Stage3to1!C10+Stage2to1!F10*Stage2to1!C10+Stage1to1!F10*Stage1to1!C10)/(Stage4to1!C10+Stage3to1!C10+Stage2to1!C10+Stage1to1!C10) -> 3.040436 | C12: =(Stage4to2!F10*Stage4to2!C10+Stage3to2!F10*Stage3to2!C10+Stage2to2!F10*Stage2to2!C10)/(Stage4to2!C10+Stage3to2!C10+Stage2to2!C10) -> 2.2537765 | D12: =(Stage4to3!F10*Stage4to3!C10+Stage3to3!F10*Stage3to3!C10)/(Stage4to3!C10+Stage3to3!C10) -> 1.689322 | E12: =Stage4to4!F10 -> 1.0599638 | F12: 13.390654 | G12: =F12-B12 -> 10.350218 | H12: =IF(G12<12,1,IF(G12<18,1.2,1.7)) -> 1 | I12: =G12/F12 -> 0.77294343 | J12: =IF(I12<0.85,1,IF(I12<0.95,1.2,1.7)) -> 1 | K12: =F12-C12 -> 11.136878 | L12: =IF(K12<12,1,IF(K12<18,1.2,1.7)) -> 1 | M12: =K12/$F12 -> 0.83169034 | N12: =IF(M12<0.85,1,IF(M12<0.95,1.2,1.7)) -> 1 | O12: =F12-D12 -> 11.701332 | P12: =IF(O12<12,1,IF(O12<18,1.2,1.7)) -> 1 | Q12: =O12/$F12 -> 0.87384321 | R12: =IF(Q12<0.85,1,IF(Q12<0.95,1.2,1.7)) -> 1.2 | S12: =F12-E12 -> 12.33069 | T12: =IF(S12<12,1,IF(S12<18,1.2,1.7)) -> 1.2 | U12: =S12/F12 -> 0.92084302 | V12: =IF(U12<0.85,1,IF(U12<0.95,1.2,1.7)) -> 1.2
A13: 59 | B13: =(Stage4to1!F11*Stage4to1!C11+Stage3to1!F11*Stage3to1!C11+Stage2to1!F11*Stage2to1!C11+Stage1to1!F11*Stage1to1!C11)/(Stage4to1!C11+Stage3to1!C11+Stage2to1!C11+Stage1to1!C11) -> 3.0386911 | C13: =(Stage4to2!F11*Stage4to2!C11+Stage3to2!F11*Stage3to2!C11+Stage2to2!F11*Stage2to2!C11)/(Stage4to2!C11+Stage3to2!C11+Stage2to2!C11) -> 2.2526514 | D13: =(Stage4to3!F11*Stage4to3!C11+Stage3to3!F11*Stage3to3!C11)/(Stage4to3!C11+Stage3to3!C11) -> 1.5599739 | E13: =Stage4to4!F11 -> 1.0527438 | F13: 13.054301 | G13: =F13-B13 -> 10.01561 | H13: =IF(G13<12,1,IF(G13<18,1.2,1.7)) -> 1 | I13: =G13/F13 -> 0.76722683 | J13: =IF(I13<0.85,1,IF(I13<0.95,1.2,1.7)) -> 1 | K13: =F13-C13 -> 10.80165 | L13: =IF(K13<12,1,IF(K13<18,1.2,1.7)) -> 1 | M13: =K13/$F13 -> 0.82743991 | N13: =IF(M13<0.85,1,IF(M13<0.95,1.2,1.7)) -> 1 | O13: =F13-D13 -> 11.494327 | P13: =IF(O13<12,1,IF(O13<18,1.2,1.7)) -> 1 | Q13: =O13/$F13 -> 0.88050116 | R13: =IF(Q13<0.85,1,IF(Q13<0.95,1.2,1.7)) -> 1.2 | S13: =F13-E13 -> 12.001558 | T13: =IF(S13<12,1,IF(S13<18,1.2,1.7)) -> 1.2 | U13: =S13/F13 -> 0.91935656 | V13: =IF(U13<0.85,1,IF(U13<0.95,1.2,1.7)) -> 1.2
A14: 60 | B14: =(Stage4to1!F12*Stage4to1!C12+Stage3to1!F12*Stage3to1!C12+Stage2to1!F12*Stage2to1!C12+Stage1to1!F12*Stage1to1!C12)/(Stage4to1!C12+Stage3to1!C12+Stage2to1!C12+Stage1to1!C12) -> 2.7416891 | C14: =(Stage4to2!F12*Stage4to2!C12+Stage3to2!F12*Stage3to2!C12+Stage2to2!F12*Stage2to2!C12)/(Stage4to2!C12+Stage3to2!C12+Stage2to2!C12) -> 1.9970318 | D14: =(Stage4to3!F12*Stage4to3!C12+Stage3to3!F12*Stage3to3!C12)/(Stage4to3!C12+Stage3to3!C12) -> 1.4229726 | E14: =Stage4to4!F12 -> 0.87410138 | F14: 12.713385 | G14: =F14-B14 -> 9.9716954 | H14: =IF(G14<12,1,IF(G14<18,1.2,1.7)) -> 1 | I14: =G14/F14 -> 0.78434625 | J14: =IF(I14<0.85,1,IF(I14<0.95,1.2,1.7)) -> 1 | K14: =F14-C14 -> 10.716353 | L14: =IF(K14<12,1,IF(K14<18,1.2,1.7)) -> 1 | M14: =K14/$F14 -> 0.84291895 | N14: =IF(M14<0.85,1,IF(M14<0.95,1.2,1.7)) -> 1 | O14: =F14-D14 -> 11.290412 | P14: =IF(O14<12,1,IF(O14<18,1.2,1.7)) -> 1 | Q14: =O14/$F14 -> 0.88807288 | R14: =IF(Q14<0.85,1,IF(Q14<0.95,1.2,1.7)) -> 1.2 | S14: =F14-E14 -> 11.839283 | T14: =IF(S14<12,1,IF(S14<18,1.2,1.7)) -> 1 | U14: =S14/F14 -> 0.93124558 | V14: =IF(U14<0.85,1,IF(U14<0.95,1.2,1.7)) -> 1.2
A15: 61 | B15: =(Stage4to1!F13*Stage4to1!C13+Stage3to1!F13*Stage3to1!C13+Stage2to1!F13*Stage2to1!C13+Stage1to1!F13*Stage1to1!C13)/(Stage4to1!C13+Stage3to1!C13+Stage2to1!C13+Stage1to1!C13) -> 2.7175241 | C15: =(Stage4to2!F13*Stage4to2!C13+Stage3to2!F13*Stage3to2!C13+Stage2to2!F13*Stage2to2!C13)/(Stage4to2!C13+Stage3to2!C13+Stage2to2!C13) -> 1.9878833 | D15: =(Stage4to3!F13*Stage4to3!C13+Stage3to3!F13*Stage3to3!C13)/(Stage4to3!C13+Stage3to3!C13) -> 1.4222513 | E15: =Stage4to4!F13 -> 0.87410138 | F15: 12.369371 | G15: =F15-B15 -> 9.6518467 | H15: =IF(G15<12,1,IF(G15<18,1.2,1.7)) -> 1 | I15: =G15/F15 -> 0.78030216 | J15: =IF(I15<0.85,1,IF(I15<0.95,1.2,1.7)) -> 1 | K15: =F15-C15 -> 10.381487 | L15: =IF(K15<12,1,IF(K15<18,1.2,1.7)) -> 1 | M15: =K15/$F15 -> 0.83928986 | N15: =IF(M15<0.85,1,IF(M15<0.95,1.2,1.7)) -> 1 | O15: =F15-D15 -> 10.947119 | P15: =IF(O15<12,1,IF(O15<18,1.2,1.7)) -> 1 | Q15: =O15/$F15 -> 0.8850183 | R15: =IF(Q15<0.85,1,IF(Q15<0.95,1.2,1.7)) -> 1.2 | S15: =F15-E15 -> 11.495269 | T15: =IF(S15<12,1,IF(S15<18,1.2,1.7)) -> 1 | U15: =S15/F15 -> 0.9293334 | V15: =IF(U15<0.85,1,IF(U15<0.95,1.2,1.7)) -> 1.2
A16: 62 | B16: =(Stage4to1!F14*Stage4to1!C14+Stage3to1!F14*Stage3to1!C14+Stage2to1!F14*Stage2to1!C14+Stage1to1!F14*Stage1to1!C14)/(Stage4to1!C14+Stage3to1!C14+Stage2to1!C14+Stage1to1!C14) -> 2.68923 | C16: =(Stage4to2!F14*Stage4to2!C14+Stage3to2!F14*Stage3to2!C14+Stage2to2!F14*Stage2to2!C14)/(Stage4to2!C14+Stage3to2!C14+Stage2to2!C14) -> 1.9680343 | D16: =(Stage4to3!F14*Stage4to3!C14+Stage3to3!F14*Stage3to3!C14)/(Stage4to3!C14+Stage3to3!C14) -> 1.4201084 | E16: =Stage4to4!F14 -> 0.87410138 | F16: 12.021493 | G16: =F16-B16 -> 9.3322629 | H16: =IF(G16<12,1,IF(G16<18,1.2,1.7)) -> 1 | I16: =G16/F16 -> 0.77629817 | J16: =IF(I16<0.85,1,IF(I16<0.95,1.2,1.7)) -> 1 | K16: =F16-C16 -> 10.053459 | L16: =IF(K16<12,1,IF(K16<18,1.2,1.7)) -> 1 | M16: =K16/$F16 -> 0.83629036 | N16: =IF(M16<0.85,1,IF(M16<0.95,1.2,1.7)) -> 1 | O16: =F16-D16 -> 10.601385 | P16: =IF(O16<12,1,IF(O16<18,1.2,1.7)) -> 1 | Q16: =O16/$F16 -> 0.88186921 | R16: =IF(Q16<0.85,1,IF(Q16<0.95,1.2,1.7)) -> 1.2 | S16: =F16-E16 -> 11.147392 | T16: =IF(S16<12,1,IF(S16<18,1.2,1.7)) -> 1 | U16: =S16/F16 -> 0.92728845 | V16: =IF(U16<0.85,1,IF(U16<0.95,1.2,1.7)) -> 1.2
A17: 63 | B17: =(Stage4to1!F15*Stage4to1!C15+Stage3to1!F15*Stage3to1!C15+Stage2to1!F15*Stage2to1!C15+Stage1to1!F15*Stage1to1!C15)/(Stage4to1!C15+Stage3to1!C15+Stage2to1!C15+Stage1to1!C15) -> 2.6644111 | C17: =(Stage4to2!F15*Stage4to2!C15+Stage3to2!F15*Stage3to2!C15+Stage2to2!F15*Stage2to2!C15)/(Stage4to2!C15+Stage3to2!C15+Stage2to2!C15) -> 1.9317637 | D17: =(Stage4to3!F15*Stage4to3!C15+Stage3to3!F15*Stage3to3!C15)/(Stage4to3!C15+Stage3to3!C15) -> 1.404573 | E17: =Stage4to4!F15 -> 0.87410138 | F17: 11.673321 | G17: =F17-B17 -> 9.0089101 | H17: =IF(G17<12,1,IF(G17<18,1.2,1.7)) -> 1 | I17: =G17/F17 -> 0.77175209 | J17: =IF(I17<0.85,1,IF(I17<0.95,1.2,1.7)) -> 1 | K17: =F17-C17 -> 9.7415575 | L17: =IF(K17<12,1,IF(K17<18,1.2,1.7)) -> 1 | M17: =K17/$F17 -> 0.83451465 | N17: =IF(M17<0.85,1,IF(M17<0.95,1.2,1.7)) -> 1 | O17: =F17-D17 -> 10.268748 | P17: =IF(O17<12,1,IF(O17<18,1.2,1.7)) -> 1 | Q17: =O17/$F17 -> 0.87967666 | R17: =IF(Q17<0.85,1,IF(Q17<0.95,1.2,1.7)) -> 1.2 | S17: =F17-E17 -> 10.79922 | T17: =IF(S17<12,1,IF(S17<18,1.2,1.7)) -> 1 | U17: =S17/F17 -> 0.92511974 | V17: =IF(U17<0.85,1,IF(U17<0.95,1.2,1.7)) -> 1.2
... A34: 80 | B34: =(Stage4to1!F32*Stage4to1!C32+Stage3to1!F32*Stage3to1!C32+Stage2to1!F32*Stage2to1!C32+Stage1to1!F32*Stage1to1!C32)/(Stage4to1!C32+Stage3to1!C32+Stage2to1!C32+Stage1to1!C32) -> #DIV/0! | C34: =(Stage4to2!F32*Stage4to2!C32+Stage3to2!F32*Stage3to2!C32+Stage2to2!F32*Stage2to2!C32)/(Stage4to2!C32+Stage3to2!C32+Stage2to2!C32) -> #DIV/0! | D34: =(Stage4to3!F32*Stage4to3!C32+Stage3to3!F32*Stage3to3!C32)/(Stage4to3!C32+Stage3to3!C32) -> #DIV/0! | E34: =Stage4to4!F32 -> #DIV/0! | F34: 5.5490187 | G34: =F34-B34 -> #DIV/0! | H34: =IF(G34<12,1,IF(G34<18,1.2,1.7)) -> #DIV/0! | I34: =G34/F34 -> #DIV/0! | J34: =IF(I34<0.85,1,IF(I34<0.95,1.2,1.7)) -> #DIV/0! | K34: =F34-C34 -> #DIV/0! | L34: =IF(K34<12,1,IF(K34<18,1.2,1.7)) -> #DIV/0! | M34: =K34/$F34 -> #DIV/0! | N34: =IF(M34<0.85,1,IF(M34<0.95,1.2,1.7)) -> #DIV/0! | O34: =F34-D34 -> #DIV/0! | P34: =IF(O34<12,1,IF(O34<18,1.2,1.7)) -> #DIV/0! | Q34: =O34/$F34 -> #DIV/0! | R34: =IF(Q34<0.85,1,IF(Q34<0.95,1.2,1.7)) -> #DIV/0! | S34: =F34-E34 -> #DIV/0! | T34: =IF(S34<12,1,IF(S34<18,1.2,1.7)) -> #DIV/0! | U34: =S34/F34 -> #DIV/0! | V34: =IF(U34<0.85,1,IF(U34<0.95,1.2,1.7)) -> #DIV/0!

Sheet Stage4to1
A1: Age | B1: Engine - SoC Markov trace - Stage 4 | C1: Engine - Galleri Markov trace - Stage 1 | D1: Post-diagnosis calculation - QALYs Galleri | E1: Per patient QALYs | F1: Per patient QALYs
A2: 50 | B2: 17.516331 | C2: 110.38722 | D2: 35.872476 | E2: =D2/C2 -> 0.32496947 | F2: =D2/B2 -> 2.0479446
A3: 51 | B3: 17.516331 | C3: 121.693 | D3: 34.2 | E3: =D3/C3 -> 0.28103506 | F3: =D3/B3 -> 1.9524637
A4: 52 | B4: 17.516331 | C4: 138.042 | D4: 34.04 | E4: =D4/C4 -> 0.24659162 | F4: =D4/B4 -> 1.9433293
A5: 53 | B5: 17.516331 | C5: 159.311 | D5: 33.88 | E5: =D5/C5 -> 0.21266579 | F5: =D5/B5 -> 1.934195
A6: 54 | B6: 17.516331 | C6: 184.117 | D6: 33.7 | E6: =D6/C6 -> 0.18303579 | F6: =D6/B6 -> 1.9239189
A7: 55 | B7: 35.513752 | C7: 213.27152 | D7: 53.055874 | E7: =D7/C7 -> 0.24877149 | F7: =D7/B7 -> 1.4939529
A8: 56 | B8: 35.513752 | C8: 230.587 | D8: 53.06 | E8: =D8/C8 -> 0.23010838 | F8: =D8/B8 -> 1.4940691
A9: 57 | B9: 35.513752 | C9: 255.66098 | D9: 52.960303 | E9: =D9/C9 -> 0.20715051 | F9: =D9/B9 -> 1.4912618
A10: 58 | B10: 35.513752 | C10: 288.04554 | D10: 52.599561 | E10: =D10/C10 -> 0.18260849 | F10: =D10/B10 -> 1.481104
A11: 59 | B11: 35.513752 | C11: 324.88685 | D11: 52.226194 | E11: =D11/C11 -> 0.16075195 | F11: =D11/B11 -> 1.4705907
A12: 60 | B12: 65.085518 | C12: 366.7883 | D12: 80.040365 | E12: =D12/C12 -> 0.21821952 | F12: =D12/B12 -> 1.2297723
A13: 61 | B13: 65.085518 | C13: 386.18231 | D13: 80.040365 | E13: =D13/C13 -> 0.20726057 | F13: =D13/B13 -> 1.2297723
... A31: 79 | B31: 169.87109 | C31: 785.94138 | D31: 127.09611 | E31: =D31/C31 -> 0.16171195 | F31: =D31/B31 -> 0.74819154
A32: 80 | E32: =D32/C32 -> #DIV/0! | F32: =D32/B32 -> #DIV/0!
A33: 81
A34: 82
A35: 83
A36: 84
A37: 85
A38: 86
A39: 87
A40: 88
A41: 89
A42: 90
A43: 91
A44: 92
... A51: 99

Sheet Stage3to1
A1: Age | B1: Engine - SoC Markov trace - Stage 3 | C1: Engine - Galleri Markov trace - Stage 1 | D1: Post-diagnosis calculation - QALYs Galleri | E1: Per patient QALYs | F1: Per patient QALYs
A2: 50 | B2: 6.715834 | C2: 37.62591 | D2: 44.455182 | E2: =D2/C2 -> 1.1815045 | F2: =D2/B2 -> 6.6194581
A3: 51 | B3: 6.715834 | C3: 41.522161 | D3: 44.329915 | E3: =D3/C3 -> 1.0676206 | F3: =D3/B3 -> 6.6008057
A4: 52 | B4: 6.715834 | C4: 47.41462 | D4: 44.200264 | E4: =D4/C4 -> 0.93220749 | F4: =D4/B4 -> 6.5815004
A5: 53 | B5: 6.715834 | C5: 55.655311 | D5: 44.066075 | E5: =D5/C5 -> 0.79176765 | F5: =D5/B5 -> 6.5615194
A6: 54 | B6: 6.715834 | C6: 65.532573 | D6: 43.912187 | E6: =D6/C6 -> 0.67008184 | F6: =D6/B6 -> 6.5386052
A7: 55 | B7: 14.493369 | C7: 76.891662 | D7: 73.175259 | E7: =D7/C7 -> 0.95166702 | F7: =D7/B7 -> 5.0488785
A8: 56 | B8: 14.493369 | C8: 82.785027 | D8: 73.037827 | E8: =D8/C8 -> 0.8822589 | F8: =D8/B8 -> 5.0393961
A9: 57 | B9: 14.493369 | C9: 91.707928 | D9: 72.821871 | E9: =D9/C9 -> 0.79406298 | F9: =D9/B9 -> 5.0244957
A10: 58 | B10: 14.493369 | C10: 104.19363 | D10: 72.594475 | E10: =D10/C10 -> 0.69672661 | F10: =D10/B10 -> 5.0088061
A11: 59 | B11: 14.493369 | C11: 118.89493 | D11: 72.359121 | E11: =D11/C11 -> 0.60859719 | F11: =D11/B11 -> 4.9925674
A12: 60 | B12: 26.96892 | C12: 135.32482 | D12: 114.0508 | E12: =D12/C12 -> 0.84279289 | F12: =D12/B12 -> 4.2289716
A13: 61 | B13: 26.96892 | C13: 141.90636 | D13: 113.91351 | E13: =D13/C13 -> 0.80273715 | F13: =D13/B13 -> 4.223881
... A31: 79 | B31: 73.279182 | C31: 310.75656 | D31: 155.77909 | E31: =D31/C31 -> 0.50128979 | F31: =D31/B31 -> 2.1258301
A32: 80 | E32: =D32/C32 -> #DIV/0! | F32: =D32/B32 -> #DIV/0!
A33: 81
A34: 82
A35: 83
A36: 84
A37: 85
A38: 86
A39: 87
A40: 88
A41: 89
A42: 90
A43: 91
A44: 92
... A51: 99

Sheet Stage2to1
A1: Age | B1: Engine - SoC Markov trace - Stage 2 | C1: Engine - Galleri Markov trace - Stage 1 | D1: Post-diagnosis calculation - QALYs Galleri | E1: Per patient QALYs | F1: Per patient QALYs
A2: 50 | B2: 1.856267 | C2: 7.5530275 | D2: 20.26917 | E2: =D2/C2 -> 2.6835822 | F2: =D2/B2 -> 10.919318
A3: 51 | B3: 1.856267 | C3: 8.2236293 | D3: 20.230939 | E3: =D3/C3 -> 2.4600986 | F3: =D3/B3 -> 10.898723
A4: 52 | B4: 1.856267 | C4: 9.3365167 | D4: 20.19137 | E4: =D4/C4 -> 2.1626234 | F4: =D4/B4 -> 10.877406
A5: 53 | B5: 1.856267 | C5: 11.182824 | D5: 20.150416 | E5: =D5/C5 -> 1.8019075 | F5: =D5/B5 -> 10.855343
A6: 54 | B6: 1.856267 | C6: 14.246207 | D6: 20.108028 | E6: =D6/C6 -> 1.4114654 | F6: =D6/B6 -> 10.832508
A7: 55 | B7: 4.507937 | C7: 17.610496 | D7: 41.794046 | E7: =D7/C7 -> 2.3732464 | F7: =D7/B7 -> 9.2712133
A8: 56 | B8: 4.507937 | C8: 18.803192 | D8: 41.740895 | E8: =D8/C8 -> 2.2198835 | F8: =D8/B8 -> 9.2594229
A9: 57 | B9: 4.507937 | C9: 20.793195 | D9: 41.685884 | E9: =D9/C9 -> 2.0047849 | F9: =D9/B9 -> 9.2472198
A10: 58 | B10: 4.507937 | C10: 24.108686 | D10: 41.628948 | E10: =D10/C10 -> 1.7267199 | F10: =D10/B10 -> 9.2345896
A11: 59 | B11: 4.507937 | C11: 29.629461 | D11: 41.51038 | E11: =D11/C11 -> 1.4009833 | F11: =D11/B11 -> 9.2082875
A12: 60 | B12: 9.623693 | C12: 35.503216 | D12: 76.579706 | E12: =D12/C12 -> 2.1569794 | F12: =D12/B12 -> 7.9574137
A13: 61 | B13: 9.623693 | C13: 36.791198 | D13: 76.523061 | E13: =D13/C13 -> 2.0799285 | F13: =D13/B13 -> 7.9515276
... A31: 79 | B31: 30.003927 | C31: 97.942193 | D31: 128.02042 | E31: =D31/C31 -> 1.3071018 | F31: =D31/B31 -> 4.2667888
A32: 80 | E32: =D32/C32 -> #DIV/0! | F32: =D32/B32 -> #DIV/0!
A33: 81
A34: 82
A35: 83
A36: 84
A37: 85
A38: 86
A39: 87
A40: 88
A41: 89
A42: 90
A43: 91
A44: 92
... A51: 99

Sheet Stage1to1
A1: Age | B1: Engine - SoC Markov trace - Stage 1 | C1: Engine - Galleri Markov trace - Stage 1 | D1: Post-diagnosis calculation - QALYs Galleri | E1: Per patient QALYs | F1: Per patient QALYs
A2: 50 | B2: 4.434902 | C2: 4.434902 | D2: 63.724927 | E2: =D2/C2 -> 14.368959 | F2: =D2/B2 -> 14.368959
A3: 51 | B3: 4.434902 | C3: 4.434902 | D3: 63.578639 | E3: =D3/C3 -> 14.335974 | F3: =D3/B3 -> 14.335974
A4: 52 | B4: 4.434902 | C4: 4.434902 | D4: 63.427232 | E4: =D4/C4 -> 14.301834 | F4: =D4/B4 -> 14.301834
A5: 53 | B5: 4.434902 | C5: 4.434902 | D5: 63.251215 | E5: =D5/C5 -> 14.262145 | F5: =D5/B5 -> 14.262145
A6: 54 | B6: 4.434902 | C6: 4.434902 | D6: 63.04999 | E6: =D6/C6 -> 14.216772 | F6: =D6/B6 -> 14.216772
A7: 55 | B7: 10.150356 | C7: 10.150356 | D7: 126.47834 | E7: =D7/C7 -> 12.460483 | F7: =D7/B7 -> 12.460483
A8: 56 | B8: 10.150356 | C8: 10.150356 | D8: 126.2093 | E8: =D8/C8 -> 12.433978 | F8: =D8/B8 -> 12.433978
A9: 57 | B9: 10.150356 | C9: 10.150356 | D9: 125.93084 | E9: =D9/C9 -> 12.406545 | F9: =D9/B9 -> 12.406545
A10: 58 | B10: 10.150356 | C10: 10.150356 | D10: 125.5956 | E10: =D10/C10 -> 12.373517 | F10: =D10/B10 -> 12.373517
A11: 59 | B11: 10.150356 | C11: 10.150356 | D11: 125.19121 | E11: =D11/C11 -> 12.333677 | F11: =D11/B11 -> 12.333677
A12: 60 | B12: 20.912485 | C12: 20.912485 | D12: 225.44772 | E12: =D12/C12 -> 10.780532 | F12: =D12/B12 -> 10.780532
A13: 61 | B13: 20.912485 | C13: 20.912485 | D13: 225.04671 | E13: =D13/C13 -> 10.761357 | F13: =D13/B13 -> 10.761357
... A31: 79 | B31: 71.974258 | C31: 71.974258 | D31: 412.45139 | E31: =D31/C31 -> 5.7305403 | F31: =D31/B31 -> 5.7305403
A32: 80 | E32: =D32/C32 -> #DIV/0! | F32: =D32/B32 -> #DIV/0!
A33: 81
A34: 82
A35: 83
A36: 84
A37: 85
A38: 86
A39: 87
A40: 88
A41: 89
A42: 90
A43: 91
A44: 92
... A51: 99

Sheet Stage4to2
A1: Age | B1: Engine - SoC Markov trace - Stage 4 | C1: Engine - Galleri Markov trace - Stage 2 | D1: Post-diagnosis calculation - QALYs Galleri | E1: Per patient QALYs | F1: Per patient QALYs
A2: 50 | B2: 17.516331 | C2: 57.409838 | D2: 30.493415 | E2: =D2/C2 -> 0.53115313 | F2: =D2/B2 -> 1.7408563
A3: 51 | B3: 17.516331 | C3: 59.616569 | D3: 30.493415 | E3: =D3/C3 -> 0.51149228 | F3: =D3/B3 -> 1.7408563
A4: 52 | B4: 17.516331 | C4: 65.176254 | D4: 30.353348 | E4: =D4/C4 -> 0.46571176 | F4: =D4/B4 -> 1.7328599
A5: 53 | B5: 17.516331 | C5: 77.792391 | D5: 30.202228 | E5: =D5/C5 -> 0.38824142 | F5: =D5/B5 -> 1.7242325
A6: 54 | B6: 17.516331 | C6: 96.130787 | D6: 30.045819 | E6: =D6/C6 -> 0.31255147 | F6: =D6/B6 -> 1.7153032
A7: 55 | B7: 35.513752 | C7: 115.4633 | D7: 47.302827 | E7: =D7/C7 -> 0.40967847 | F7: =D7/B7 -> 1.331958
A8: 56 | B8: 35.513752 | C8: 118.99736 | D8: 47.302827 | E8: =D8/C8 -> 0.39751158 | F8: =D8/B8 -> 1.331958
A9: 57 | B9: 35.513752 | C9: 128.00574 | D9: 47.21762 | E9: =D9/C9 -> 0.3688711 | F9: =D9/B9 -> 1.3295588
A10: 58 | B10: 35.513752 | C10: 148.4823 | D10: 46.895995 | E10: =D10/C10 -> 0.31583558 | F10: =D10/B10 -> 1.3205024
A11: 59 | B11: 35.513752 | C11: 178.22712 | D11: 46.563112 | E11: =D11/C11 -> 0.26125717 | F11: =D11/B11 -> 1.3111291
A12: 60 | B12: 65.085518 | C12: 209.21772 | D12: 71.361289 | E12: =D12/C12 -> 0.34108627 | F12: =D12/B12 -> 1.0964235
A13: 61 | B13: 65.085518 | C13: 213.18963 | D13: 71.361289 | E13: =D13/C13 -> 0.33473152 | F13: =D13/B13 -> 1.0964235
... A31: 79 | B31: 169.87109 | C31: 515.52651 | D31: 113.31461 | E31: =D31/C31 -> 0.21980364 | F31: =D31/B31 -> 0.66706234
A32: 80 | E32: =D32/C32 -> #DIV/0! | F32: =D32/B32 -> #DIV/0!
A33: 81
A34: 82
A35: 83
A36: 84
A37: 85
A38: 86
A39: 87
A40: 88
A41: 89
A42: 90
A43: 91
A44: 92
... A51: 99

Sheet Stage3to2
A1: Age | B1: Engine - SoC Markov trace - Stage 3 | C1: Engine - Galleri Markov trace - Stage 2 | D1: Post-diagnosis calculation - QALYs Galleri | E1: Per patient QALYs | F1: Per patient QALYs
A2: 50 | B2: 6.715834 | C2: 17.497552 | D2: 42.139589 | E2: =D2/C2 -> 2.4083134 | F2: =D2/B2 -> 6.2746621
A3: 51 | B3: 6.715834 | C3: 17.875627 | D3: 42.0209 | E3: =D3/C3 -> 2.3507372 | F3: =D3/B3 -> 6.2569891
A4: 52 | B4: 6.715834 | C4: 18.916559 | D4: 41.898058 | E4: =D4/C4 -> 2.214888 | F4: =D4/B4 -> 6.2386976
A5: 53 | B5: 6.715834 | C5: 21.768862 | D5: 41.770915 | E5: =D5/C5 -> 1.9188378 | F5: =D5/B5 -> 6.2197659
A6: 54 | B6: 6.715834 | C6: 29.572638 | D6: 41.624321 | E6: =D6/C6 -> 1.4075281 | F6: =D6/B6 -> 6.1979377
A7: 55 | B7: 14.493369 | C7: 37.551749 | D7: 68.252238 | E7: =D7/C7 -> 1.8175515 | F7: =D7/B7 -> 4.7092045
A8: 56 | B8: 14.493369 | C8: 38.139871 | D8: 68.129708 | E8: =D8/C8 -> 1.786312 | F8: =D8/B8 -> 4.7007503
A9: 57 | B9: 14.493369 | C9: 39.781627 | D9: 67.929176 | E9: =D9/C9 -> 1.7075515 | F9: =D9/B9 -> 4.6869141
A10: 58 | B10: 14.493369 | C10: 44.308782 | D10: 67.717744 | E10: =D10/C10 -> 1.5283143 | F10: =D10/B10 -> 4.6723259
A11: 59 | B11: 14.493369 | C11: 56.743305 | D11: 67.498912 | E11: =D11/C11 -> 1.1895485 | F11: =D11/B11 -> 4.6572272
A12: 60 | B12: 26.96892 | C12: 69.423634 | D12: 105.02142 | E12: =D12/C12 -> 1.5127617 | F12: =D12/B12 -> 3.8941647
A13: 61 | B13: 26.96892 | C13: 70.070269 | D13: 104.89902 | E13: =D13/C13 -> 1.4970546 | F13: =D13/B13 -> 3.8896261
... A31: 79 | B31: 73.279182 | C31: 181.67832 | D31: 138.88738 | E31: =D31/C31 -> 0.76446865 | F31: =D31/B31 -> 1.8953184
A32: 80 | E32: =D32/C32 -> #DIV/0! | F32: =D32/B32 -> #DIV/0!
A33: 81
A34: 82
A35: 83
A36: 84
A37: 85
A38: 86
A39: 87
A40: 88
A41: 89
A42: 90
A43: 91
A44: 92
... A51: 99

Sheet Stage2to2
A1: Age | B1: Engine - SoC Markov trace - Stage 2 | C1: Engine - Galleri Markov trace - Stage 2 | D1: Post-diagnosis calculation - QALYs Galleri | E1: Per patient QALYs | F1: Per patient QALYs
A2: 50 | B2: 1.856267 | C2: 1.856267 | D2: 20.355622 | E2: =D2/C2 -> 10.965891 | F2: =D2/B2 -> 10.965891
A3: 51 | B3: 1.856267 | C3: 1.856267 | D3: 20.316156 | E3: =D3/C3 -> 10.944631 | F3: =D3/B3 -> 10.944631
A4: 52 | B4: 1.856267 | C4: 1.856267 | D4: 20.278469 | E4: =D4/C4 -> 10.924328 | F4: =D4/B4 -> 10.924328
A5: 53 | B5: 1.856267 | C5: 1.856267 | D5: 20.239463 | E5: =D5/C5 -> 10.903314 | F5: =D5/B5 -> 10.903314
A6: 54 | B6: 1.856267 | C6: 1.856267 | D6: 20.199091 | E6: =D6/C6 -> 10.881565 | F6: =D6/B6 -> 10.881565
A7: 55 | B7: 4.507937 | C7: 4.507937 | D7: 41.72053 | E7: =D7/C7 -> 9.2549054 | F7: =D7/B7 -> 9.2549054
A8: 56 | B8: 4.507937 | C8: 4.507937 | D8: 41.672015 | E8: =D8/C8 -> 9.2441432 | F8: =D8/B8 -> 9.2441432
A9: 57 | B9: 4.507937 | C9: 4.507937 | D9: 41.621802 | E9: =D9/C9 -> 9.2330043 | F9: =D9/B9 -> 9.2330043
A10: 58 | B10: 4.507937 | C10: 4.507937 | D10: 41.571588 | E10: =D10/C10 -> 9.2218654 | F10: =D10/B10 -> 9.2218654
A11: 59 | B11: 4.507937 | C11: 4.507937 | D11: 41.516041 | E11: =D11/C11 -> 9.2095433 | F11: =D11/B11 -> 9.2095433
A12: 60 | B12: 9.623693 | C12: 9.623693 | D12: 75.936179 | E12: =D12/C12 -> 7.8905446 | F12: =D12/B12 -> 7.8905446
A13: 61 | B13: 9.623693 | C13: 9.623693 | D13: 75.925145 | E13: =D13/C13 -> 7.889398 | F13: =D13/B13 -> 7.889398
... A31: 79 | B31: 30.003927 | C31: 30.003927 | D31: 124.62603 | E31: =D31/C31 -> 4.1536573 | F31: =D31/B31 -> 4.1536573
A32: 80 | E32: =D32/C32 -> #DIV/0! | F32: =D32/B32 -> #DIV/0!
A33: 81
A34: 82
A35: 83
A36: 84
A37: 85
A38: 86
A39: 87
A40: 88
A41: 89
A42: 90
A43: 91
A44: 92
... A51: 99

Sheet Stage4to3
A1: Age | B1: Engine - SoC Markov trace - Stage 4 | C1: Engine - Galleri Markov trace - Stage 3 | D1: Post-diagnosis calculation - QALYs Galleri | E1: Per patient QALYs | F1: Per patient QALYs
A2: 50 | B2: 17.516331 | C2: 37.6918 | D2: 27.19683 | E2: =D2/C2 -> 0.72155826 | F2: =D2/B2 -> 1.5526556
A3: 51 | B3: 17.516331 | C3: 37.728202 | D3: 27.19683 | E3: =D3/C3 -> 0.72086206 | F3: =D3/B3 -> 1.5526556
A4: 52 | B4: 17.516331 | C4: 38.044709 | D4: 27.071905 | E4: =D4/C4 -> 0.71158134 | F4: =D4/B4 -> 1.5455237
A5: 53 | B5: 17.516331 | C5: 40.445515 | D5: 26.937122 | E5: =D5/C5 -> 0.66601012 | F5: =D5/B5 -> 1.537829
A6: 54 | B6: 17.516331 | C6: 58.333706 | D6: 26.797622 | E6: =D6/C6 -> 0.45938488 | F6: =D6/B6 -> 1.529865
A7: 55 | B7: 35.513752 | C7: 76.309051 | D7: 42.189008 | E7: =D7/C7 -> 0.5528703 | F7: =D7/B7 -> 1.1879626
A8: 56 | B8: 35.513752 | C8: 76.355578 | D8: 42.189008 | E8: =D8/C8 -> 0.55253341 | F8: =D8/B8 -> 1.1879626
A9: 57 | B9: 35.513752 | C9: 76.860072 | D9: 42.113012 | E9: =D9/C9 -> 0.54791794 | F9: =D9/B9 -> 1.1858227
A10: 58 | B10: 35.513752 | C10: 80.772754 | D10: 41.826157 | E10: =D10/C10 -> 0.51782508 | F10: =D10/B10 -> 1.1777454
A11: 59 | B11: 35.513752 | C11: 110.0698 | D11: 41.529262 | E11: =D11/C11 -> 0.37729933 | F11: =D11/B11 -> 1.1693854
A12: 60 | B12: 65.085518 | C12: 139.57734 | D12: 63.646555 | E12: =D12/C12 -> 0.4559949 | F12: =D12/B12 -> 0.9778912
A13: 61 | B13: 65.085518 | C13: 139.602 | D13: 63.646555 | E13: =D13/C13 -> 0.45591434 | F13: =D13/B13 -> 0.9778912
... A31: 79 | B31: 169.87109 | C31: 357.03035 | D31: 101.06438 | E31: =D31/C31 -> 0.28306943 | F31: =D31/B31 -> 0.59494749
A32: 80 | E32: =D32/C32 -> #DIV/0! | F32: =D32/B32 -> #DIV/0!
A33: 81
A34: 82
A35: 83
A36: 84
A37: 85
A38: 86
A39: 87
A40: 88
A41: 89
A42: 90
A43: 91
A44: 92
... A51: 99

Sheet Stage3to3
A1: Age | B1: Engine - SoC Markov trace - Stage 3 | C1: Engine - Galleri Markov trace - Stage 3 | D1: Post-diagnosis calculation - QALYs Galleri | E1: Per patient QALYs | F1: Per patient QALYs
A2: 50 | B2: 6.715834 | C2: 6.715834 | D2: 41.59697 | E2: =D2/C2 -> 6.1938652 | F2: =D2/B2 -> 6.1938652
A3: 51 | B3: 6.715834 | C3: 6.715834 | D3: 41.484129 | E3: =D3/C3 -> 6.1770629 | F3: =D3/B3 -> 6.1770629
