Workbook
Name Age: 'AW calculator'!$B$5
Name Age: '[2]AW calculator'!$B$5
Name cohortSize: [1]Parameters!$E$15
Name compliance: [1]Parameters!$E$112:$E$117
Name compliance.PostDiag: [1]Parameters!$E$118:$E$123
Name Disc: 'AW calculator'!$B$3
Name Disc: '[2]AW calculator'!$B$3
Name discCost: [1]Parameters!$E$9
Name discHealth: [1]Parameters!$E$8
Name endAge: [1]Parameters!$E$12
Name Female: 'AW calculator'!$B$4
Name Female: '[2]AW calculator'!$B$4
Name genPopUtility: [1]Parameters!$E$1783:$E$1792
Name iatrogenicHarmUtility: [1]Parameters!$E$1793
Name incidenceStage1: '[1]Intermediate Calcs'!$F$18:$AA$68
Name incidenceStage2: '[1]Intermediate Calcs'!$F$76:$AA$126
Name incidenceStage3: '[1]Intermediate Calcs'!$F$134:$AA$184
Name incidenceStage4: '[1]Intermediate Calcs'!$F$192:$AA$242
Name IncludeCancer: [1]Settings!$F$38:$F$59
Name lifetable: 'AW calculator'!$A$9:$E$109
Name lifetable: '[2]AW calculator'!$A$9:$E$109
Name minAgeBand: [1]Parameters!$E$92:$E$101
Name percFemale: [1]Parameters!$E$14
Name rngPercIatrogenic: '[1]Survival Table'!$F$106:$CO$115
Name socCompliance: [1]Parameters!$E$46:$E$67
Name socSpecificity: [1]Parameters!$E$68:$E$89
Name socTestCosts: [1]Parameters!$E$24:$E$45
Name socTestEligibility: '[1]Intermediate Calcs'!$G$248:$G$269
Name startAge: [1]Parameters!$E$11
Name tblDeaths5y: '[1]Survival Table'!$F$25:$CO$34
Name tblSurvival: '[1]Survival Table'!$F$10:$CO$19
Name testCosts: [1]Parameters!$E$1118:$E$1121
Name testSpecificity: [1]Parameters!$E$90
Name timeHorizon: [1]Parameters!$E$13
Name timeIatrogenicHarm: [1]Parameters!$E$19
Name timeShift3To1: '[1]Time Shift Lookup'!$F$29:$Y$50
Name timeShift4To1: '[1]Time Shift Lookup'!$F$55:$Y$76
Name timeShift4To2: '[1]Time Shift Lookup'!$F$81:$Y$102
Name timeShiftDist: '[1]Time Shift Lookup'!$F$10:$Y$21
Name timeShiftDistMean: '[1]Time Shift Lookup'!$E$10:$E$21
Name util: 'AW calculator'!$E$3
Name util: '[2]AW calculator'!$E$3

Sheet Raw Lung Inc&Surv
A1: stage | B1: Age_band | C1: male_incidenceper100k | E1: male_mean_survival | F1: female_incidenceper100k | G1: female_mean_survival
A2: I | B2: 50-54 | C2: 4.434902 | D2: 0.772 | E2: 26.24 | F2: 4.434902 | G2: 28.64
A3: I | B3: 55-59 | C3: 10.150356 | D3: 0.69 | E3: 21.42 | F3: 10.150356 | G3: 23.38
A4: I | B4: 60-64 | C4: 20.912485 | D4: 0.674 | E4: 17.7 | F4: 20.912485 | G4: 19.41
A5: I | B5: 65-69 | C5: 35.53529 | D5: 0.643 | E5: 13.55 | F5: 35.53529 | G5: 14.89
A6: I | B6: 70-74 | C6: 56.038109 | D6: 0.549 | E6: 10.08 | F6: 56.038109 | G6: 11.06
A7: I | B7: 75-79 | C7: 71.974258 | D7: 0.479 | E7: 9.18 | F7: 71.974258 | G7: 10.17
A8: II | B8: 50-54 | C8: 1.856267 | D8: 0.469 | E8: 18.06 | F8: 1.856267 | G8: 20.43
A9: II | B9: 55-59 | C9: 4.507937 | D9: 0.525 | E9: 14.47 | F9: 4.507937 | G9: 17
A10: II | B10: 60-64 | C10: 9.623693 | D10: 0.484 | E10: 13.07 | F10: 9.623693 | G10: 13.39
A11: II | B11: 65-69 | C11: 15.235883 | D11: 0.39 | E11: 9.01 | F11: 15.235883 | G11: 9.86
A12: II | B12: 70-74 | C12: 23.261631 | D12: 0.312 | E12: 7.18 | F12: 23.261631 | G12: 7.61
A13: II | B13: 75-79 | C13: 30.003927 | D13: 0.27 | E13: 7.25 | F13: 30.003927 | G13: 8.22
... A25: IV | B25: 75-79 | C25: 169.87109 | D25: 0.018 | E25: 4.12 | F25: 169.87109 | G25: 4.46

Sheet Corrected Inc&Surv
A1: stage | B1: Age_band | C1: incidenceper100k | D1: 5-year_net_survival | E1: male_mean_survival | F1: female_mean_survival | G1: pooled_mean_survival
A2: I | B2: 50-54 | C2: 4.434902 | D2: 0.772 | E2: 26.24 | F2: 28.64 | G2: =SUM(E2*(1-0.53) + F2*0.53) -> 27.512
A3: I | B3: 55-59 | C3: 10.150356 | D3: 0.69 | E3: 21.42 | F3: 23.38 | G3: =SUM(E3*(1-0.53) + F3*0.53) -> 22.4588
A4: I | B4: 60-64 | C4: 20.912485 | D4: 0.674 | E4: 17.7 | F4: 19.41 | G4: =SUM(E4*(1-0.53) + F4*0.53) -> 18.6063
A5: I | B5: 65-69 | C5: 35.53529 | D5: 0.643 | E5: 13.55 | F5: 14.89 | G5: =SUM(E5*(1-0.53) + F5*0.53) -> 14.2602
A6: I | B6: 70-74 | C6: 56.038109 | D6: 0.549 | E6: 10.08 | F6: 11.06 | G6: =SUM(E6*(1-0.53) + F6*0.53) -> 10.5994
A7: I | B7: 75-79 | C7: 71.974258 | D7: 0.479 | E7: 9.18 | F7: 10.17 | G7: =SUM(E7*(1-0.53) + F7*0.53) -> 9.7047
A8: II | B8: 50-54 | C8: 1.856267 | D8: 0.469 | E8: 18.06 | F8: 20.43 | G8: =SUM(E8*(1-0.53) + F8*0.53) -> 19.3161
A9: II | B9: 55-59 | C9: 4.507937 | D9: 0.525 | E9: 14.47 | F9: 17 | G9: =SUM(E9*(1-0.53) + F9*0.53) -> 15.8109
A10: II | B10: 60-64 | C10: 9.623693 | D10: 0.484 | E10: 13.07 | F10: 13.39 | G10: =SUM(E10*(1-0.53) + F10*0.53) -> 13.2396
A11: II | B11: 65-69 | C11: 15.235883 | D11: 0.39 | E11: 9.01 | F11: 9.86 | G11: =SUM(E11*(1-0.53) + F11*0.53) -> 9.4605
A12: II | B12: 70-74 | C12: 23.261631 | D12: 0.312 | E12: 7.18 | F12: 7.61 | G12: =SUM(E12*(1-0.53) + F12*0.53) -> 7.4079
A13: II | B13: 75-79 | C13: 30.003927 | D13: 0.27 | E13: =E12 -> 7.18 | F13: =F12 -> 7.61 | G13: =SUM(E13*(1-0.53) + F13*0.53) -> 7.4079
A14: III | B14: 50-54 | C14: 6.715834 | D14: 0.235 | E14: 10.05 | F14: 10.83 | G14: =SUM(E14*(1-0.53) + F14*0.53) -> 10.4634
A15: III | B15: 55-59 | C15: 14.493369 | D15: 0.18 | E15: 7.57 | F15: 8.29 | G15: =SUM(E15*(1-0.53) + F15*0.53) -> 7.9516
A16: III | B16: 60-64 | C16: 26.96892 | D16: 0.175 | E16: 6.48 | F16: 6.97 | G16: =SUM(E16*(1-0.53) + F16*0.53) -> 6.7397
A17: III | B17: 65-69 | C17: 41.374767 | D17: 0.138 | E17: 4.51 | F17: 4.63 | G17: =SUM(E17*(1-0.53) + F17*0.53) -> 4.5736
A18: III | B18: 70-74 | C18: 58.420326 | D18: 0.112 | E18: 3.46 | F18: 3.7 | G18: =SUM(E18*(1-0.53) + F18*0.53) -> 3.5872
A19: III | B19: 75-79 | C19: 73.279182 | D19: 0.096 | E19: =E18 -> 3.46 | F19: =F18 -> 3.7 | G19: =SUM(E19*(1-0.53) + F19*0.53) -> 3.5872
A20: IV | B20: 50-54 | C20: 17.516331 | D20: 0.055 | E20: 3.06 | F20: 2.87 | G20: =SUM(E20*(1-0.53) + F20*0.53) -> 2.9593
A21: IV | B21: 55-59 | C21: 35.513752 | D21: 0.045 | E21: 2.2 | F21: 2.34 | G21: =SUM(E21*(1-0.53) + F21*0.53) -> 2.2742
A22: IV | B22: 60-64 | C22: 65.085518 | D22: 0.035 | E22: 1.83 | F22: 1.94 | G22: =SUM(E22*(1-0.53) + F22*0.53) -> 1.8883
A23: IV | B23: 65-69 | C23: 99.622284 | D23: 0.027 | E23: 1.39 | F23: 1.51 | G23: =SUM(E23*(1-0.53) + F23*0.53) -> 1.4536
A24: IV | B24: 70-74 | C24: 138.44875 | D24: 0.023 | E24: 1.14 | F24: 1.28 | G24: =SUM(E24*(1-0.53) + F24*0.53) -> 1.2142
A25: IV | B25: 75-79 | C25: 169.87109 | D25: 0.018 | E25: =E24 -> 1.14 | F25: =F24 -> 1.28 | G25: =SUM(E25*(1-0.53) + F25*0.53) -> 1.2142

Sheet AW calculator
A1: NICE DSU Severity calculator - Allan Wailoo, Paul Tappenden. | N1: Calculations | Y1: Output
A2: USER INPUT VALUES | J2: Output | Z2: Males | AA2: Females | AB2: overall
A3: Discount rate | B3: 0.035 | D3: Utility source | E3: 1 | F3: (1= Hernandez 3L, 2 = PT source) | J3: AS | K3: =Z9 -> -3.9133626 | Y3: Life years | Z3: =SUMIF(P9:P109,"<>#N/A") -> 9.0301057 | AA3: =SUMIF(Q9:Q109,"<>#N/A") -> 10.319695 | AB3: =(Z3*(1-Female))+(AA3*Female) -> 9.713588
A4: Proportion female | B4: 0.53 | D4: Comparator QALE | E4: 6.03 | J4: PS | K4: =Z10 -> -1.8488583 | Y4: 1/2 cycle adjusted | Z4: =SUMIF(R9:R109,"<>#N/A") -> 9.0241602 | AA4: =SUMIF(S9:S109,"<>#N/A") -> 10.306913 | AB4: =(Z4*(1-Female))+(AA4*Female) -> 9.7040193
A5: Starting age | B5: 50 | Y5: QALYs | Z5: =SUMIF(T9:T109,"<>#N/A") -> 6.8492554 | AA5: =SUMIF(U9:U109,"<>#N/A") -> 7.147638 | AB5: =(Z5*(1-Female))+(AA5*Female) -> 7.0073982
A6: National Life Tables, England, period expectation of life, based on data for the years 2017-2019 | J6: Age-specific utility (from paper) | Y6: Disc QALYs | Z6: =SUMIF(V9:V109,"<>#N/A") -> 2.086411 | AA6: =SUMIF(W9:W109,"<>#N/A") -> 2.1434419 | AB6: =(Z6*(1-Female))+(AA6*Female) -> 2.1166374
B7: male | C7: female | D7: Active utility | F7: male | G7: female | H7: PT | P7: Proportion alive at the beginning of the period | R7: 1/2 cycle adjust | T7: utilities | V7: discounted | Y7: check | Z7: =SUM(P9:P47) -> 6.8741618 | AA7: =SUM(Q9:Q47) -> 7.3537686 | AB7: =Z7*(1-Female)+AA7*Female -> 7.1283534
A8: age | B8: qx | C8: qx | D8: Male | E8: female | F8: utility_m4 | G8: utility_f4 | H8: Male | I8: Female | J8: Age cat | K8: Cat low bound | L8: Males | M8: Females | N8: Year | O8: Age | P8: Alive males | Q8: Alive females | R8: males | S8: females | T8: males | U8: females | V8: males | W8: females
A9: 0 | B9: 0.004312 | C9: 0.003576 | D9: =IF(util=1,F9,IF(util=2,H9,"err")) -> 0.94464086 | E9: =IF(util=1,G9,IF(util=2,I9,"err")) -> 0.91032568 | F9: 0.94464086 | G9: 0.91032568 | H9: =VLOOKUP($A9,$K$9:$M$26,2) -> 0.916 | I9: =VLOOKUP($A9,$K$9:$M$26,3) -> 0.881 | J9: 0-15 | K9: 0 | L9: =L10 -> 0.916 | M9: =M10 -> 0.881 | N9: 0 | O9: =Age+N9 -> 50 | P9: 0 | Q9: 0 | R9: =(P9+P10)/2 -> 0 | S9: =(Q9+Q10)/2 -> 0 | T9: =R9*VLOOKUP(O9,lifetable,4,FALSE) -> 0 | U9: =S9*VLOOKUP(O9,lifetable,5,FALSE) -> 0 | V9: =T9/(1+Disc)^N9 -> 0 | W9: =U9/(1+Disc)^N9 -> 0 | Y9: AS | Z9: =AB6-E4 -> -3.9133626
A10: 1 | B10: 0.000242 | C10: 0.000213 | D10: =IF(util=1,F10,IF(util=2,H10,"err")) -> 0.94464086 | E10: =IF(util=1,G10,IF(util=2,I10,"err")) -> 0.91032568 | F10: 0.94464086 | G10: 0.91032568 | H10: =VLOOKUP($A10,$K$9:$M$26,2) -> 0.916 | I10: =VLOOKUP($A10,$K$9:$M$26,3) -> 0.881 | J10: 16-17 | K10: 16 | L10: 0.916 | M10: 0.881 | N10: 1 | O10: =Age+N10 -> 51 | P10: 0 | Q10: 0 | R10: =(P10+P11)/2 -> 0 | S10: =(Q10+Q11)/2 -> 0 | T10: =R10*VLOOKUP(O10,lifetable,4,FALSE) -> 0 | U10: =S10*VLOOKUP(O10,lifetable,5,FALSE) -> 0 | V10: =T10/(1+Disc)^N10 -> 0 | W10: =U10/(1+Disc)^N10 -> 0 | Y10: PS | Z10: =Z9/AB6 -> -1.8488583
A11: 2 | B11: 0.000132 | C11: 0.000125 | D11: =IF(util=1,F11,IF(util=2,H11,"err")) -> 0.94464086 | E11: =IF(util=1,G11,IF(util=2,I11,"err")) -> 0.91032568 | F11: 0.94464086 | G11: 0.91032568 | H11: =VLOOKUP($A11,$K$9:$M$26,2) -> 0.916 | I11: =VLOOKUP($A11,$K$9:$M$26,3) -> 0.881 | J11: 18-19 | K11: 18 | L11: 0.933 | M11: 0.864 | N11: 2 | O11: =Age+N11 -> 52 | P11: 0 | Q11: 0 | R11: =(P11+P12)/2 -> 0 | S11: =(Q11+Q12)/2 -> 0 | T11: =R11*VLOOKUP(O11,lifetable,4,FALSE) -> 0 | U11: =S11*VLOOKUP(O11,lifetable,5,FALSE) -> 0 | V11: =T11/(1+Disc)^N11 -> 0 | W11: =U11/(1+Disc)^N11 -> 0
A12: 3 | B12: 0.000102 | C12: 9.8e-05 | D12: =IF(util=1,F12,IF(util=2,H12,"err")) -> 0.94464086 | E12: =IF(util=1,G12,IF(util=2,I12,"err")) -> 0.91032568 | F12: 0.94464086 | G12: 0.91032568 | H12: =VLOOKUP($A12,$K$9:$M$26,2) -> 0.916 | I12: =VLOOKUP($A12,$K$9:$M$26,3) -> 0.881 | J12: 20-24 | K12: 20 | L12: 0.895 | M12: 0.866 | N12: 3 | O12: =Age+N12 -> 53 | P12: 0 | Q12: 0 | R12: =(P12+P13)/2 -> 0 | S12: =(Q12+Q13)/2 -> 0 | T12: =R12*VLOOKUP(O12,lifetable,4,FALSE) -> 0 | U12: =S12*VLOOKUP(O12,lifetable,5,FALSE) -> 0 | V12: =T12/(1+Disc)^N12 -> 0 | W12: =U12/(1+Disc)^N12 -> 0
A13: 4 | B13: 9.4e-05 | C13: 6.4e-05 | D13: =IF(util=1,F13,IF(util=2,H13,"err")) -> 0.94464086 | E13: =IF(util=1,G13,IF(util=2,I13,"err")) -> 0.91032568 | F13: 0.94464086 | G13: 0.91032568 | H13: =VLOOKUP($A13,$K$9:$M$26,2) -> 0.916 | I13: =VLOOKUP($A13,$K$9:$M$26,3) -> 0.881 | J13: 25-29 | K13: 25 | L13: 0.895 | M13: 0.873 | N13: 4 | O13: =Age+N13 -> 54 | P13: 0 | Q13: 0 | R13: =(P13+P14)/2 -> 0 | S13: =(Q13+Q14)/2 -> 0 | T13: =R13*VLOOKUP(O13,lifetable,4,FALSE) -> 0 | U13: =S13*VLOOKUP(O13,lifetable,5,FALSE) -> 0 | V13: =T13/(1+Disc)^N13 -> 0 | W13: =U13/(1+Disc)^N13 -> 0
A14: 5 | B14: 8.9e-05 | C14: 8.5e-05 | D14: =IF(util=1,F14,IF(util=2,H14,"err")) -> 0.94464086 | E14: =IF(util=1,G14,IF(util=2,I14,"err")) -> 0.91032568 | F14: 0.94464086 | G14: 0.91032568 | H14: =VLOOKUP($A14,$K$9:$M$26,2) -> 0.916 | I14: =VLOOKUP($A14,$K$9:$M$26,3) -> 0.881 | J14: 30-34 | K14: 30 | L14: 0.916 | M14: 0.87 | N14: 5 | O14: =Age+N14 -> 55 | P14: 0 | Q14: 0 | R14: =(P14+P15)/2 -> 0 | S14: =(Q14+Q15)/2 -> 0 | T14: =R14*VLOOKUP(O14,lifetable,4,FALSE) -> 0 | U14: =S14*VLOOKUP(O14,lifetable,5,FALSE) -> 0 | V14: =T14/(1+Disc)^N14 -> 0 | W14: =U14/(1+Disc)^N14 -> 0
A15: 6 | B15: 8.3e-05 | C15: 7.9e-05 | D15: =IF(util=1,F15,IF(util=2,H15,"err")) -> 0.94464086 | E15: =IF(util=1,G15,IF(util=2,I15,"err")) -> 0.91032568 | F15: 0.94464086 | G15: 0.91032568 | H15: =VLOOKUP($A15,$K$9:$M$26,2) -> 0.916 | I15: =VLOOKUP($A15,$K$9:$M$26,3) -> 0.881 | J15: 35-39 | K15: 35 | L15: 0.862 | M15: 0.857 | N15: 6 | O15: =Age+N15 -> 56 | P15: 0 | Q15: 0 | R15: =(P15+P16)/2 -> 0 | S15: =(Q15+Q16)/2 -> 0 | T15: =R15*VLOOKUP(O15,lifetable,4,FALSE) -> 0 | U15: =S15*VLOOKUP(O15,lifetable,5,FALSE) -> 0 | V15: =T15/(1+Disc)^N15 -> 0 | W15: =U15/(1+Disc)^N15 -> 0
A16: 7 | B16: 7.3e-05 | C16: 6.1e-05 | D16: =IF(util=1,F16,IF(util=2,H16,"err")) -> 0.94464086 | E16: =IF(util=1,G16,IF(util=2,I16,"err")) -> 0.91032568 | F16: 0.94464086 | G16: 0.91032568 | H16: =VLOOKUP($A16,$K$9:$M$26,2) -> 0.916 | I16: =VLOOKUP($A16,$K$9:$M$26,3) -> 0.881 | J16: 40-44 | K16: 40 | L16: 0.87 | M16: 0.85 | N16: 7 | O16: =Age+N16 -> 57 | P16: 0 | Q16: 0 | R16: =(P16+P17)/2 -> 0 | S16: =(Q16+Q17)/2 -> 0 | T16: =R16*VLOOKUP(O16,lifetable,4,FALSE) -> 0 | U16: =S16*VLOOKUP(O16,lifetable,5,FALSE) -> 0 | V16: =T16/(1+Disc)^N16 -> 0 | W16: =U16/(1+Disc)^N16 -> 0
A17: 8 | B17: 6.4e-05 | C17: 6.4e-05 | D17: =IF(util=1,F17,IF(util=2,H17,"err")) -> 0.94464086 | E17: =IF(util=1,G17,IF(util=2,I17,"err")) -> 0.91032568 | F17: 0.94464086 | G17: 0.91032568 | H17: =VLOOKUP($A17,$K$9:$M$26,2) -> 0.916 | I17: =VLOOKUP($A17,$K$9:$M$26,3) -> 0.881 | J17: 45-49 | K17: 45 | L17: 0.824 | M17: 0.815 | N17: 8 | O17: =Age+N17 -> 58 | P17: 0 | Q17: 0 | R17: =(P17+P18)/2 -> 0 | S17: =(Q17+Q18)/2 -> 0 | T17: =R17*VLOOKUP(O17,lifetable,4,FALSE) -> 0 | U17: =S17*VLOOKUP(O17,lifetable,5,FALSE) -> 0 | V17: =T17/(1+Disc)^N17 -> 0 | W17: =U17/(1+Disc)^N17 -> 0
A18: 9 | B18: 6.2e-05 | C18: 5.6e-05 | D18: =IF(util=1,F18,IF(util=2,H18,"err")) -> 0.94464086 | E18: =IF(util=1,G18,IF(util=2,I18,"err")) -> 0.91032568 | F18: 0.94464086 | G18: 0.91032568 | H18: =VLOOKUP($A18,$K$9:$M$26,2) -> 0.916 | I18: =VLOOKUP($A18,$K$9:$M$26,3) -> 0.881 | J18: 50-54 | K18: 50 | L18: 0.837 | M18: 0.805 | N18: 9 | O18: =Age+N18 -> 59 | P18: 0 | Q18: 0 | R18: =(P18+P19)/2 -> 0 | S18: =(Q18+Q19)/2 -> 0 | T18: =R18*VLOOKUP(O18,lifetable,4,FALSE) -> 0 | U18: =S18*VLOOKUP(O18,lifetable,5,FALSE) -> 0 | V18: =T18/(1+Disc)^N18 -> 0 | W18: =U18/(1+Disc)^N18 -> 0
A19: 10 | B19: 7.2e-05 | C19: 6.4e-05 | D19: =IF(util=1,F19,IF(util=2,H19,"err")) -> 0.94464086 | E19: =IF(util=1,G19,IF(util=2,I19,"err")) -> 0.91032568 | F19: 0.94464086 | G19: 0.91032568 | H19: =VLOOKUP($A19,$K$9:$M$26,2) -> 0.916 | I19: =VLOOKUP($A19,$K$9:$M$26,3) -> 0.881 | J19: 55-59 | K19: 55 | L19: 0.817 | M19: 0.802 | N19: 10 | O19: =Age+N19 -> 60 | P19: 0 | Q19: 0 | R19: =(P19+P20)/2 -> 0 | S19: =(Q19+Q20)/2 -> 0 | T19: =R19*VLOOKUP(O19,lifetable,4,FALSE) -> 0 | U19: =S19*VLOOKUP(O19,lifetable,5,FALSE) -> 0 | V19: =T19/(1+Disc)^N19 -> 0 | W19: =U19/(1+Disc)^N19 -> 0
A20: 11 | B20: 8.1e-05 | C20: 6.2e-05 | D20: =IF(util=1,F20,IF(util=2,H20,"err")) -> 0.94464086 | E20: =IF(util=1,G20,IF(util=2,I20,"err")) -> 0.91032568 | F20: 0.94464086 | G20: 0.91032568 | H20: =VLOOKUP($A20,$K$9:$M$26,2) -> 0.916 | I20: =VLOOKUP($A20,$K$9:$M$26,3) -> 0.881 | J20: 60-64 | K20: 60 | L20: 0.809 | M20: 0.784 | N20: 11 | O20: =Age+N20 -> 61 | P20: 0 | Q20: 0 | R20: =(P20+P21)/2 -> 0 | S20: =(Q20+Q21)/2 -> 0 | T20: =R20*VLOOKUP(O20,lifetable,4,FALSE) -> 0 | U20: =S20*VLOOKUP(O20,lifetable,5,FALSE) -> 0 | V20: =T20/(1+Disc)^N20 -> 0 | W20: =U20/(1+Disc)^N20 -> 0
A21: 12 | B21: 0.000105 | C21: 5.7e-05 | D21: =IF(util=1,F21,IF(util=2,H21,"err")) -> 0.94464086 | E21: =IF(util=1,G21,IF(util=2,I21,"err")) -> 0.91032568 | F21: 0.94464086 | G21: 0.91032568 | H21: =VLOOKUP($A21,$K$9:$M$26,2) -> 0.916 | I21: =VLOOKUP($A21,$K$9:$M$26,3) -> 0.881 | J21: 65-69 | K21: 65 | L21: 0.798 | M21: 0.782 | N21: 12 | O21: =Age+N21 -> 62 | P21: 0 | Q21: 0 | R21: =(P21+P22)/2 -> 0 | S21: =(Q21+Q22)/2 -> 0 | T21: =R21*VLOOKUP(O21,lifetable,4,FALSE) -> 0 | U21: =S21*VLOOKUP(O21,lifetable,5,FALSE) -> 0 | V21: =T21/(1+Disc)^N21 -> 0 | W21: =U21/(1+Disc)^N21 -> 0
A22: 13 | B22: 0.000125 | C22: 7.9e-05 | D22: =IF(util=1,F22,IF(util=2,H22,"err")) -> 0.94464086 | E22: =IF(util=1,G22,IF(util=2,I22,"err")) -> 0.91032568 | F22: 0.94464086 | G22: 0.91032568 | H22: =VLOOKUP($A22,$K$9:$M$26,2) -> 0.916 | I22: =VLOOKUP($A22,$K$9:$M$26,3) -> 0.881 | J22: 70-74 | K22: 70 | L22: 0.802 | M22: 0.787 | N22: 13 | O22: =Age+N22 -> 63 | P22: 0 | Q22: 0 | R22: =(P22+P23)/2 -> 0 | S22: =(Q22+Q23)/2 -> 0 | T22: =R22*VLOOKUP(O22,lifetable,4,FALSE) -> 0 | U22: =S22*VLOOKUP(O22,lifetable,5,FALSE) -> 0 | V22: =T22/(1+Disc)^N22 -> 0 | W22: =U22/(1+Disc)^N22 -> 0
... A26: 17 | B26: 0.000303 | C26: 0.000159 | D26: =IF(util=1,F26,IF(util=2,H26,"err")) -> 0.94333139 | E26: =IF(util=1,G26,IF(util=2,I26,"err")) -> 0.91087276 | F26: 0.94333139 | G26: 0.91087276 | H26: =VLOOKUP($A26,$K$9:$M$26,2) -> 0.916 | I26: =VLOOKUP($A26,$K$9:$M$26,3) -> 0.881 | J26: 90+ | K26: 90 | L26: 0.663 | M26: 0.665 | N26: 17 | O26: =Age+N26 -> 67 | P26: 0 | Q26: 0 | R26: =(P26+P27)/2 -> 0 | S26: =(Q26+Q27)/2 -> 0 | T26: =R26*VLOOKUP(O26,lifetable,4,FALSE) -> 0 | U26: =S26*VLOOKUP(O26,lifetable,5,FALSE) -> 0 | V26: =T26/(1+Disc)^N26 -> 0 | W26: =U26/(1+Disc)^N26 -> 0
A27: 18 | B27: 0.000387 | C27: 0.000211 | D27: =IF(util=1,F27,IF(util=2,H27,"err")) -> 0.94198997 | E27: =IF(util=1,G27,IF(util=2,I27,"err")) -> 0.911239 | F27: 0.94198997 | G27: 0.911239 | H27: =VLOOKUP($A27,$K$9:$M$26,2) -> 0.933 | I27: =VLOOKUP($A27,$K$9:$M$26,3) -> 0.864 | N27: 18 | O27: =Age+N27 -> 68 | P27: 0 | Q27: 0 | R27: =(P27+P28)/2 -> 0 | S27: =(Q27+Q28)/2 -> 0 | T27: =R27*VLOOKUP(O27,lifetable,4,FALSE) -> 0 | U27: =S27*VLOOKUP(O27,lifetable,5,FALSE) -> 0 | V27: =T27/(1+Disc)^N27 -> 0 | W27: =U27/(1+Disc)^N27 -> 0
A28: 19 | B28: 0.000415 | C28: 0.000194 | D28: =IF(util=1,F28,IF(util=2,H28,"err")) -> 0.94061612 | E28: =IF(util=1,G28,IF(util=2,I28,"err")) -> 0.9114333 | F28: 0.94061612 | G28: 0.9114333 | H28: =VLOOKUP($A28,$K$9:$M$26,2) -> 0.933 | I28: =VLOOKUP($A28,$K$9:$M$26,3) -> 0.864 | N28: 19 | O28: =Age+N28 -> 69 | P28: 0 | Q28: 0 | R28: =(P28+P29)/2 -> 0 | S28: =(Q28+Q29)/2 -> 0 | T28: =R28*VLOOKUP(O28,lifetable,4,FALSE) -> 0 | U28: =S28*VLOOKUP(O28,lifetable,5,FALSE) -> 0 | V28: =T28/(1+Disc)^N28 -> 0 | W28: =U28/(1+Disc)^N28 -> 0
A29: 20 | B29: 0.000503 | C29: 0.000179 | D29: =IF(util=1,F29,IF(util=2,H29,"err")) -> 0.93920935 | E29: =IF(util=1,G29,IF(util=2,I29,"err")) -> 0.91146389 | F29: 0.93920935 | G29: 0.91146389 | H29: =VLOOKUP($A29,$K$9:$M$26,2) -> 0.895 | I29: =VLOOKUP($A29,$K$9:$M$26,3) -> 0.866 | N29: 20 | O29: =Age+N29 -> 70 | P29: 0 | Q29: 0 | R29: =(P29+P30)/2 -> 0 | S29: =(Q29+Q30)/2 -> 0 | T29: =R29*VLOOKUP(O29,lifetable,4,FALSE) -> 0 | U29: =S29*VLOOKUP(O29,lifetable,5,FALSE) -> 0 | V29: =T29/(1+Disc)^N29 -> 0 | W29: =U29/(1+Disc)^N29 -> 0
A30: 21 | B30: 0.000498 | C30: 0.000201 | D30: =IF(util=1,F30,IF(util=2,H30,"err")) -> 0.93776916 | E30: =IF(util=1,G30,IF(util=2,I30,"err")) -> 0.91133843 | F30: 0.93776916 | G30: 0.91133843 | H30: =VLOOKUP($A30,$K$9:$M$26,2) -> 0.895 | I30: =VLOOKUP($A30,$K$9:$M$26,3) -> 0.866 | N30: 21 | O30: =Age+N30 -> 71 | P30: 0 | Q30: 0 | R30: =(P30+P31)/2 -> 0 | S30: =(Q30+Q31)/2 -> 0 | T30: =R30*VLOOKUP(O30,lifetable,4,FALSE) -> 0 | U30: =S30*VLOOKUP(O30,lifetable,5,FALSE) -> 0 | V30: =T30/(1+Disc)^N30 -> 0 | W30: =U30/(1+Disc)^N30 -> 0
A31: 22 | B31: 0.000478 | C31: 0.000215 | D31: =IF(util=1,F31,IF(util=2,H31,"err")) -> 0.93629505 | E31: =IF(util=1,G31,IF(util=2,I31,"err")) -> 0.91106401 | F31: 0.93629505 | G31: 0.91106401 | H31: =VLOOKUP($A31,$K$9:$M$26,2) -> 0.895 | I31: =VLOOKUP($A31,$K$9:$M$26,3) -> 0.866 | N31: 22 | O31: =Age+N31 -> 72 | P31: 0 | Q31: 0 | R31: =(P31+P32)/2 -> 0 | S31: =(Q31+Q32)/2 -> 0 | T31: =R31*VLOOKUP(O31,lifetable,4,FALSE) -> 0 | U31: =S31*VLOOKUP(O31,lifetable,5,FALSE) -> 0 | V31: =T31/(1+Disc)^N31 -> 0 | W31: =U31/(1+Disc)^N31 -> 0
A32: 23 | B32: 0.00047 | C32: 0.0002 | D32: =IF(util=1,F32,IF(util=2,H32,"err")) -> 0.93478653 | E32: =IF(util=1,G32,IF(util=2,I32,"err")) -> 0.91064718 | F32: 0.93478653 | G32: 0.91064718 | H32: =VLOOKUP($A32,$K$9:$M$26,2) -> 0.895 | I32: =VLOOKUP($A32,$K$9:$M$26,3) -> 0.866 | N32: 23 | O32: =Age+N32 -> 73 | P32: 0 | Q32: 0 | R32: =(P32+P33)/2 -> 0 | S32: =(Q32+Q33)/2 -> 0 | T32: =R32*VLOOKUP(O32,lifetable,4,FALSE) -> 0 | U32: =S32*VLOOKUP(O32,lifetable,5,FALSE) -> 0 | V32: =T32/(1+Disc)^N32 -> 0 | W32: =U32/(1+Disc)^N32 -> 0
A33: 24 | B33: 0.000513 | C33: 0.000218 | D33: =IF(util=1,F33,IF(util=2,H33,"err")) -> 0.93324312 | E33: =IF(util=1,G33,IF(util=2,I33,"err")) -> 0.910094 | F33: 0.93324312 | G33: 0.910094 | H33: =VLOOKUP($A33,$K$9:$M$26,2) -> 0.895 | I33: =VLOOKUP($A33,$K$9:$M$26,3) -> 0.866 | N33: 24 | O33: =Age+N33 -> 74 | P33: 0 | Q33: 0 | R33: =(P33+P34)/2 -> 0 | S33: =(Q33+Q34)/2 -> 0 | T33: =R33*VLOOKUP(O33,lifetable,4,FALSE) -> 0 | U33: =S33*VLOOKUP(O33,lifetable,5,FALSE) -> 0 | V33: =T33/(1+Disc)^N33 -> 0 | W33: =U33/(1+Disc)^N33 -> 0
A34: 25 | B34: 0.000538 | C34: 0.000244 | D34: =IF(util=1,F34,IF(util=2,H34,"err")) -> 0.93166431 | E34: =IF(util=1,G34,IF(util=2,I34,"err")) -> 0.90941003 | F34: 0.93166431 | G34: 0.90941003 | H34: =VLOOKUP($A34,$K$9:$M$26,2) -> 0.895 | I34: =VLOOKUP($A34,$K$9:$M$26,3) -> 0.873 | N34: 25 | O34: =Age+N34 -> 75 | P34: 0 | Q34: 0 | R34: =(P34+P35)/2 -> 0 | S34: =(Q34+Q35)/2 -> 0 | T34: =R34*VLOOKUP(O34,lifetable,4,FALSE) -> 0 | U34: =S34*VLOOKUP(O34,lifetable,5,FALSE) -> 0 | V34: =T34/(1+Disc)^N34 -> 0 | W34: =U34/(1+Disc)^N34 -> 0
A35: 26 | B35: 0.000543 | C35: 0.000259 | D35: =IF(util=1,F35,IF(util=2,H35,"err")) -> 0.93004962 | E35: =IF(util=1,G35,IF(util=2,I35,"err")) -> 0.90860044 | F35: 0.93004962 | G35: 0.90860044 | H35: =VLOOKUP($A35,$K$9:$M$26,2) -> 0.895 | I35: =VLOOKUP($A35,$K$9:$M$26,3) -> 0.873 | N35: 26 | O35: =Age+N35 -> 76 | P35: 0 | Q35: 0 | R35: =(P35+P36)/2 -> 0 | S35: =(Q35+Q36)/2 -> 0 | T35: =R35*VLOOKUP(O35,lifetable,4,FALSE) -> 0 | U35: =S35*VLOOKUP(O35,lifetable,5,FALSE) -> 0 | V35: =T35/(1+Disc)^N35 -> 0 | W35: =U35/(1+Disc)^N35 -> 0
A36: 27 | B36: 0.000574 | C36: 0.00027 | D36: =IF(util=1,F36,IF(util=2,H36,"err")) -> 0.92839856 | E36: =IF(util=1,G36,IF(util=2,I36,"err")) -> 0.90766993 | F36: 0.92839856 | G36: 0.90766993 | H36: =VLOOKUP($A36,$K$9:$M$26,2) -> 0.895 | I36: =VLOOKUP($A36,$K$9:$M$26,3) -> 0.873 | N36: 27 | O36: =Age+N36 -> 77 | P36: 0 | Q36: 0 | R36: =(P36+P37)/2 -> 0 | S36: =(Q36+Q37)/2 -> 0 | T36: =R36*VLOOKUP(O36,lifetable,4,FALSE) -> 0 | U36: =S36*VLOOKUP(O36,lifetable,5,FALSE) -> 0 | V36: =T36/(1+Disc)^N36 -> 0 | W36: =U36/(1+Disc)^N36 -> 0
A37: 28 | B37: 0.000629 | C37: 0.000304 | D37: =IF(util=1,F37,IF(util=2,H37,"err")) -> 0.92671065 | E37: =IF(util=1,G37,IF(util=2,I37,"err")) -> 0.90662285 | F37: 0.92671065 | G37: 0.90662285 | H37: =VLOOKUP($A37,$K$9:$M$26,2) -> 0.895 | I37: =VLOOKUP($A37,$K$9:$M$26,3) -> 0.873 | N37: 28 | O37: =Age+N37 -> 78 | P37: 0 | Q37: 0 | R37: =(P37+P38)/2 -> 0 | S37: =(Q37+Q38)/2 -> 0 | T37: =R37*VLOOKUP(O37,lifetable,4,FALSE) -> 0 | U37: =S37*VLOOKUP(O37,lifetable,5,FALSE) -> 0 | V37: =T37/(1+Disc)^N37 -> 0 | W37: =U37/(1+Disc)^N37 -> 0
A38: 29 | B38: 0.000664 | C38: 0.000302 | D38: =IF(util=1,F38,IF(util=2,H38,"err")) -> 0.92498541 | E38: =IF(util=1,G38,IF(util=2,I38,"err")) -> 0.90546319 | F38: 0.92498541 | G38: 0.90546319 | H38: =VLOOKUP($A38,$K$9:$M$26,2) -> 0.895 | I38: =VLOOKUP($A38,$K$9:$M$26,3) -> 0.873 | N38: 29 | O38: =Age+N38 -> 79 | P38: 0 | Q38: 0 | R38: =(P38+P39)/2 -> 0.5 | S38: =(Q38+Q39)/2 -> 0.5 | T38: =R38*VLOOKUP(O38,lifetable,4,FALSE) -> 0.39176323 | U38: =S38*VLOOKUP(O38,lifetable,5,FALSE) -> 0.36709955 | V38: =T38/(1+Disc)^N38 -> 0.14446197 | W38: =U38/(1+Disc)^N38 -> 0.13536728
A39: 30 | B39: 0.000711 | C39: 0.000358 | D39: =IF(util=1,F39,IF(util=2,H39,"err")) -> 0.92322236 | E39: =IF(util=1,G39,IF(util=2,I39,"err")) -> 0.90419457 | F39: 0.92322236 | G39: 0.90419457 | H39: =VLOOKUP($A39,$K$9:$M$26,2) -> 0.916 | I39: =VLOOKUP($A39,$K$9:$M$26,3) -> 0.87 | N39: 30 | O39: =Age+N39 -> 80 | P39: 1 | Q39: 1 | R39: =(P39+P40)/2 -> 0.973554 | S39: =(Q39+Q40)/2 -> 0.981175 | T39: =R39*VLOOKUP(O39,lifetable,4,FALSE) -> 0.75894717 | U39: =S39*VLOOKUP(O39,lifetable,5,FALSE) -> 0.71476395 | V39: =T39/(1+Disc)^N39 -> 0.27039649 | W39: =U39/(1+Disc)^N39 -> 0.25465496
A40: 31 | B40: 0.000772 | C40: 0.000369 | D40: =IF(util=1,F40,IF(util=2,H40,"err")) -> 0.92142102 | E40: =IF(util=1,G40,IF(util=2,I40,"err")) -> 0.90282033 | F40: 0.92142102 | G40: 0.90282033 | H40: =VLOOKUP($A40,$K$9:$M$26,2) -> 0.916 | I40: =VLOOKUP($A40,$K$9:$M$26,3) -> 0.87 | N40: 31 | O40: =Age+N40 -> 81 | P40: =P39-P39*VLOOKUP(O39,lifetable,2,FALSE) -> 0.947108 | Q40: =Q39-Q39*VLOOKUP(O39,lifetable,3,FALSE) -> 0.96235 | R40: =(P40+P41)/2 -> 0.91922467 | S40: =(Q40+Q41)/2 -> 0.94196791 | T40: =R40*VLOOKUP(O40,lifetable,4,FALSE) -> 0.71291686 | U40: =S40*VLOOKUP(O40,lifetable,5,FALSE) -> 0.68071508 | V40: =T40/(1+Disc)^N40 -> 0.24540762 | W40: =U40/(1+Disc)^N40 -> 0.23432279
A41: 32 | B41: 0.000755 | C41: 0.000436 | D41: =IF(util=1,F41,IF(util=2,H41,"err")) -> 0.91958093 | E41: =IF(util=1,G41,IF(util=2,I41,"err")) -> 0.9013435 | F41: 0.91958093 | G41: 0.9013435 | H41: =VLOOKUP($A41,$K$9:$M$26,2) -> 0.916 | I41: =VLOOKUP($A41,$K$9:$M$26,3) -> 0.87 | N41: 32 | O41: =Age+N41 -> 82 | P41: =P40-P40*VLOOKUP(O40,lifetable,2,FALSE) -> 0.89134133 | Q41: =Q40-Q40*VLOOKUP(O40,lifetable,3,FALSE) -> 0.92158582 | R41: =(P41+P42)/2 -> 0.8623255 | S41: =(Q41+Q42)/2 -> 0.89952121 | T41: =R41*VLOOKUP(O41,lifetable,4,FALSE) -> 0.66530723 | U41: =S41*VLOOKUP(O41,lifetable,5,FALSE) -> 0.64470683 | V41: =T41/(1+Disc)^N41 -> 0.22127434 | W41: =U41/(1+Disc)^N41 -> 0.21442286
A42: 33 | B42: 0.000861 | C42: 0.000451 | D42: =IF(util=1,F42,IF(util=2,H42,"err")) -> 0.91770163 | E42: =IF(util=1,G42,IF(util=2,I42,"err")) -> 0.89976685 | F42: 0.91770163 | G42: 0.89976685 | H42: =VLOOKUP($A42,$K$9:$M$26,2) -> 0.916 | I42: =VLOOKUP($A42,$K$9:$M$26,3) -> 0.87 | N42: 33 | O42: =Age+N42 -> 83 | P42: =P41-P41*VLOOKUP(O41,lifetable,2,FALSE) -> 0.83330966 | Q42: =Q41-Q41*VLOOKUP(O41,lifetable,3,FALSE) -> 0.8774566 | R42: =(P42+P43)/2 -> 0.80271262 | S42: =(Q42+Q43)/2 -> 0.85321686 | T42: =R42*VLOOKUP(O42,lifetable,4,FALSE) -> 0.61604618 | U42: =S42*VLOOKUP(O42,lifetable,5,FALSE) -> 0.60637058 | V42: =T42/(1+Disc)^N42 -> 0.19796195 | W42: =U42/(1+Disc)^N42 -> 0.19485277
A43: 34 | B43: 0.000892 | C43: 0.000525 | D43: =IF(util=1,F43,IF(util=2,H43,"err")) -> 0.91578265 | E43: =IF(util=1,G43,IF(util=2,I43,"err")) -> 0.89809286 | F43: 0.91578265 | G43: 0.89809286 | H43: =VLOOKUP($A43,$K$9:$M$26,2) -> 0.916 | I43: =VLOOKUP($A43,$K$9:$M$26,3) -> 0.87 | N43: 34 | O43: =Age+N43 -> 84 | P43: =P42-P42*VLOOKUP(O42,lifetable,2,FALSE) -> 0.77211557 | Q43: =Q42-Q42*VLOOKUP(O42,lifetable,3,FALSE) -> 0.82897712 | R43: =(P43+P44)/2 -> 0.73989094 | S43: =(Q43+Q44)/2 -> 0.80306993 | T43: =R43*VLOOKUP(O43,lifetable,4,FALSE) -> 0.56479616 | U43: =S43*VLOOKUP(O43,lifetable,5,FALSE) -> 0.56580125 | V43: =T43/(1+Disc)^N43 -> 0.17535568 | W43: =U43/(1+Disc)^N43 -> 0.17566774
...

Sheet QALYsForUndiagnosedCancer
A1: Weighred average of Discounted QALYs per person
D2: Undiagnosed Cancer | I2: Stage I | M2: Stage II | Q2: Stage III | U2: Stage IV
A3: Cycle | B3: Time (years) | C3: Age | D3: Stage I | E3: Stage II | F3: Stage III | G3: Stage IV | H3: Discounted gen pop QALYs (50 year model start age) | I3: Absolute shortfall | J3: Modifier | K3: Proportional shortfall | L3: Modifier | M3: Absolute shortfall | N3: Modifier | O3: Proportional shortfall | P3: Modifier | Q3: Absolute shortfall | R3: Modifier | S3: Proportional shortfall | T3: Modifier | U3: Absolute shortfall | V3: Modifier | W3: Proportional shortfall | X3: Modifier
A4: 1 | B4: 1 | C4: 50 | D4: =(Stage4to1!H2*Stage4to1!E2+Stage3to1!H2*Stage3to1!E2+Stage2to1!H2*Stage2to1!E2+Stage1to1!H2*Stage1to1!E2)/(Stage4to1!E2+Stage3to1!E2+Stage2to1!E2+Stage1to1!E2) -> 4.0333391 | E4: =(Stage4to2!H2*Stage4to2!E2+Stage3to2!H2*Stage3to2!E2+Stage2to2!H2*Stage2to2!E2)/(Stage4to2!E2+Stage3to2!E2+Stage2to2!E2) -> 3.1535826 | F4: =(Stage4to3!H2*Stage4to3!E2+Stage3to3!H2*Stage3to3!E2)/(Stage4to3!E2+Stage3to3!E2) -> 2.3629927 | G4: =Stage4to4!H2 -> 1.4486124 | H4: 15.926122 | I4: =H4-D4 -> 11.892783 | J4: =IF(I4<12,1,IF(I4<18,1.2,1.7)) -> 1 | K4: =I4/H4 -> 0.74674694 | L4: =IF(K4<0.85,1,IF(K4<0.95,1.2,1.7)) -> 1 | M4: =H4-E4 -> 12.772539 | N4: =IF(M4<12,1,IF(M4<18,1.2,1.7)) -> 1.2 | O4: =M4/$H4 -> 0.80198679 | P4: =IF(O4<0.85,1,IF(O4<0.95,1.2,1.7)) -> 1 | Q4: =H4-F4 -> 13.563129 | R4: =IF(Q4<12,1,IF(Q4<18,1.2,1.7)) -> 1.2 | S4: =Q4/$H4 -> 0.85162787 | T4: =IF(S4<0.85,1,IF(S4<0.95,1.2,1.7)) -> 1.2 | U4: =H4-G4 -> 14.47751 | V4: =IF(U4<12,1,IF(U4<18,1.2,1.7)) -> 1.2 | W4: =U4/H4 -> 0.90904174 | X4: =IF(W4<0.85,1,IF(W4<0.95,1.2,1.7)) -> 1.2
A5: 2 | B5: 2 | C5: 51 | D5: =(Stage4to1!H3*Stage4to1!E3+Stage3to1!H3*Stage3to1!E3+Stage2to1!H3*Stage2to1!E3+Stage1to1!H3*Stage1to1!E3)/(Stage4to1!E3+Stage3to1!E3+Stage2to1!E3+Stage1to1!E3) -> 5.5205144 | E5: =(Stage4to2!H3*Stage4to2!E3+Stage3to2!H3*Stage3to2!E3+Stage2to2!H3*Stage2to2!E3)/(Stage4to2!E3+Stage3to2!E3+Stage2to2!E3) -> 4.1783825 | F5: =(Stage4to3!H3*Stage4to3!E3+Stage3to3!H3*Stage3to3!E3)/(Stage4to3!E3+Stage3to3!E3) -> 3.2937202 | G5: =Stage4to4!H3 -> 1.4064198 | H5: 15.53249 | I5: =H5-D5 -> 10.011975 | J5: =IF(I5<12,1,IF(I5<18,1.2,1.7)) -> 1 | K5: =I5/H5 -> 0.64458278 | L5: =IF(K5<0.85,1,IF(K5<0.95,1.2,1.7)) -> 1 | M5: =H5-E5 -> 11.354107 | N5: =IF(M5<12,1,IF(M5<18,1.2,1.7)) -> 1 | O5: =M5/$H5 -> 0.73099081 | P5: =IF(O5<0.85,1,IF(O5<0.95,1.2,1.7)) -> 1 | Q5: =H5-F5 -> 12.23877 | R5: =IF(Q5<12,1,IF(Q5<18,1.2,1.7)) -> 1.2 | S5: =Q5/$H5 -> 0.78794641 | T5: =IF(S5<0.85,1,IF(S5<0.95,1.2,1.7)) -> 1 | U5: =H5-G5 -> 14.12607 | V5: =IF(U5<12,1,IF(U5<18,1.2,1.7)) -> 1.2 | W5: =U5/H5 -> 0.90945304 | X5: =IF(W5<0.85,1,IF(W5<0.95,1.2,1.7)) -> 1.2
A6: 3 | B6: 3 | C6: 52 | D6: =(Stage4to1!H4*Stage4to1!E4+Stage3to1!H4*Stage3to1!E4+Stage2to1!H4*Stage2to1!E4+Stage1to1!H4*Stage1to1!E4)/(Stage4to1!E4+Stage3to1!E4+Stage2to1!E4+Stage1to1!E4) -> 5.8412998 | E6: =(Stage4to2!H4*Stage4to2!E4+Stage3to2!H4*Stage3to2!E4+Stage2to2!H4*Stage2to2!E4)/(Stage4to2!E4+Stage3to2!E4+Stage2to2!E4) -> 4.307258 | F6: =(Stage4to3!H4*Stage4to3!E4+Stage3to3!H4*Stage3to3!E4)/(Stage4to3!E4+Stage3to3!E4) -> 3.2264569 | G6: =Stage4to4!H4 -> 1.3654561 | H6: 14.721659 | I6: =H6-D6 -> 8.8803596 | J6: =IF(I6<12,1,IF(I6<18,1.2,1.7)) -> 1 | K6: =I6/H6 -> 0.6032173 | L6: =IF(K6<0.85,1,IF(K6<0.95,1.2,1.7)) -> 1 | M6: =H6-E6 -> 10.414401 | N6: =IF(M6<12,1,IF(M6<18,1.2,1.7)) -> 1 | O6: =M6/$H6 -> 0.70742035 | P6: =IF(O6<0.85,1,IF(O6<0.95,1.2,1.7)) -> 1 | Q6: =H6-F6 -> 11.495203 | R6: =IF(Q6<12,1,IF(Q6<18,1.2,1.7)) -> 1 | S6: =Q6/$H6 -> 0.78083606 | T6: =IF(S6<0.85,1,IF(S6<0.95,1.2,1.7)) -> 1 | U6: =H6-G6 -> 13.356203 | V6: =IF(U6<12,1,IF(U6<18,1.2,1.7)) -> 1.2 | W6: =U6/H6 -> 0.90724849 | X6: =IF(W6<0.85,1,IF(W6<0.95,1.2,1.7)) -> 1.2
A7: 4 | B7: 4 | C7: 53 | D7: =(Stage4to1!H5*Stage4to1!E5+Stage3to1!H5*Stage3to1!E5+Stage2to1!H5*Stage2to1!E5+Stage1to1!H5*Stage1to1!E5)/(Stage4to1!E5+Stage3to1!E5+Stage2to1!E5+Stage1to1!E5) -> 6.1618911 | E7: =(Stage4to2!H5*Stage4to2!E5+Stage3to2!H5*Stage3to2!E5+Stage2to2!H5*Stage2to2!E5)/(Stage4to2!E5+Stage3to2!E5+Stage2to2!E5) -> 4.247165 | F7: =(Stage4to3!H5*Stage4to3!E5+Stage3to3!H5*Stage3to3!E5)/(Stage4to3!E5+Stage3to3!E5) -> 3.0467385 | G7: =Stage4to4!H5 -> 1.3133956 | H7: 13.943401 | I7: =H7-D7 -> 7.7815096 | J7: =IF(I7<12,1,IF(I7<18,1.2,1.7)) -> 1 | K7: =I7/H7 -> 0.55807832 | L7: =IF(K7<0.85,1,IF(K7<0.95,1.2,1.7)) -> 1 | M7: =H7-E7 -> 9.6962357 | N7: =IF(M7<12,1,IF(M7<18,1.2,1.7)) -> 1 | O7: =M7/$H7 -> 0.69539963 | P7: =IF(O7<0.85,1,IF(O7<0.95,1.2,1.7)) -> 1 | Q7: =H7-F7 -> 10.896662 | R7: =IF(Q7<12,1,IF(Q7<18,1.2,1.7)) -> 1 | S7: =Q7/$H7 -> 0.78149243 | T7: =IF(S7<0.85,1,IF(S7<0.95,1.2,1.7)) -> 1 | U7: =H7-G7 -> 12.630005 | V7: =IF(U7<12,1,IF(U7<18,1.2,1.7)) -> 1.2 | W7: =U7/H7 -> 0.90580522 | X7: =IF(W7<0.85,1,IF(W7<0.95,1.2,1.7)) -> 1.2
A8: 5 | B8: 5 | C8: 54 | D8: =(Stage4to1!H6*Stage4to1!E6+Stage3to1!H6*Stage3to1!E6+Stage2to1!H6*Stage2to1!E6+Stage1to1!H6*Stage1to1!E6)/(Stage4to1!E6+Stage3to1!E6+Stage2to1!E6+Stage1to1!E6) -> 6.3847421 | E8: =(Stage4to2!H6*Stage4to2!E6+Stage3to2!H6*Stage3to2!E6+Stage2to2!H6*Stage2to2!E6)/(Stage4to2!E6+Stage3to2!E6+Stage2to2!E6) -> 4.3172215 | F8: =(Stage4to3!H6*Stage4to3!E6+Stage3to3!H6*Stage3to3!E6)/(Stage4to3!E6+Stage3to3!E6) -> 2.6004237 | G8: =Stage4to4!H6 -> 1.2624804 | H8: 13.195787 | I8: =H8-D8 -> 6.8110452 | J8: =IF(I8<12,1,IF(I8<18,1.2,1.7)) -> 1 | K8: =I8/H8 -> 0.516153 | L8: =IF(K8<0.85,1,IF(K8<0.95,1.2,1.7)) -> 1 | M8: =H8-E8 -> 8.8785658 | N8: =IF(M8<12,1,IF(M8<18,1.2,1.7)) -> 1 | O8: =M8/$H8 -> 0.67283335 | P8: =IF(O8<0.85,1,IF(O8<0.95,1.2,1.7)) -> 1 | Q8: =H8-F8 -> 10.595364 | R8: =IF(Q8<12,1,IF(Q8<18,1.2,1.7)) -> 1 | S8: =Q8/$H8 -> 0.80293532 | T8: =IF(S8<0.85,1,IF(S8<0.95,1.2,1.7)) -> 1 | U8: =H8-G8 -> 11.933307 | V8: =IF(U8<12,1,IF(U8<18,1.2,1.7)) -> 1 | W8: =U8/H8 -> 0.90432701 | X8: =IF(W8<0.85,1,IF(W8<0.95,1.2,1.7)) -> 1.2
A9: 6 | B9: 6 | C9: 55 | D9: =(Stage4to1!H7*Stage4to1!E7+Stage3to1!H7*Stage3to1!E7+Stage2to1!H7*Stage2to1!E7+Stage1to1!H7*Stage1to1!E7)/(Stage4to1!E7+Stage3to1!E7+Stage2to1!E7+Stage1to1!E7) -> 5.9673047 | E9: =(Stage4to2!H7*Stage4to2!E7+Stage3to2!H7*Stage3to2!E7+Stage2to2!H7*Stage2to2!E7)/(Stage4to2!E7+Stage3to2!E7+Stage2to2!E7) -> 3.7210203 | F9: =(Stage4to3!H7*Stage4to3!E7+Stage3to3!H7*Stage3to3!E7)/(Stage4to3!E7+Stage3to3!E7) -> 2.3403977 | G9: =Stage4to4!H7 -> 0.93375707 | H9: 12.478226 | I9: =H9-D9 -> 6.5109213 | J9: =IF(I9<12,1,IF(I9<18,1.2,1.7)) -> 1 | K9: =I9/H9 -> 0.52178261 | L9: =IF(K9<0.85,1,IF(K9<0.95,1.2,1.7)) -> 1 | M9: =H9-E9 -> 8.7572057 | N9: =IF(M9<12,1,IF(M9<18,1.2,1.7)) -> 1 | O9: =M9/$H9 -> 0.70179893 | P9: =IF(O9<0.85,1,IF(O9<0.95,1.2,1.7)) -> 1 | Q9: =H9-F9 -> 10.137828 | R9: =IF(Q9<12,1,IF(Q9<18,1.2,1.7)) -> 1 | S9: =Q9/$H9 -> 0.81244147 | T9: =IF(S9<0.85,1,IF(S9<0.95,1.2,1.7)) -> 1 | U9: =H9-G9 -> 11.544469 | V9: =IF(U9<12,1,IF(U9<18,1.2,1.7)) -> 1 | W9: =U9/H9 -> 0.92516909 | X9: =IF(W9<0.85,1,IF(W9<0.95,1.2,1.7)) -> 1.2
A10: 7 | B10: 7 | C10: 56 | D10: =(Stage4to1!H8*Stage4to1!E8+Stage3to1!H8*Stage3to1!E8+Stage2to1!H8*Stage2to1!E8+Stage1to1!H8*Stage1to1!E8)/(Stage4to1!E8+Stage3to1!E8+Stage2to1!E8+Stage1to1!E8) -> 5.8303512 | E10: =(Stage4to2!H8*Stage4to2!E8+Stage3to2!H8*Stage3to2!E8+Stage2to2!H8*Stage2to2!E8)/(Stage4to2!E8+Stage3to2!E8+Stage2to2!E8) -> 3.5798499 | F10: =(Stage4to3!H8*Stage4to3!E8+Stage3to3!H8*Stage3to3!E8)/(Stage4to3!E8+Stage3to3!E8) -> 2.2703893 | G10: =Stage4to4!H8 -> 0.90656026 | H10: 11.790485 | I10: =H10-D10 -> 5.9601338 | J10: =IF(I10<12,1,IF(I10<18,1.2,1.7)) -> 1 | K10: =I10/H10 -> 0.5055037 | L10: =IF(K10<0.85,1,IF(K10<0.95,1.2,1.7)) -> 1 | M10: =H10-E10 -> 8.210635 | N10: =IF(M10<12,1,IF(M10<18,1.2,1.7)) -> 1 | O10: =M10/$H10 -> 0.69637806 | P10: =IF(O10<0.85,1,IF(O10<0.95,1.2,1.7)) -> 1 | Q10: =H10-F10 -> 9.5200956 | R10: =IF(Q10<12,1,IF(Q10<18,1.2,1.7)) -> 1 | S10: =Q10/$H10 -> 0.80743885 | T10: =IF(S10<0.85,1,IF(S10<0.95,1.2,1.7)) -> 1 | U10: =H10-G10 -> 10.883925 | V10: =IF(U10<12,1,IF(U10<18,1.2,1.7)) -> 1 | W10: =U10/H10 -> 0.92311086 | X10: =IF(W10<0.85,1,IF(W10<0.95,1.2,1.7)) -> 1.2
A11: 8 | B11: 8 | C11: 57 | D11: =(Stage4to1!H9*Stage4to1!E9+Stage3to1!H9*Stage3to1!E9+Stage2to1!H9*Stage2to1!E9+Stage1to1!H9*Stage1to1!E9)/(Stage4to1!E9+Stage3to1!E9+Stage2to1!E9+Stage1to1!E9) -> 5.6570949 | E11: =(Stage4to2!H9*Stage4to2!E9+Stage3to2!H9*Stage3to2!E9+Stage2to2!H9*Stage2to2!E9)/(Stage4to2!E9+Stage3to2!E9+Stage2to2!E9) -> 3.4033964 | F11: =(Stage4to3!H9*Stage4to3!E9+Stage3to3!H9*Stage3to3!E9)/(Stage4to3!E9+Stage3to3!E9) -> 2.1982747 | G11: =Stage4to4!H9 -> 0.88015559 | H11: 11.132279 | I11: =H11-D11 -> 5.4751844 | J11: =IF(I11<12,1,IF(I11<18,1.2,1.7)) -> 1 | K11: =I11/H11 -> 0.49182959 | L11: =IF(K11<0.85,1,IF(K11<0.95,1.2,1.7)) -> 1 | M11: =H11-E11 -> 7.728883 | N11: =IF(M11<12,1,IF(M11<18,1.2,1.7)) -> 1 | O11: =M11/$H11 -> 0.69427677 | P11: =IF(O11<0.85,1,IF(O11<0.95,1.2,1.7)) -> 1 | Q11: =H11-F11 -> 8.9340047 | R11: =IF(Q11<12,1,IF(Q11<18,1.2,1.7)) -> 1 | S11: =Q11/$H11 -> 0.80253149 | T11: =IF(S11<0.85,1,IF(S11<0.95,1.2,1.7)) -> 1 | U11: =H11-G11 -> 10.252124 | V11: =IF(U11<12,1,IF(U11<18,1.2,1.7)) -> 1 | W11: =U11/H11 -> 0.92093662 | X11: =IF(W11<0.85,1,IF(W11<0.95,1.2,1.7)) -> 1.2
A12: 9 | B12: 9 | C12: 58 | D12: =(Stage4to1!H10*Stage4to1!E10+Stage3to1!H10*Stage3to1!E10+Stage2to1!H10*Stage2to1!E10+Stage1to1!H10*Stage1to1!E10)/(Stage4to1!E10+Stage3to1!E10+Stage2to1!E10+Stage1to1!E10) -> 5.5152724 | E12: =(Stage4to2!H10*Stage4to2!E10+Stage3to2!H10*Stage3to2!E10+Stage2to2!H10*Stage2to2!E10)/(Stage4to2!E10+Stage3to2!E10+Stage2to2!E10) -> 3.2097637 | F12: =(Stage4to3!H10*Stage4to3!E10+Stage3to3!H10*Stage3to3!E10)/(Stage4to3!E10+Stage3to3!E10) -> 2.0909317 | G12: =Stage4to4!H10 -> 0.85451999 | H12: 10.501916 | I12: =H12-D12 -> 4.9866432 | J12: =IF(I12<12,1,IF(I12<18,1.2,1.7)) -> 1 | K12: =I12/H12 -> 0.47483178 | L12: =IF(K12<0.85,1,IF(K12<0.95,1.2,1.7)) -> 1 | M12: =H12-E12 -> 7.2921519 | N12: =IF(M12<12,1,IF(M12<18,1.2,1.7)) -> 1 | O12: =M12/$H12 -> 0.69436398 | P12: =IF(O12<0.85,1,IF(O12<0.95,1.2,1.7)) -> 1 | Q12: =H12-F12 -> 8.4109839 | R12: =IF(Q12<12,1,IF(Q12<18,1.2,1.7)) -> 1 | S12: =Q12/$H12 -> 0.80089997 | T12: =IF(S12<0.85,1,IF(S12<0.95,1.2,1.7)) -> 1 | U12: =H12-G12 -> 9.6473956 | V12: =IF(U12<12,1,IF(U12<18,1.2,1.7)) -> 1 | W12: =U12/H12 -> 0.91863199 | X12: =IF(W12<0.85,1,IF(W12<0.95,1.2,1.7)) -> 1.2
A13: 10 | B13: 10 | C13: 59 | D13: =(Stage4to1!H11*Stage4to1!E11+Stage3to1!H11*Stage3to1!E11+Stage2to1!H11*Stage2to1!E11+Stage1to1!H11*Stage1to1!E11)/(Stage4to1!E11+Stage3to1!E11+Stage2to1!E11+Stage1to1!E11) -> 5.4156629 | E13: =(Stage4to2!H11*Stage4to2!E11+Stage3to2!H11*Stage3to2!E11+Stage2to2!H11*Stage2to2!E11)/(Stage4to2!E11+Stage3to2!E11+Stage2to2!E11) -> 3.1628004 | F13: =(Stage4to3!H11*Stage4to3!E11+Stage3to3!H11*Stage3to3!E11)/(Stage4to3!E11+Stage3to3!E11) -> 1.8382123 | G13: =Stage4to4!H11 -> 0.82963106 | H13: 9.898711 | I13: =H13-D13 -> 4.4830481 | J13: =IF(I13<12,1,IF(I13<18,1.2,1.7)) -> 1 | K13: =I13/H13 -> 0.45289211 | L13: =IF(K13<0.85,1,IF(K13<0.95,1.2,1.7)) -> 1 | M13: =H13-E13 -> 6.7359105 | N13: =IF(M13<12,1,IF(M13<18,1.2,1.7)) -> 1 | O13: =M13/$H13 -> 0.6804836 | P13: =IF(O13<0.85,1,IF(O13<0.95,1.2,1.7)) -> 1 | Q13: =H13-F13 -> 8.0604987 | R13: =IF(Q13<12,1,IF(Q13<18,1.2,1.7)) -> 1 | S13: =Q13/$H13 -> 0.81429781 | T13: =IF(S13<0.85,1,IF(S13<0.95,1.2,1.7)) -> 1 | U13: =H13-G13 -> 9.0690799 | V13: =IF(U13<12,1,IF(U13<18,1.2,1.7)) -> 1 | W13: =U13/H13 -> 0.91618797 | X13: =IF(W13<0.85,1,IF(W13<0.95,1.2,1.7)) -> 1.2
A14: 11 | B14: 11 | C14: 60 | D14: =(Stage4to1!H12*Stage4to1!E12+Stage3to1!H12*Stage3to1!E12+Stage2to1!H12*Stage2to1!E12+Stage1to1!H12*Stage1to1!E12)/(Stage4to1!E12+Stage3to1!E12+Stage2to1!E12+Stage1to1!E12) -> 5.0810513 | E14: =(Stage4to2!H12*Stage4to2!E12+Stage3to2!H12*Stage3to2!E12+Stage2to2!H12*Stage2to2!E12)/(Stage4to2!E12+Stage3to2!E12+Stage2to2!E12) -> 2.9014166 | F14: =(Stage4to3!H12*Stage4to3!E12+Stage3to3!H12*Stage3to3!E12)/(Stage4to3!E12+Stage3to3!E12) -> 1.731879 | G14: =Stage4to4!H12 -> 0.67297734 | H14: 9.3210337 | I14: =H14-D14 -> 4.2399824 | J14: =IF(I14<12,1,IF(I14<18,1.2,1.7)) -> 1 | K14: =I14/H14 -> 0.45488329 | L14: =IF(K14<0.85,1,IF(K14<0.95,1.2,1.7)) -> 1 | M14: =H14-E14 -> 6.4196171 | N14: =IF(M14<12,1,IF(M14<18,1.2,1.7)) -> 1 | O14: =M14/$H14 -> 0.68872373 | P14: =IF(O14<0.85,1,IF(O14<0.95,1.2,1.7)) -> 1 | Q14: =H14-F14 -> 7.5891547 | R14: =IF(Q14<12,1,IF(Q14<18,1.2,1.7)) -> 1 | S14: =Q14/$H14 -> 0.81419668 | T14: =IF(S14<0.85,1,IF(S14<0.95,1.2,1.7)) -> 1 | U14: =H14-G14 -> 8.6480564 | V14: =IF(U14<12,1,IF(U14<18,1.2,1.7)) -> 1 | W14: =U14/H14 -> 0.92780014 | X14: =IF(W14<0.85,1,IF(W14<0.95,1.2,1.7)) -> 1.2
A15: 12 | B15: 12 | C15: 61 | D15: =(Stage4to1!H13*Stage4to1!E13+Stage3to1!H13*Stage3to1!E13+Stage2to1!H13*Stage2to1!E13+Stage1to1!H13*Stage1to1!E13)/(Stage4to1!E13+Stage3to1!E13+Stage2to1!E13+Stage1to1!E13) -> 4.8864738 | E15: =(Stage4to2!H13*Stage4to2!E13+Stage3to2!H13*Stage3to2!E13+Stage2to2!H13*Stage2to2!E13)/(Stage4to2!E13+Stage3to2!E13+Stage2to2!E13) -> 2.7976582 | F15: =(Stage4to3!H13*Stage4to3!E13+Stage3to3!H13*Stage3to3!E13)/(Stage4to3!E13+Stage3to3!E13) -> 1.6797766 | G15: =Stage4to4!H13 -> 0.65337606 | H15: 8.7689619 | I15: =H15-D15 -> 3.8824881 | J15: =IF(I15<12,1,IF(I15<18,1.2,1.7)) -> 1 | K15: =I15/H15 -> 0.44275344 | L15: =IF(K15<0.85,1,IF(K15<0.95,1.2,1.7)) -> 1 | M15: =H15-E15 -> 5.9713037 | N15: =IF(M15<12,1,IF(M15<18,1.2,1.7)) -> 1 | O15: =M15/$H15 -> 0.68095902 | P15: =IF(O15<0.85,1,IF(O15<0.95,1.2,1.7)) -> 1 | Q15: =H15-F15 -> 7.0891853 | R15: =IF(Q15<12,1,IF(Q15<18,1.2,1.7)) -> 1 | S15: =Q15/$H15 -> 0.80844066 | T15: =IF(S15<0.85,1,IF(S15<0.95,1.2,1.7)) -> 1 | U15: =H15-G15 -> 8.1155858 | V15: =IF(U15<12,1,IF(U15<18,1.2,1.7)) -> 1 | W15: =U15/H15 -> 0.92548992 | X15: =IF(W15<0.85,1,IF(W15<0.95,1.2,1.7)) -> 1.2
... A34: 31 | B34: 31 | C34: 80 | D34: =(Stage4to1!H32*Stage4to1!E32+Stage3to1!H32*Stage3to1!E32+Stage2to1!H32*Stage2to1!E32+Stage1to1!H32*Stage1to1!E32)/(Stage4to1!E32+Stage3to1!E32+Stage2to1!E32+Stage1to1!E32) -> 2.0088517 | E34: =(Stage4to2!H32*Stage4to2!E32+Stage3to2!H32*Stage3to2!E32+Stage2to2!H32*Stage2to2!E32)/(Stage4to2!E32+Stage3to2!E32+Stage2to2!E32) -> 1.0434433 | F34: =(Stage4to3!H32*Stage4to3!E32+Stage3to3!H32*Stage3to3!E32)/(Stage4to3!E32+Stage3to3!E32) -> 0.41675804 | G34: =Stage4to4!H32 -> 0.21910549 | H34: 2.1166374 | I34: =H34-D34 -> 0.10778565 | J34: =IF(I34<12,1,IF(I34<18,1.2,1.7)) -> 1 | K34: =I34/H34 -> 0.050923059 | L34: =IF(K34<0.85,1,IF(K34<0.95,1.2,1.7)) -> 1 | M34: =H34-E34 -> 1.0731941 | N34: =IF(M34<12,1,IF(M34<18,1.2,1.7)) -> 1 | O34: =M34/$H34 -> 0.50702783 | P34: =IF(O34<0.85,1,IF(O34<0.95,1.2,1.7)) -> 1 | Q34: =H34-F34 -> 1.6998793 | R34: =IF(Q34<12,1,IF(Q34<18,1.2,1.7)) -> 1 | S34: =Q34/$H34 -> 0.80310371 | T34: =IF(S34<0.85,1,IF(S34<0.95,1.2,1.7)) -> 1 | U34: =H34-G34 -> 1.8975319 | V34: =IF(U34<12,1,IF(U34<18,1.2,1.7)) -> 1 | W34: =U34/H34 -> 0.89648416 | X34: =IF(W34<0.85,1,IF(W34<0.95,1.2,1.7)) -> 1.2

Sheet Stage4to1
A1: Cycle | B1: Time (years) | C1: Age | D1: Engine - SoC Markov trace - Stage 4 | E1: Engine - Galleri Markov trace - Stage 1 | F1: Post-diagnosis calculation - QALYs Galleri | G1: Per patient QALYs | H1: Per patient QALYs
A2: 1 | B2: 1 | C2: 50 | D2: 17.516331 | E2: 110.38722 | F2: 35.872476 | G2: =F2/E2 -> 0.32496947 | H2: =F2/D2 -> 2.0479446
A3: 2 | B3: 2 | C3: 51 | D3: 17.450387 | E3: 28.363546 | F3: 47.080199 | G3: =F3/E3 -> 1.6598841 | H3: =F3/D3 -> 2.6979457
A4: 3 | B4: 3 | C4: 52 | D4: 17.3793 | E4: 33.177609 | F4: 57.039266 | G4: =F4/E4 -> 1.7192097 | H4: =F4/D4 -> 3.2820232
A5: 4 | B5: 4 | C5: 53 | D5: 17.302532 | E5: 37.783852 | F5: 65.857353 | G5: =F5/E5 -> 1.7430026 | H5: =F5/D5 -> 3.8062264
A6: 5 | B6: 5 | C6: 54 | D6: 17.219041 | E6: 40.928609 | F6: 71.100716 | G6: =F6/E6 -> 1.7371887 | H6: =F6/D6 -> 4.1291914
A7: 6 | B7: 6 | C7: 55 | D7: 34.726033 | E7: 44.767771 | F7: 133.09048 | G7: =F7/E7 -> 2.9729082 | H7: =F7/D7 -> 3.8325851
A8: 7 | B8: 7 | C8: 56 | D8: 34.518061 | E8: 50.307546 | F8: 134.37285 | G8: =F8/E8 -> 2.6710277 | H8: =F8/D8 -> 3.8928272
A9: 8 | B9: 8 | C9: 57 | D9: 34.293415 | E9: 57.271399 | F9: 133.17105 | G9: =F9/E9 -> 2.3252627 | H9: =F9/D9 -> 3.8832834
A10: 9 | B10: 9 | C10: 58 | D10: 34.052456 | E10: 63.610786 | F10: 130.78837 | G10: =F10/E10 -> 2.0560722 | H10: =F10/D10 -> 3.8407911
A11: 10 | B11: 10 | C11: 59 | D11: 33.794983 | E11: 67.022425 | F11: 127.53655 | G11: =F11/E11 -> 1.9028937 | H11: =F11/D11 -> 3.773831
A12: 11 | B12: 11 | C12: 60 | D12: 61.432238 | E12: 70.832079 | F12: 213.60951 | G12: =F12/E12 -> 3.0157171 | H12: =F12/D12 -> 3.4771565
A13: 12 | B13: 12 | C13: 61 | D13: 60.877817 | E13: 76.448018 | F13: 206.47029 | G13: =F13/E13 -> 2.7007933 | H13: =F13/D13 -> 3.3915522
... A32: 31 | B32: 31 | C32: 80 | D32: 106.69068 | E32: 84.058785 | F32: 169.81591 | G32: =F32/E32 -> 2.0202042 | H32: =F32/D32 -> 1.5916658
A33: 32 | B33: 32 | C33: 81 | D33: 101.92128
A34: 33 | B34: 33 | C34: 82 | D34: 96.901969
A35: 34 | B35: 34 | C35: 83 | D35: 91.59712
A36: 35 | B36: 35 | C36: 84 | D36: 86.023244
A37: 36 | B37: 36 | C37: 85 | D37: 80.212064
A38: 37 | B38: 37 | C38: 86 | D38: 74.113011
A39: 38 | B39: 38 | C39: 87 | D39: 67.849565
A40: 39 | B40: 39 | C40: 88 | D40: 61.527719
A41: 40 | B41: 40 | C41: 89 | D41: 55.086552
A42: 41 | B42: 41 | C42: 90 | D42: 48.621821
A43: 42 | B43: 42 | C43: 91 | D43: 42.241519
A44: 43 | B44: 43 | C44: 92 | D44: 36.060968
... A51: 50 | B51: 50 | C51: 99 | D51: 6.2424834

Sheet Stage3to1
A1: Cycle | B1: Time (years) | C1: Age | D1: Engine - SoC Markov trace - Stage 3 | E1: Engine - Galleri Markov trace - Stage 1 | F1: Post-diagnosis calculation - QALYs Galleri | G1: Per patient QALYs | H1: Per patient QALYs
A2: 1 | B2: 1 | C2: 50 | D2: 6.715834 | E2: 37.62591 | F2: 46.766535 | G2: =F2/E2 -> 1.2429343 | H2: =F2/D2 -> 6.9636228
A3: 2 | B3: 2 | C3: 51 | D3: 6.6912737 | E3: 10.460236 | F3: 50.677879 | G3: =F3/E3 -> 4.8448123 | H3: =F3/D3 -> 7.5737268
A4: 3 | B4: 3 | C4: 52 | D4: 6.6647354 | E4: 12.37482 | F4: 53.925961 | G4: =F4/E4 -> 4.3577168 | H4: =F4/D4 -> 8.0912381
A5: 4 | B5: 4 | C5: 53 | D5: 6.6360126 | E5: 14.604694 | F5: 55.665058 | G5: =F5/E5 -> 3.8114498 | H5: =F5/D5 -> 8.3883292
A6: 5 | B6: 5 | C6: 54 | D6: 6.6047049 | E6: 16.09038 | F6: 56.103293 | G6: =F6/E6 -> 3.48676 | H6: =F6/D6 -> 8.4944435
A7: 6 | B7: 6 | C7: 55 | D7: 14.179552 | E7: 17.383292 | F7: 100.2709 | G7: =F7/E7 -> 5.7682345 | H7: =F7/D7 -> 7.0715141
A8: 7 | B8: 7 | C8: 56 | D8: 14.097596 | E8: 19.477181 | F8: 98.508481 | G8: =F8/E8 -> 5.0576354 | H8: =F8/D8 -> 6.9876086
A9: 8 | B9: 8 | C9: 57 | D9: 14.008793 | E9: 22.214931 | F9: 95.897603 | G9: =F9/E9 -> 4.3168084 | H9: =F9/D9 -> 6.8455293
A10: 9 | B10: 9 | C10: 58 | D10: 13.913287 | E10: 25.390444 | F10: 93.03335 | G10: =F10/E10 -> 3.6641088 | H10: =F10/D10 -> 6.6866552
A11: 10 | B11: 10 | C11: 59 | D11: 13.810991 | E11: 27.187006 | F11: 89.941586 | G11: =F11/E11 -> 3.3082564 | H11: =F11/D11 -> 6.5123197
A12: 11 | B12: 11 | C12: 60 | D12: 25.495683 | E12: 28.446286 | F12: 146.30855 | G12: =F12/E12 -> 5.1433271 | H12: =F12/D12 -> 5.7385618
A13: 12 | B13: 12 | C13: 61 | D13: 25.275223 | E13: 30.557667 | F13: 140.93752 | G13: =F13/E13 -> 4.6121821 | H13: =F13/D13 -> 5.576114
... A32: 31 | B32: 31 | C32: 80 | D32: 46.731753 | E32: 38.232176 | F32: 96.869292 | G32: =F32/E32 -> 2.5337112 | H32: =F32/D32 -> 2.0728795
A33: 32 | B33: 32 | C33: 81 | D33: 44.685895
A34: 33 | B34: 33 | C34: 82 | D34: 42.526358
A35: 34 | B35: 34 | C35: 83 | D35: 40.237169
A36: 35 | B36: 35 | C36: 84 | D36: 37.825216
A37: 36 | B37: 36 | C37: 85 | D37: 35.304112
A38: 37 | B38: 37 | C38: 86 | D38: 32.651269
A39: 38 | B39: 38 | C39: 87 | D39: 29.920764
A40: 39 | B40: 39 | C40: 88 | D40: 27.159166
A41: 40 | B41: 40 | C41: 89 | D41: 24.339475
A42: 41 | B42: 41 | C42: 90 | D42: 21.503881
A43: 42 | B43: 42 | C43: 91 | D43: 18.700153
A44: 43 | B44: 43 | C44: 92 | D44: 15.979494
... A51: 50 | B51: 50 | C51: 99 | D51: 2.7849862

Sheet Stage2to1
A1: Cycle | B1: Time (years) | C1: Age | D1: Engine - SoC Markov trace - Stage 2 | E1: Engine - Galleri Markov trace - Stage 1 | F1: Post-diagnosis calculation - QALYs Galleri | G1: Per patient QALYs | H1: Per patient QALYs
A2: 1 | B2: 1 | C2: 50 | D2: 1.856267 | E2: 7.5530275 | F2: 21.717878 | G2: =F2/E2 -> 2.8753871 | H2: =F2/D2 -> 11.69976
A3: 2 | B3: 2 | C3: 51 | D3: 1.8495684 | E3: 2.4971926 | F3: 22.496899 | G3: =F3/E3 -> 9.0088761 | H3: =F3/D3 -> 12.163324
A4: 3 | B4: 3 | C4: 52 | D4: 1.8423223 | E4: 2.9219941 | F4: 22.635268 | G4: =F4/E4 -> 7.7465139 | H4: =F4/D4 -> 12.286269
A5: 4 | B5: 4 | C5: 53 | D5: 1.8344717 | E5: 3.6274648 | F5: 22.393814 | G5: =F5/E5 -> 6.1734061 | H5: =F5/D5 -> 12.207228
A6: 5 | B6: 5 | C6: 54 | D6: 1.8259057 | E6: 4.796144 | F6: 21.929399 | G6: =F6/E6 -> 4.572298 | H6: =F6/D6 -> 12.010149
A7: 6 | B7: 6 | C7: 55 | D7: 4.411401 | E7: 5.0460848 | F7: 45.182412 | G7: =F7/E7 -> 8.9539541 | H7: =F7/D7 -> 10.242191
A8: 7 | B8: 7 | C8: 56 | D8: 4.3863415 | E8: 5.4740291 | F8: 43.829818 | G8: =F8/E8 -> 8.0068661 | H8: =F8/D8 -> 9.9923407
A9: 8 | B9: 8 | C9: 57 | D9: 4.3591466 | E9: 6.197229 | F9: 42.402796 | G9: =F9/E9 -> 6.8422187 | H9: =F9/D9 -> 9.727316
A10: 9 | B10: 9 | C10: 58 | D10: 4.32986 | E10: 7.4085791 | F10: 40.944858 | G10: =F10/E10 -> 5.5266816 | H10: =F10/D10 -> 9.4563929
A11: 10 | B11: 10 | C11: 59 | D11: 4.2984544 | E11: 9.4261278 | F11: 39.39533 | G11: =F11/E11 -> 4.1793758 | H11: =F11/D11 -> 9.1649989
A12: 11 | B12: 11 | C12: 60 | D12: 9.1047335 | E12: 9.6345642 | F12: 72.244968 | G12: =F12/E12 -> 7.4985195 | H12: =F12/D12 -> 7.93488
A13: 12 | B13: 12 | C13: 61 | D13: 9.0275713 | E13: 10.028271 | F13: 69.455506 | G13: =F13/E13 -> 6.9259703 | H13: =F13/D13 -> 7.693709
... A32: 31 | B32: 31 | C32: 80 | D32: 19.265504 | E32: 16.956604 | F32: 51.64136 | G32: =F32/E32 -> 3.0455014 | H32: =F32/D32 -> 2.6805091
A33: 32 | B33: 32 | C33: 81 | D33: 18.430063
A34: 33 | B34: 33 | C34: 82 | D34: 17.546988
A35: 34 | B35: 34 | C35: 83 | D35: 16.609626
A36: 35 | B36: 35 | C36: 84 | D36: 15.62075
A37: 36 | B37: 36 | C37: 85 | D37: 14.585919
A38: 37 | B38: 37 | C38: 86 | D38: 13.495737
A39: 38 | B39: 38 | C39: 87 | D39: 12.372494
A40: 39 | B40: 39 | C40: 88 | D40: 11.235413
A41: 40 | B41: 40 | C41: 89 | D41: 10.073302
A42: 41 | B42: 41 | C42: 90 | D42: 8.9035981
A43: 42 | B43: 42 | C43: 91 | D43: 7.7460786
A44: 43 | B44: 43 | C44: 92 | D44: 6.6219789
... A51: 50 | B51: 50 | C51: 99 | D51: 1.1576149

Sheet Stage1to1
A1: Cycle | B1: Time (years) | C1: Age | D1: Engine - SoC Markov trace - Stage 1 | E1: Engine - Galleri Markov trace - Stage 1 | F1: Post-diagnosis calculation - QALYs Galleri | G1: Per patient QALYs | H1: Per patient QALYs
A2: 1 | B2: 1 | C2: 50 | D2: 4.434902 | E2: 4.434902 | F2: 68.890365 | G2: =F2/E2 -> 15.533684 | H2: =F2/D2 -> 15.533684
A3: 2 | B3: 2 | C3: 51 | D3: 4.418784 | E3: 4.418784 | F3: 66.386556 | G3: =F3/E3 -> 15.023716 | H3: =F3/D3 -> 15.023716
A4: 3 | B4: 3 | C4: 52 | D4: 4.4013591 | E4: 4.4013591 | F4: 63.945591 | G4: =F4/E4 -> 14.528601 | H4: =F4/D4 -> 14.528601
A5: 4 | B5: 4 | C5: 53 | D5: 4.3824906 | E5: 4.3824906 | F5: 61.564823 | G5: =F5/E5 -> 14.047908 | H5: =F5/D5 -> 14.047908
A6: 5 | B6: 5 | C6: 54 | D6: 4.3619142 | E6: 4.3619142 | F6: 59.240094 | G6: =F6/E6 -> 13.581215 | H6: =F6/D6 -> 13.581215
A7: 6 | B7: 6 | C7: 55 | D7: 9.9317088 | E7: 9.9317088 | F7: 114.06594 | G7: =F7/E7 -> 11.485026 | H7: =F7/D7 -> 11.485026
A8: 7 | B8: 7 | C8: 56 | D8: 9.8747332 | E8: 9.8747332 | F8: 109.72227 | G8: =F8/E8 -> 11.111417 | H8: =F8/D8 -> 11.111417
A9: 8 | B9: 8 | C9: 57 | D9: 9.8129571 | E9: 9.8129571 | F9: 105.47642 | G9: =F9/E9 -> 10.748689 | H9: =F9/D9 -> 10.748689
A10: 9 | B10: 9 | C10: 58 | D10: 9.7464796 | E10: 9.7464796 | F10: 101.32952 | G10: =F10/E10 -> 10.396526 | H10: =F10/D10 -> 10.396526
A11: 10 | B11: 10 | C11: 59 | D11: 9.6752399 | E11: 9.6752399 | F11: 97.280858 | G11: =F11/E11 -> 10.05462 | H11: =F11/D11 -> 10.05462
A12: 11 | B12: 11 | C12: 60 | D12: 19.776644 | E12: 19.776644 | F12: 167.89421 | G12: =F12/E12 -> 8.48952 | H12: =F12/D12 -> 8.48952
A13: 12 | B13: 12 | C13: 61 | D13: 19.606824 | E13: 19.606824 | F13: 160.86652 | G13: =F13/E13 -> 8.2046191 | H13: =F13/D13 -> 8.2046191
... A32: 31 | B32: 31 | C32: 80 | D32: 45.950582 | E32: 45.950582 | F32: 113.53909 | G32: =F32/E32 -> 2.4708956 | H32: =F32/D32 -> 2.4708956
A33: 32 | B33: 32 | C33: 81 | D33: 43.939497
A34: 33 | B34: 33 | C34: 82 | D34: 41.816577
A35: 34 | B35: 34 | C35: 83 | D35: 39.566112
A36: 35 | B36: 35 | C36: 84 | D36: 37.19487
A37: 36 | B37: 36 | C37: 85 | D37: 34.716233
A38: 37 | B38: 37 | C38: 86 | D38: 32.107984
A39: 38 | B39: 38 | C39: 87 | D39: 29.423296
A40: 39 | B40: 39 | C40: 88 | D40: 26.707962
A41: 40 | B41: 40 | C41: 89 | D41: 23.935428
A42: 41 | B42: 41 | C42: 90 | D42: 21.147182
A43: 42 | B43: 42 | C43: 91 | D43: 18.390202
A44: 43 | B44: 43 | C44: 92 | D44: 15.714842
... A51: 50 | B51: 50 | C51: 99 | D51: 2.7391118

Sheet Stage4to2
A1: Cycle | B1: Time (years) | C1: Age | D1: Engine - SoC Markov trace - Stage 4 | E1: Engine - Galleri Markov trace - Stage 2 | F1: Post-diagnosis calculation - QALYs Galleri | G1: Per patient QALYs | H1: Per patient QALYs
A2: 1 | B2: 1 | C2: 50 | D2: 17.516331 | E2: 57.409838 | F2: 31.982689 | G2: =F2/E2 -> 0.55709423 | H2: =F2/D2 -> 1.8258783
A3: 2 | B3: 2 | C3: 51 | D3: 17.450387 | E3: 19.498625 | F3: 41.975117 | G3: =F3/E3 -> 2.1527219 | H3: =F3/D3 -> 2.4053974
A4: 3 | B4: 3 | C4: 52 | D4: 17.3793 | E4: 22.724633 | F4: 48.006352 | G4: =F4/E4 -> 2.1125248 | H4: =F4/D4 -> 2.7622719
A5: 4 | B5: 4 | C5: 53 | D5: 17.302532 | E5: 29.555802 | F5: 50.537009 | G5: =F5/E5 -> 1.7098845 | H5: =F5/D5 -> 2.9207869
A6: 5 | B6: 5 | C6: 54 | D6: 17.219041 | E6: 34.958892 | F6: 50.30775 | G6: =F6/E6 -> 1.4390545 | H6: =F6/D6 -> 2.9216348
A7: 6 | B7: 6 | C7: 55 | D7: 34.726033 | E7: 35.622045 | F7: 85.751094 | G7: =F7/E7 -> 2.4072479 | H7: =F7/D7 -> 2.4693605
A8: 7 | B8: 7 | C8: 56 | D8: 34.518061 | E8: 37.484844 | F8: 82.8665 | G8: =F8/E8 -> 2.2106668 | H8: =F8/D8 -> 2.4006708
A9: 8 | B9: 8 | C9: 57 | D9: 34.293415 | E9: 42.464169 | F9: 79.948894 | G9: =F9/E9 -> 1.8827377 | H9: =F9/D9 -> 2.3313191
A10: 9 | B10: 9 | C10: 58 | D10: 34.052456 | E10: 53.058904 | F10: 77.032813 | G10: =F10/E10 -> 1.4518357 | H10: =F10/D10 -> 2.2621808
A11: 10 | B11: 10 | C11: 59 | D11: 33.794983 | E11: 61.281214 | F11: 74.224106 | G11: =F11/E11 -> 1.2112049 | H11: =F11/D11 -> 2.1963055
A12: 11 | B12: 11 | C12: 60 | D12: 61.432238 | E12: 61.667803 | F12: 119.84976 | G12: =F12/E12 -> 1.9434739 | H12: =F12/D12 -> 1.9509262
A13: 12 | B13: 12 | C13: 61 | D13: 60.877817 | E13: 63.365181 | F13: 115.30186 | G13: =F13/E13 -> 1.8196406 | H13: =F13/D13 -> 1.8939881
... A32: 31 | B32: 31 | C32: 80 | D32: 106.69068 | E32: 95.587703 | F32: 88.024586 | G32: =F32/E32 -> 0.92087772 | H32: =F32/D32 -> 0.82504475
A33: 32 | B33: 32 | C33: 81 | D33: 101.92128
A34: 33 | B34: 33 | C34: 82 | D34: 96.901969
A35: 34 | B35: 34 | C35: 83 | D35: 91.59712
A36: 35 | B36: 35 | C36: 84 | D36: 86.023244
A37: 36 | B37: 36 | C37: 85 | D37: 80.212064
A38: 37 | B38: 37 | C38: 86 | D38: 74.113011
A39: 38 | B39: 38 | C39: 87 | D39: 67.849565
A40: 39 | B40: 39 | C40: 88 | D40: 61.527719
A41: 40 | B41: 40 | C41: 89 | D41: 55.086552
A42: 41 | B42: 41 | C42: 90 | D42: 48.621821
A43: 42 | B43: 42 | C43: 91 | D43: 42.241519
A44: 43 | B44: 43 | C44: 92 | D44: 36.060968
... A51: 50 | B51: 50 | C51: 99 | D51: 6.2424834

Sheet Stage3to2
A1: Cycle | B1: Time (years) | C1: Age | D1: Engine - SoC Markov trace - Stage 3 | E1: Engine - Galleri Markov trace - Stage 2 | F1: Post-diagnosis calculation - QALYs Galleri | G1: Per patient QALYs | H1: Per patient QALYs
A2: 1 | B2: 1 | C2: 50 | D2: 6.715834 | E2: 17.497552 | F2: 44.342242 | G2: =F2/E2 -> 2.5341969 | H2: =F2/D2 -> 6.6026412
A3: 2 | B3: 2 | C3: 51 | D3: 6.6912737 | E3: 7.0285362 | F3: 48.262452 | G3: =F3/E3 -> 6.8666435 | H3: =F3/D3 -> 7.2127452
A4: 3 | B4: 3 | C4: 52 | D4: 6.6647354 | E4: 7.6536484 | F4: 48.569037 | G4: =F4/E4 -> 6.3458674 | H4: =F4/D4 -> 7.2874667
A5: 4 | B5: 4 | C5: 53 | D5: 6.6360126 | E5: 9.4022335 | F5: 47.577508 | G5: =F5/E5 -> 5.0602347 | H5: =F5/D5 -> 7.1695928
A6: 5 | B6: 5 | C6: 54 | D6: 6.6047049 | E6: 14.209176 | F6: 46.110882 | G6: =F6/E6 -> 3.2451482 | H6: =F6/D6 -> 6.9815204
A7: 6 | B7: 6 | C7: 55 | D7: 14.179552 | E7: 14.260078 | F7: 76.44237 | G7: =F7/E7 -> 5.3605858 | H7: =F7/D7 -> 5.3910285
A8: 7 | B8: 7 | C8: 56 | D8: 14.097596 | E8: 14.539268 | F8: 73.779467 | G8: =F8/E8 -> 5.0744969 | H8: =F8/D8 -> 5.2334788
A9: 8 | B9: 8 | C9: 57 | D9: 14.008793 | E9: 15.450772 | F9: 71.067241 | G9: =F9/E9 -> 4.5995915 | H9: =F9/D9 -> 5.0730453
A10: 9 | B10: 9 | C10: 58 | D10: 13.913287 | E10: 18.092606 | F10: 68.40635 | G10: =F10/E10 -> 3.7809008 | H10: =F10/D10 -> 4.9166205
A11: 10 | B11: 10 | C11: 59 | D11: 13.810991 | E11: 25.449629 | F11: 65.806568 | G11: =F11/E11 -> 2.5857575 | H11: =F11/D11 -> 4.7647971
A12: 11 | B12: 11 | C12: 60 | D12: 25.495683 | E12: 25.370495 | F12: 102.51553 | G12: =F12/E12 -> 4.0407382 | H12: =F12/D12 -> 4.0208974
A13: 12 | B13: 12 | C13: 61 | D13: 25.275223 | E13: 25.534198 | F13: 98.487392 | G13: =F13/E13 -> 3.857078 | H13: =F13/D13 -> 3.8965983
... A32: 31 | B32: 31 | C32: 80 | D32: 46.731753 | E32: 43.386724 | F32: 56.32548 | G32: =F32/E32 -> 1.2982192 | H32: =F32/D32 -> 1.2052936
A33: 32 | B33: 32 | C33: 81 | D33: 44.685895
A34: 33 | B34: 33 | C34: 82 | D34: 42.526358
A35: 34 | B35: 34 | C35: 83 | D35: 40.237169
A36: 35 | B36: 35 | C36: 84 | D36: 37.825216
A37: 36 | B37: 36 | C37: 85 | D37: 35.304112
A38: 37 | B38: 37 | C38: 86 | D38: 32.651269
A39: 38 | B39: 38 | C39: 87 | D39: 29.920764
A40: 39 | B40: 39 | C40: 88 | D40: 27.159166
A41: 40 | B41: 40 | C41: 89 | D41: 24.339475
A42: 41 | B42: 41 | C42: 90 | D42: 21.503881
A43: 42 | B43: 42 | C43: 91 | D43: 18.700153
A44: 43 | B44: 43 | C44: 92 | D44: 15.979494
... A51: 50 | B51: 50 | C51: 99 | D51: 2.7849862

Sheet Stage2to2
A1: Cycle | B1: Time (years) | C1: Age | D1: Engine - SoC Markov trace - Stage 2 | E1: Engine - Galleri Markov trace - Stage 2 | F1: Post-diagnosis calculation - QALYs Galleri | G1: Per patient QALYs | H1: Per patient QALYs
A2: 1 | B2: 1 | C2: 50 | D2: 1.856267 | E2: 1.856267 | F2: 21.727093 | G2: =F2/E2 -> 11.704724 | H2: =F2/D2 -> 11.704724
A3: 2 | B3: 2 | C3: 51 | D3: 1.8495684 | E3: 1.8495684 | F3: 20.971846 | G3: =F3/E3 -> 11.338778 | H3: =F3/D3 -> 11.338778
A4: 3 | B4: 3 | C4: 52 | D4: 1.8423223 | E4: 1.8423223 | F4: 20.235131 | G4: =F4/E4 -> 10.983491 | H4: =F4/D4 -> 10.983491
A5: 4 | B5: 4 | C5: 53 | D5: 1.8344717 | E5: 1.8344717 | F5: 19.516122 | G5: =F5/E5 -> 10.638552 | H5: =F5/D5 -> 10.638552
A6: 5 | B6: 5 | C6: 54 | D6: 1.8259057 | E6: 1.8259057 | F6: 18.81351 | G6: =F6/E6 -> 10.30366 | H6: =F6/D6 -> 10.30366
A7: 6 | B7: 6 | C7: 55 | D7: 4.411401 | E7: 4.411401 | F7: 37.18715 | G7: =F7/E7 -> 8.4297822 | H7: =F7/D7 -> 8.4297822
A8: 7 | B8: 7 | C8: 56 | D8: 4.3863415 | E8: 4.3863415 | F8: 35.861237 | G8: =F8/E8 -> 8.1756601 | H8: =F8/D8 -> 8.1756601
A9: 8 | B9: 8 | C9: 57 | D9: 4.3591466 | E9: 4.3591466 | F9: 34.56341 | G9: =F9/E9 -> 7.9289395 | H9: =F9/D9 -> 7.9289395
A10: 9 | B10: 9 | C10: 58 | D10: 4.32986 | E10: 4.32986 | F10: 33.294047 | G10: =F10/E10 -> 7.689405 | H10: =F10/D10 -> 7.689405
A11: 10 | B11: 10 | C11: 59 | D11: 4.2984544 | E11: 4.2984544 | F11: 32.052918 | G11: =F11/E11 -> 7.4568472 | H11: =F11/D11 -> 7.4568472
A12: 11 | B12: 11 | C12: 60 | D12: 9.1047335 | E12: 9.1047335 | F12: 56.629497 | G12: =F12/E12 -> 6.2197863 | H12: =F12/D12 -> 6.2197863
A13: 12 | B13: 12 | C13: 61 | D13: 9.0275713 | E13: 9.0275713 | F13: 54.456725 | G13: =F13/E13 -> 6.0322676 | H13: =F13/D13 -> 6.0322676
... A32: 31 | B32: 31 | C32: 80 | D32: 19.265504 | E32: 19.265504 | F32: 33.956527 | G32: =F32/E32 -> 1.7625558 | H32: =F32/D32 -> 1.7625558
A33: 32 | B33: 32 | C33: 81 | D33: 18.430063
A34: 33 | B34: 33 | C34: 82 | D34: 17.546988
A35: 34 | B35: 34 | C35: 83 | D35: 16.609626
A36: 35 | B36: 35 | C36: 84 | D36: 15.62075
A37: 36 | B37: 36 | C37: 85 | D37: 14.585919
A38: 37 | B38: 37 | C38: 86 | D38: 13.495737
A39: 38 | B39: 38 | C39: 87 | D39: 12.372494
A40: 39 | B40: 39 | C40: 88 | D40: 11.235413
A41: 40 | B41: 40 | C41: 89 | D41: 10.073302
A42: 41 | B42: 41 | C42: 90 | D42: 8.9035981
A43: 42 | B43: 42 | C43: 91 | D43: 7.7460786
A44: 43 | B44: 43 | C44: 92 | D44: 6.6219789
... A51: 50 | B51: 50 | C51: 99 | D51: 1.1576149

Sheet Stage4to3
A1: Cycle | B1: Time (years) | C1: Age | D1: Engine - SoC Markov trace - Stage 4 | E1: Engine - Galleri Markov trace - Stage 3 | F1: Post-diagnosis calculation - QALYs Galleri | G1: Per patient QALYs | H1: Per patient QALYs
A2: 1 | B2: 1 | C2: 50 | D2: 17.516331 | E2: 37.6918 | F2: 28.525101 | G2: =F2/E2 -> 0.75679859 | H2: =F2/D2 -> 1.6284861
A3: 2 | B3: 2 | C3: 51 | D3: 17.450387 | E3: 17.410698 | F3: 37.437266 | G3: =F3/E3 -> 2.150245 | H3: =F3/D3 -> 2.1453544
A4: 3 | B4: 3 | C4: 52 | D4: 17.3793 | E4: 17.611304 | F4: 37.278731 | G4: =F4/E4 -> 2.1167502 | H4: =F4/D4 -> 2.1450076
A5: 4 | B5: 4 | C5: 53 | D5: 17.302532 | E5: 19.584066 | F5: 36.033129 | G5: =F5/E5 -> 1.8399207 | H5: =F5/D5 -> 2.082535
